Workbook

Sheet Summary
A1: Fairfax County
A2: General Election
A3: Nov. 2 2021
A5: Absentee & Early Voting Report - *Unofficial*
D6: As of 11/05/2021
A8: Active Voters | B8: Mailed/ Emailed | C8: Returned by Mail | D8: Returned by Dropbox | E8: Total Returned AB | F8: Early Voting In Person | G8: % Voted (Turnout)
A9: 730300 | B9: =Mailed!B6 -> 82239 | C9: ='Returned mail'!B6 -> 48058 | D9: ='Returned Drop Box'!B6 -> 19217 | E9: =C9+D9 -> 67275 | F9: ='Early voting'!B5 -> 109764 | G9: =D11/A9 -> 0.24241955
B11: Total Ballots Cast | D11: =E9+F9 -> 177039 | E11: =E9/(B9-'In person instead'!B5) -> 0.8353096
B12: Of Total Ballots Cast | F12: =0.75*B9 -> 61679.25
B13: Voted early in person | D13: =F9/D11 -> 0.61999898
B14: Voted by AB | D14: =E9/D11 -> 0.38000102
A16: Early voters who had requested an AB | D16: ='In person instead'!B5/F9 -> 0.015487774
A17: AB returned by drop box | D17: =D9/E9 -> 0.28564846

Sheet Mailed
A1: Mailed Absentee Ballots
A2: Nov 2, 2021 ▪ General Election
A4: Total Ballots Mailed
A5: Date | B5: Total | C5: Domestic | D5: UOCAVA | E5: E-mail UOCAVA
A6: Total | B6: =SUM(B7:B52) -> 82239 | C6: =SUM(C7:C52) -> 75522 | D6: =SUM(D7:D52) -> 1779 | E6: =SUM(E7:E52) -> 4938
A7: 44456 | B7: =SUM(C7:E7) -> 41065 | C7: =36534-D7 -> 34987 | D7: =1542+5 -> 1547 | E7: =4525+6 -> 4531 | F7: =SUM(C7:D7) -> 36534
A8: 44457 | F8: =SUM(C8:D8) -> 0
A9: 44458 | F9: =SUM(C9:D9) -> 0
A10: 44459 | B10: =SUM(C10:E10) -> 2064 | C10: 2047 | D10: 10 | E10: 7 | F10: =SUM(C10:D10) -> 2057
A11: 44460 | B11: =SUM(C11:E11) -> 1597 | C11: =1578-D11 -> 1572 | D11: 6 | E11: 19 | F11: =SUM(C11:D11) -> 1578
A12: 44461 | B12: =SUM(C12:E12) -> 1123 | C12: =1111-5 -> 1106 | D12: 5 | E12: 12 | F12: =SUM(C12:D12) -> 1111
A13: 44462 | B13: =SUM(C13:E13) -> 1038 | C13: =1029-5 -> 1024 | D13: 5 | E13: 9 | F13: =SUM(C13:D13) -> 1029
A14: 44463 | B14: =SUM(C14:E14) -> 911 | C14: =901-D14 -> 895 | D14: 6 | E14: 10 | F14: =SUM(C14:D14) -> 901
A15: 44464 | F15: =SUM(C15:D15) -> 0
A16: 44465 | F16: =SUM(C16:D16) -> 0
A17: 44466 | B17: =SUM(C17:E17) -> 2130 | C17: 2106 | D17: 11 | E17: 13 | F17: =SUM(C17:D17) -> 2117
A18: 44467 | B18: =SUM(C18:E18) -> 1582 | C18: =1582-16 -> 1566 | D18: 16 | E18: 0 | F18: =SUM(C18:D18) -> 1582
A19: 44468 | B19: =SUM(C19:E19) -> 1551 | C19: =(92-4)+(1438-9) -> 1517 | D19: =9+4 -> 13 | E19: 21
A20: 44469 | B20: =SUM(C20:E20) -> 1189 | C20: =1189-8 -> 1181 | D20: 8 | E20: 0 | F20: =SUM(C20:D20) -> 1189
A21: 44470 | B21: =SUM(C21:E21) -> 1063 | C21: =1059-12-22+1 -> 1026 | D21: 12 | E21: 25 | F21: =SUM(C21:D21) -> 1038
A22: 44471 | F22: =SUM(C22:D22) -> 0
A23: 44472 | F23: =SUM(C23:D23) -> 0
A24: 44473 | B24: =SUM(C24:E24) -> 2074 | C24: =2059-12-6+1 -> 2042 | D24: 12 | E24: 20 | F24: =SUM(C24:D24) -> 2054
A25: 44474 | B25: =SUM(C25:E25) -> 1461 | C25: =1439-D25 -> 1428 | D25: 11 | E25: 22 | F25: =SUM(C25:D25) -> 1439
A26: 44475 | B26: =SUM(C26:E26) -> 1314 | C26: =1414-5-115 -> 1294 | D26: 5 | E26: 15 | F26: =SUM(C26:D26) -> 1299
A27: 44476 | B27: =SUM(C27:E27) -> 878 | C27: =868-3-D27 -> 861 | D27: 4 | E27: 13 | F27: =SUM(C27:D27) -> 865
A28: 44477 | B28: =SUM(C28:E28) -> 553 | C28: =495-2-D28+53 -> 541 | D28: 5 | E28: 7 | F28: =SUM(C28:D28) -> 546
A29: 44478 | F29: =SUM(C29:D29) -> 0
A30: 44479 | F30: =SUM(C30:D30) -> 0
A31: 44480 | B31: =SUM(C31:E31) -> 2033 | C31: =2020+2-D31-8 -> 2011 | D31: 3 | E31: 19 | F31: =SUM(C31:D31) -> 2014
A32: 44481 | B32: =SUM(C32:E32) -> 2927 | C32: =2906+19-22-D32 -> 2881 | D32: 22 | E32: 24 | F32: =SUM(C32:D32) -> 2903
A33: 44482 | B33: =SUM(C33:E33) -> 2326 | C33: =2288+2-D13 -> 2285 | D33: 15 | E33: 26 | F33: =SUM(C34:D34) -> 1617
A34: 44483 | B34: =SUM(C34:E34) -> 1628 | C34: =1617+1-11-D13 -> 1602 | D34: 15 | E34: 11 | F34: =SUM(#REF!) -> #REF!
A35: 44484 | B35: =SUM(C35:E35) -> 1506 | C35: =1497+1-8-D35 -> 1482 | D35: 8 | E35: 16 | F35: =SUM(C35:D35) -> 1490
A36: 44485 | F36: =SUM(C36:D36) -> 0
A37: 44486 | F37: =SUM(C37:D37) -> 0
A38: 44487 | B38: =SUM(C38:E38) -> 2361 | C38: =2362-18-D38 -> 2339 | D38: 5 | E38: 17 | F38: =SUM(C38:D38) -> 2344
A39: 44488 | B39: =SUM(C39:E39) -> 2331 | C39: =2335-D39-42 -> 2282 | D39: 11 | E39: 38 | F39: =SUM(C39:D39) -> 2293
A40: 44489 | B40: =SUM(C40:E40) -> 1391 | C40: =1367+18-15-D20 -> 1362 | D40: 9 | E40: 20 | F40: =SUM(C40:D40) -> 1371
A41: 44490 | B41: =SUM(C41:E41) -> 1506 | C41: =1503-18-D41 -> 1484 | D41: 1 | E41: 21 | F41: =SUM(C41:D41) -> 1485
...

Sheet Early Voting Option
A1: Early Voting
A3: June 8, 2021 ▪ Democratic Primary Election | G3: Total | H3: =F54 -> 38810
B5: Total Voters | G5: Government Center | O5: Government Center | W5: Government Center | AE5: Government Center | AM5: Government Center | AU5: Government Center | BC5: Government Center | BK5: Government Center
A6: Date | B6: Domestic | C6: UOCAVA | D6: E-mail UOCAVA | E6: Fax | F6: Total | G6: 34 | H6: 36 | I6: 38 | J6: 45 | K6: 49 | L6: 86 | M6: None | N6: Total | O6: 34 | P6: 36 | Q6: 38 | R6: 45 | S6: 49 | T6: 86 | U6: None | V6: Total | W6: 34 | X6: 36 | Y6: 38 | Z6: 45 | AA6: 49 | AB6: 86 | AC6: None | AD6: Total | AE6: 34 | AF6: 36 | AG6: 38 | AH6: 45 | AI6: 49 | AJ6: 86 | AK6: None | AL6: Total | AM6: 34 | AN6: 36 | AO6: 38 | AP6: 45 | AQ6: 49 | AR6: 86 | AS6: None | AT6: Total | AU6: 34 | AV6: 36 | AW6: 38 | AX6: 45 | AY6: 49 | AZ6: 86 | BA6: None | BB6: Total | BC6: 34 | BD6: 36 | BE6: 38 | BF6: 45 | BG6: 49 | BH6: 86 | BI6: None | BJ6: Total | BK6: 34 | BL6: 36 | BM6: 38 | BN6: 45 | BO6: 49 | BP6: 86 | BQ6: None | BR6: Total
A7: 44309 | B7: 4232 | C7: 234 | D7: 648 | E7: 0 | F7: =SUM(B7:E7) -> 5114 | N7: =SUM(L7:M7) -> 0 | V7: =SUM(T7:U7) -> 0 | AD7: =SUM(AB7:AC7) -> 0 | AL7: =SUM(AJ7:AK7) -> 0 | AT7: =SUM(AR7:AS7) -> 0 | BB7: =SUM(AZ7:BA7) -> 0 | BJ7: =SUM(BH7:BI7) -> 0 | BR7: =SUM(BP7:BQ7) -> 0
A8: 44310 | F8: =SUM(B8:E8) -> 0 | N8: =SUM(L8:M8) -> 0 | V8: =SUM(T8:U8) -> 0 | AD8: =SUM(AB8:AC8) -> 0 | AL8: =SUM(AJ8:AK8) -> 0 | AT8: =SUM(AR8:AS8) -> 0 | BB8: =SUM(AZ8:BA8) -> 0 | BJ8: =SUM(BH8:BI8) -> 0 | BR8: =SUM(BP8:BQ8) -> 0
A9: 44311
A10: 44312
A11: 44313 | B11: 481 | C11: 0 | D11: 1 | E11: 0 | F11: =SUM(B11:E11) -> 482 | N11: =SUM(L11:M11) -> 0 | V11: =SUM(T11:U11) -> 0 | AD11: =SUM(AB11:AC11) -> 0 | AL11: =SUM(AJ11:AK11) -> 0 | AT11: =SUM(AR11:AS11) -> 0 | BB11: =SUM(AZ11:BA11) -> 0 | BJ11: =SUM(BH11:BI11) -> 0 | BR11: =SUM(BP11:BQ11) -> 0
A12: 44314 | B12: 533 | C12: 2 | D12: 2 | E12: 0 | F12: =SUM(B12:E12) -> 537 | N12: =SUM(L12:M12) -> 0 | V12: =SUM(T12:U12) -> 0 | AD12: =SUM(AB12:AC12) -> 0 | AL12: =SUM(AJ12:AK12) -> 0 | AT12: =SUM(AR12:AS12) -> 0 | BB12: =SUM(AZ12:BA12) -> 0 | BJ12: =SUM(BH12:BI12) -> 0 | BR12: =SUM(BP12:BQ12) -> 0
A13: 44315 | B13: =398+350 -> 748 | C13: 6 | D13: 7 | E13: 0 | F13: =SUM(B13:E13) -> 761 | N13: =SUM(L13:M13) -> 0 | V13: =SUM(T13:U13) -> 0 | AD13: =SUM(AB13:AC13) -> 0 | AL13: =SUM(AJ13:AK13) -> 0 | AT13: =SUM(AR13:AS13) -> 0 | BB13: =SUM(AZ13:BA13) -> 0 | BJ13: =SUM(BH13:BI13) -> 0 | BR13: =SUM(BP13:BQ13) -> 0
A14: 44316 | B14: =346+295 -> 641 | C14: 3 | D14: 1 | E14: 0 | F14: =SUM(B14:E14) -> 645 | N14: =SUM(L14:M14) -> 0 | V14: =SUM(T14:U14) -> 0 | AD14: =SUM(AB14:AC14) -> 0 | AL14: =SUM(AJ14:AK14) -> 0 | AT14: =SUM(AR14:AS14) -> 0 | BB14: =SUM(AZ14:BA14) -> 0 | BJ14: =SUM(BH14:BI14) -> 0 | BR14: =SUM(BP14:BQ14) -> 0
A15: 44317 | B15: 1243 | C15: 1 | D15: 0 | E15: 0 | F15: =SUM(B15:E15) -> 1244 | N15: =SUM(L15:M15) -> 0 | V15: =SUM(T15:U15) -> 0 | AD15: =SUM(AB15:AC15) -> 0 | AL15: =SUM(AJ15:AK15) -> 0 | AT15: =SUM(AR15:AS15) -> 0 | BB15: =SUM(AZ15:BA15) -> 0 | BJ15: =SUM(BH15:BI15) -> 0 | BR15: =SUM(BP15:BQ15) -> 0
A16: 44318
A17: 44319
A18: 44320 | B18: =400+361+378 -> 1139 | C18: 0 | D18: 0 | E18: 0 | F18: =SUM(B18:E18) -> 1139 | N18: =SUM(L18:M18) -> 0 | V18: =SUM(T18:U18) -> 0 | AD18: =SUM(AB18:AC18) -> 0 | AL18: =SUM(AJ18:AK18) -> 0 | AT18: =SUM(AR18:AS18) -> 0 | BB18: =SUM(AZ18:BA18) -> 0 | BJ18: =SUM(BH18:BI18) -> 0 | BR18: =SUM(BP18:BQ18) -> 0
A19: 44321 | B19: =370+368+341+361 -> 1440 | C19: 1 | D19: 6 | E19: 0 | F19: =SUM(B19:E19) -> 1447 | N19: =SUM(L19:M19) -> 0 | V19: =SUM(T19:U19) -> 0 | AD19: =SUM(AB19:AC19) -> 0 | AL19: =SUM(AJ19:AK19) -> 0 | AT19: =SUM(AR19:AS19) -> 0 | BB19: =SUM(AZ19:BA19) -> 0 | BJ19: =SUM(BH19:BI19) -> 0 | BR19: =SUM(BP19:BQ19) -> 0
A20: 44322 | B20: 350 | C20: 0 | D20: 6 | E20: 0 | F20: =SUM(B20:E20) -> 356 | N20: =SUM(L20:M20) -> 0 | V20: =SUM(T20:U20) -> 0 | AD20: =SUM(AB20:AC20) -> 0 | AL20: =SUM(AJ20:AK20) -> 0 | AT20: =SUM(AR20:AS20) -> 0 | BB20: =SUM(AZ20:BA20) -> 0 | BJ20: =SUM(BH20:BI20) -> 0 | BR20: =SUM(BP20:BQ20) -> 0
A21: 44323 | B21: =352+355+332 -> 1039 | C21: 7 | D21: 0 | E21: 0 | F21: =SUM(B21:E21) -> 1046 | N21: =SUM(L21:M21) -> 0 | V21: =SUM(T21:U21) -> 0 | AD21: =SUM(AB21:AC21) -> 0 | AL21: =SUM(AJ21:AK21) -> 0 | AT21: =SUM(AR21:AS21) -> 0 | BB21: =SUM(AZ21:BA21) -> 0 | BJ21: =SUM(BH21:BI21) -> 0 | BR21: =SUM(BP21:BQ21) -> 0
A22: 44324 | B22: =93+367+354+383+348+359 -> 1904 | C22: 2 | D22: 1 | E22: 0 | F22: =SUM(B22:E22) -> 1907 | N22: =SUM(L22:M22) -> 0 | V22: =SUM(T22:U22) -> 0 | AD22: =SUM(AB22:AC22) -> 0 | AL22: =SUM(AJ22:AK22) -> 0 | AT22: =SUM(AR22:AS22) -> 0 | BB22: =SUM(AZ22:BA22) -> 0 | BJ22: =SUM(BH22:BI22) -> 0 | BR22: =SUM(BP22:BQ22) -> 0
A23: 44325
A24: 44326
A25: 44327 | F25: =SUM(B25:E25) -> 0
A26: 44328 | B26: =377+355+370+368+368 -> 1838 | C26: 0 | D26: 6 | E26: 0 | F26: =SUM(B26:E26) -> 1844 | N26: =SUM(L26:M26) -> 0 | V26: =SUM(T26:U26) -> 0 | AD26: =SUM(AB26:AC26) -> 0 | AL26: =SUM(AJ26:AK26) -> 0 | AT26: =SUM(AR26:AS26) -> 0 | BB26: =SUM(AZ26:BA26) -> 0 | BJ26: =SUM(BH26:BI26) -> 0 | BR26: =SUM(BP26:BQ26) -> 0
A27: 44329 | B27: =358+381+410+390 -> 1539 | C27: 4 | D27: 6 | E27: 0 | F27: =SUM(B27:E27) -> 1549 | N27: =SUM(L27:M27) -> 0 | V27: =SUM(T27:U27) -> 0 | AD27: =SUM(AB27:AC27) -> 0 | AL27: =SUM(AJ27:AK27) -> 0 | AT27: =SUM(AR27:AS27) -> 0 | BB27: =SUM(AZ27:BA27) -> 0 | BJ27: =SUM(BH27:BI27) -> 0 | BR27: =SUM(BP27:BQ27) -> 0
A28: 44330 | B28: =254+947+331 -> 1532 | C28: 0 | D28: 0 | E28: 0 | F28: =SUM(B28:E28) -> 1532 | N28: =SUM(L28:M28) -> 0 | V28: =SUM(T28:U28) -> 0 | AD28: =SUM(AB28:AC28) -> 0 | AL28: =SUM(AJ28:AK28) -> 0 | AT28: =SUM(AR28:AS28) -> 0 | BB28: =SUM(AZ28:BA28) -> 0 | BJ28: =SUM(BH28:BI28) -> 0 | BR28: =SUM(BP28:BQ28) -> 0
A29: 44331 | B29: =347+275+415+345+353 -> 1735 | C29: 5 | D29: 3 | E29: 0 | F29: =SUM(B29:E29) -> 1743 | N29: =SUM(L29:M29) -> 0 | V29: =SUM(T29:U29) -> 0 | AD29: =SUM(AB29:AC29) -> 0 | AL29: =SUM(AJ29:AK29) -> 0 | AT29: =SUM(AR29:AS29) -> 0 | BB29: =SUM(AZ29:BA29) -> 0 | BJ29: =SUM(BH29:BI29) -> 0 | BR29: =SUM(BP29:BQ29) -> 0
A30: 44332
A31: 44333
A32: 44334 | B32: =372+353+347+348+328 -> 1748 | C32: 3 | D32: 12 | E32: 0 | F32: =SUM(B32:E32) -> 1763 | N32: =SUM(L32:M32) -> 0 | V32: =SUM(T32:U32) -> 0 | AD32: =SUM(AB32:AC32) -> 0 | AL32: =SUM(AJ32:AK32) -> 0 | AT32: =SUM(AR32:AS32) -> 0 | BB32: =SUM(AZ32:BA32) -> 0 | BJ32: =SUM(BH32:BI32) -> 0 | BR32: =SUM(BP32:BQ32) -> 0
A33: 44335 | B33: =360+365+358+348+348+334+360+354 -> 2827 | C33: 1 | D33: 0 | E33: 0 | F33: =SUM(B33:E33) -> 2828 | N33: =SUM(L33:M33) -> 0 | V33: =SUM(T33:U33) -> 0 | AD33: =SUM(AB33:AC33) -> 0 | AL33: =SUM(AJ33:AK33) -> 0 | AT33: =SUM(AR33:AS33) -> 0 | BB33: =SUM(AZ33:BA33) -> 0 | BJ33: =SUM(BH33:BI33) -> 0 | BR33: =SUM(BP33:BQ33) -> 0
A34: 44336 | B34: =368+332 -> 700 | C34: 4 | D34: 19 | E34: 0 | F34: =SUM(B34:E34) -> 723 | N34: =SUM(L34:M34) -> 0 | V34: =SUM(T34:U34) -> 0 | AD34: =SUM(AB34:AC34) -> 0 | AL34: =SUM(AJ34:AK34) -> 0 | AT34: =SUM(AR34:AS34) -> 0 | BB34: =SUM(AZ34:BA34) -> 0 | BJ34: =SUM(BH34:BI34) -> 0 | BR34: =SUM(BP34:BQ34) -> 0
A35: 44337 | B35: =334+419+322+256+363 -> 1694 | C35: 9 | D35: 17 | E35: 0 | F35: =SUM(B35:E35) -> 1720 | N35: =SUM(L35:M35) -> 0 | V35: =SUM(T35:U35) -> 0 | AD35: =SUM(AB35:AC35) -> 0 | AL35: =SUM(AJ35:AK35) -> 0 | AT35: =SUM(AR35:AS35) -> 0 | BB35: =SUM(AZ35:BA35) -> 0 | BJ35: =SUM(BH35:BI35) -> 0 | BR35: =SUM(BP35:BQ35) -> 0
A36: 44338 | B36: =355+350+347+315 -> 1367 | C36: 6 | D36: 6 | E36: 0 | F36: =SUM(B36:E36) -> 1379 | N36: =SUM(L36:M36) -> 0 | V36: =SUM(T36:U36) -> 0 | AD36: =SUM(AB36:AC36) -> 0 | AL36: =SUM(AJ36:AK36) -> 0 | AT36: =SUM(AR36:AS36) -> 0 | BB36: =SUM(AZ36:BA36) -> 0 | BJ36: =SUM(BH36:BI36) -> 0 | BR36: =SUM(BP36:BQ36) -> 0
A37: 44339
A38: 44340
A39: 44341 | B39: =322+340+264+349 -> 1275 | C39: 6 | D39: 18 | E39: 1 | F39: =SUM(B39:E39) -> 1300 | N39: =SUM(L39:M39) -> 0 | V39: =SUM(T39:U39) -> 0 | AD39: =SUM(AB39:AC39) -> 0 | AL39: =SUM(AJ39:AK39) -> 0 | AT39: =SUM(AR39:AS39) -> 0 | BB39: =SUM(AZ39:BA39) -> 0 | BJ39: =SUM(BH39:BI39) -> 0 | BR39: =SUM(BP39:BQ39) -> 0
A40: 44342 | B40: =359+340+366 -> 1065 | C40: 1 | D40: 4 | E40: 0 | F40: =SUM(B40:E40) -> 1070 | N40: =SUM(L40:M40) -> 0 | V40: =SUM(T40:U40) -> 0 | AD40: =SUM(AB40:AC40) -> 0 | AL40: =SUM(AJ40:AK40) -> 0 | AT40: =SUM(AR40:AS40) -> 0 | BB40: =SUM(AZ40:BA40) -> 0 | BJ40: =SUM(BH40:BI40) -> 0 | BR40: =SUM(BP40:BQ40) -> 0
A41: 44343 | B41: =317+338 -> 655 | C41: 1 | D41: 5 | E41: 0 | F41: =SUM(B41:E41) -> 661 | N41: =SUM(L41:M41) -> 0 | V41: =SUM(T41:U41) -> 0 | AD41: =SUM(AB41:AC41) -> 0 | AL41: =SUM(AJ41:AK41) -> 0 | AT41: =SUM(AR41:AS41) -> 0 | BB41: =SUM(AZ41:BA41) -> 0 | BJ41: =SUM(BH41:BI41) -> 0 | BR41: =SUM(BP41:BQ41) -> 0
A42: 44344 | B42: =345+355+340 -> 1040 | C42: 3 | D42: 10 | E42: 0 | F42: =SUM(B42:E42) -> 1053 | N42: =SUM(L42:M42) -> 0 | V42: =SUM(T42:U42) -> 0 | AD42: =SUM(AB42:AC42) -> 0 | AL42: =SUM(AJ42:AK42) -> 0 | AT42: =SUM(AR42:AS42) -> 0 | BB42: =SUM(AZ42:BA42) -> 0 | BJ42: =SUM(BH42:BI42) -> 0 | BR42: =SUM(BP42:BQ42) -> 0
...

Sheet Returned mail
A1: Returned By Mail
A2: Nov 2, 2021 ▪ General Election
A4: Total Ballots Returned by Mail
A5: Date | B5: Total | C5: Domestic | D5: UOCAVA | E5: E-mail UOCAVA | F5: Undeliverable
A6: Total | B6: =SUM(B7:B56) -> 48058 | C6: =SUM(C7:C56) -> 45971 | D6: =SUM(D7:D56) -> 598 | E6: =SUM(E7:E56) -> 1489 | F6: =SUM(F7:F56) -> 971 | G6: =SUM(C6:E6) -> 48058
A7: 44456 | B7: =SUM(C7:E7) -> 2 | C7: 0 | D7: 0 | E7: 2 | F7: 0
A8: 44457
A9: 44458
A10: 44459 | B10: =SUM(C10:E10) -> 2 | C10: 0 | D10: 0 | E10: 2 | F10: 0
A11: 44460 | B11: =SUM(C11:E11) -> 8 | C11: 3 | D11: 0 | E11: 5 | F11: 0
A12: 44461 | B12: =SUM(C12:E12) -> 8 | C12: 3 | D12: 0 | E12: 5 | F12: 37
A13: 44462 | B13: =SUM(C13:E13) -> 1583 | C13: 1573 | D13: 3 | E13: 7 | F13: =171+41 -> 212
A14: 44463 | B14: =SUM(C14:E14) -> 1466 | C14: =1445+6 -> 1451 | D14: 4 | E14: 11 | F14: =93+50 -> 143
A15: 44464
A16: 44465
A17: 44466 | B17: =SUM(C17:E17) -> 3221 | C17: =3192+4 -> 3196 | D17: 13 | E17: 12 | F17: =112+10 -> 122
A18: 44467 | B18: =SUM(C18:E18) -> 140 | C18: =122-9 -> 113 | D18: 9 | E18: =17+1 -> 18 | F18: 12
A19: 44468 | B19: =SUM(C19:E19) -> 29 | C19: 8 | D19: 4 | E19: 17 | F19: =61+7 -> 68
A20: 44469 | B20: =SUM(C20:E20) -> 3234 | C20: =3212+1 -> 3213 | D20: 4 | E20: 17 | F20: 12
A21: 44470 | B21: =SUM(C21:E21) -> 1092 | C21: 1063 | D21: 13 | E21: 16 | F21: 6
A22: 44471
A23: 44472
A24: 44473 | B24: =SUM(C24:E24) -> 2449 | C24: =2418-1 -> 2417 | D24: 9 | E24: 23 | F24: 28
A25: 44474 | B25: =SUM(C25:E25) -> 27 | C25: 5 | D25: 9 | E25: 13 | F25: 13
A26: 44475 | B26: =SUM(C26:E26) -> 125 | C26: 90 | D26: 14 | E26: 21 | F26: 20
A27: 44476 | B27: =SUM(C27:E27) -> 2675 | C27: 2643 | D27: 4 | E27: 28 | F27: 11
A28: 44477 | B28: =SUM(C28:E28) -> 1133 | C28: 1091 | D28: 14 | E28: 28 | F28: 5
A29: 44478
A30: 44479
A31: 44480 | B31: =SUM(C31:E31) -> 41 | C31: 6 | D31: 10 | E31: 25 | F31: 13
A32: 44481 | B32: =SUM(C32:E32) -> 2512 | C32: 2457 | D32: 16 | E32: 39 | F32: =18+5 -> 23
A33: 44482 | B33: =SUM(C33:E33) -> 19 | C33: 1 | D33: 6 | E33: 12 | F33: 9
A34: 44483 | B34: =SUM(C34:E34) -> 2131 | C34: 2069 | D34: 27 | E34: 35 | F34: 8
A35: 44484 | B35: =SUM(C35:E35) -> 1617 | C35: 1583 | D35: 14 | E35: =21-1 -> 20 | F35: 9
A36: 44485
A37: 44486
A38: 44487 | B38: =SUM(C38:E38) -> 2897 | C38: 2836 | D38: 24 | E38: 37 | F38: 20
A39: 44488 | B39: =SUM(C39:E39) -> 169 | C39: 122 | D39: 19 | E39: 28 | F39: 2
A40: 44489 | B40: =SUM(C40:E40) -> 1885 | C40: 1829 | D40: 22 | E40: 34 | F40: 3
A41: 44490 | B41: =SUM(C41:E41) -> 1621 | C41: 1579 | D41: 13 | E41: 29 | F41: 34
...

Sheet Returned Drop Box
A1: Returned by Dropbox
A2: Nov 2, 2021 ▪ General Election
A4: Total Ballots Returned by Drop Box
A5: Date | B5: Total | C5: Domestic | D5: UOCAVA | E5: E-mail UOCAVA
A6: Total | B6: =SUM(B7:B53) -> 19217 | C6: =SUM(C7:C53) -> 19147 | D6: =SUM(D7:D53) -> 23 | E6: =SUM(E7:E53) -> 47 | F6: =SUM(C6:E6) -> 19217
A7: 44456 | B7: =SUM(C7:E7) -> 1 | C7: 0 | D7: 0 | E7: 1
A8: 44457
A9: 44458
A10: 44459 | B10: =SUM(C10:E10) -> 5 | C10: 5 | D10: 0 | E10: 0
A11: 44460 | B11: =SUM(C11:E11) -> 122 | C11: =68+54 -> 122 | D11: 0 | E11: 0
A12: 44461 | B12: =SUM(C12:E12) -> 103 | C12: =79+24 -> 103 | D12: 0 | E12: 0
A13: 44462 | B13: =SUM(C13:E13) -> 208 | C13: =66+142 -> 208 | D13: 0 | E13: 0
A14: 44463 | B14: =SUM(C14:E14) -> 116 | C14: =80+36 -> 116 | D14: 0 | E14: 0
A15: 44464
A16: 44465
A17: 44466 | B17: =SUM(C17:E17) -> 297 | C17: =269+28 -> 297 | D17: 0 | E17: 0
A18: 44467 | B18: =SUM(C18:E18) -> 374 | C18: =92+279+2 -> 373 | D18: 1 | E18: 0
A19: 44468 | B19: =SUM(C19:E19) -> 92 | C19: =78+15-1 -> 92 | D19: 0 | E19: 0
A20: 44469 | B20: =SUM(C20:E20) -> 249 | C20: =95+154 -> 249 | D20: 0 | E20: 0
A21: 44470 | B21: =SUM(C21:E21) -> 158 | C21: =119+39 -> 158 | D21: 0 | E21: 0
A22: 44471
A23: 44472
A24: 44473 | B24: =SUM(C24:E24) -> 351 | C24: =340+11 -> 351 | D24: 0 | E24: 0
A25: 44474 | B25: =SUM(C25:E25) -> 336 | C25: =89+247 -> 336 | D25: 0 | E25: 0
A26: 44475 | B26: =SUM(C26:E26) -> 87 | C26: =71+16 -> 87 | D26: 0 | E26: 0
A27: 44476 | B27: =SUM(C27:E27) -> 230 | C27: =93+136 -> 229 | D27: 0 | E27: 1
A28: 44477 | B28: =SUM(C28:E28) -> 121 | C28: =109+11 -> 120 | D28: 0 | E28: 1
A29: 44478
A30: 44479
A31: 44480 | B31: =SUM(C31:E31) -> 331 | C31: =303+28 -> 331 | D31: 0 | E31: 0
A32: 44481 | B32: =SUM(C32:E32) -> 303 | C32: =101+202 -> 303 | D32: 0 | E32: 0
A33: 44482 | B33: =SUM(C33:E33) -> 115 | C33: =93+21 -> 114 | D33: 0 | E33: 1
A34: 44483 | B34: =SUM(C34:E34) -> 342 | C34: =126+215 -> 341 | D34: 1 | E34: 0
A35: 44484 | B35: =SUM(C35:E35) -> 166 | C35: =144+22 -> 166 | D35: 0 | E35: 0
A36: 44485
A37: 44486
A38: 44487 | B38: =SUM(C38:E38) -> 476 | C38: =462+13 -> 475 | D38: 0 | E38: 1
A39: 44488 | B39: =SUM(C39:E39) -> 275 | C39: =129+146 -> 275 | D39: 0 | E39: 0
A40: 44489 | B40: =SUM(C40:E40) -> 321 | C40: =118+203 -> 321 | D40: 0 | E40: 0
A41: 44490 | B41: =SUM(C41:E41) -> 278 | C41: =109+169 -> 278 | D41: 0 | E41: 0
...

Sheet Early voting
A1: Early Voting
A2: Nov 2, 2021 ▪ General Election
A4: Date | B4: Total | C4: Gov't Center | D4: Mount Vernon | E4: North County | F4: Burke | G4: Centreville | H4: Franconia | I4: Gerry Hyland | J4: Great Falls | K4: Herndon | L4: Mason | M4: McLean | N4: Providence | O4: Sully | P4: Thomas Jefferson | Q4: Tysons Pimmit | R4: West Springfield
A5: Total | B5: =SUM(B6:B50) -> 109764 | C5: =SUM(C6:C50) -> 24632 | D5: =SUM(D6:D50) -> 11337 | E5: =SUM(E6:E50) -> 11433 | F5: =SUM(F6:F50) -> 5264 | G5: =SUM(G6:G50) -> 4173 | H5: =SUM(H6:H50) -> 5248 | I5: =SUM(I6:I50) -> 1266 | ... R5: =SUM(R6:R50) -> 7220
A6: 44456 | B6: =SUM(C6:R6) -> 1003 | C6: 579 | D6: 195 | E6: 229
A7: 44457 | B7: =SUM(C7:R7) -> 847 | C7: 391 | D7: 210 | E7: 246
A8: 44458
A9: 44459 | B9: =SUM(C9:E9) -> 823 | C9: 456 | D9: 185 | E9: 182
A10: 44460 | B10: =SUM(C10:E10) -> 690 | C10: 382 | D10: 178 | E10: 130
A11: 44461 | B11: =SUM(C11:E11) -> 629 | C11: 367 | D11: 145 | E11: 117
A12: 44462 | B12: =SUM(C12:E12) -> 719 | C12: 431 | D12: 150 | E12: 138
A13: 44463 | B13: =SUM(C13:E13) -> 824 | C13: 476 | D13: 164 | E13: 184
A14: 44464
A15: 44465
A16: 44466 | B16: =SUM(C16:E16) -> 817 | C16: 477 | D16: 158 | E16: 182
A17: 44467 | B17: =SUM(C17:E17) -> 800 | C17: 492 | D17: 157 | E17: 151
A18: 44468 | B18: =SUM(C18:E18) -> 951 | C18: 567 | D18: 215 | E18: 169
A19: 44469 | B19: =SUM(C19:E19) -> 884 | C19: 531 | D19: 158 | E19: 195
A20: 44470 | B20: =SUM(C20:E20) -> 1158 | C20: 682 | D20: 230 | E20: 246
A21: 44471
A22: 44472
A23: 44473 | B23: =SUM(C23:E23) -> 1035 | C23: 591 | D23: 214 | E23: 230
A24: 44474 | B24: =SUM(C24:E24) -> 976 | C24: 593 | D24: 192 | E24: 191
A25: 44475 | B25: =SUM(C25:E25) -> 861 | C25: 499 | D25: 175 | E25: 187
A26: 44476 | B26: =SUM(C26:E26) -> 896 | C26: 549 | D26: 172 | E26: 175
A27: 44477 | B27: =SUM(C27:E27) -> 1256 | C27: 726 | D27: 243 | E27: 287
A28: 44478
A29: 44479
A30: 44480 | B30: =SUM(C30:E30) -> 946 | C30: 542 | D30: 199 | E30: 205
A31: 44481 | B31: =SUM(C31:E31) -> 1402 | C31: 809 | D31: 325 | E31: 268
A32: 44482 | B32: =SUM(C32:E32) -> 1260 | C32: 684 | D32: 284 | E32: 292
A33: 44483 | B33: =SUM(C33:E33) -> 1261 | C33: 685 | D33: 303 | E33: 273
A34: 44484 | B34: =SUM(C34:E34) -> 1699 | C34: 924 | D34: 356 | E34: 419
A35: 44485
A36: 44486
A37: 44487 | B37: =SUM(C37:E37) -> 1775 | C37: 857 | D37: 402 | E37: 516
A38: 44488 | B38: =SUM(C38:E38) -> 1597 | C38: 836 | D38: 351 | E38: 410
A39: 44489 | B39: =SUM(C39:E39) -> 1542 | C39: 773 | D39: 387 | E39: 382
A40: 44490 | B40: =SUM(C40:R40) -> 6476 | C40: 795 | D40: 322 | E40: 343 | F40: 423 | G40: 308 | H40: 453 | I40: 59 | J40: 249 | K40: 268 | L40: 589 | M40: 703 | N40: 423 | O40: 313 | P40: 285 | Q40: 408 | R40: 535
A41: 44491 | B41: =SUM(C41:R41) -> 7378 | C41: 995 | D41: 478 | E41: 416 | F41: 479 | G41: 318 | H41: 505 | I41: 68 | J41: 266 | K41: 325 | L41: 595 | M41: 687 | N41: 475 | O41: 357 | P41: 329 | Q41: 442 | R41: 643
...

Sheet Sheet1
A1: Final 5 Days of Early Voting
A2: Day | B2: 2017 | C2: 2020 | D2: 2021
A3: 6 | B3: 373 | C3: 10565 | D3: 7128
A4: 5 | B4: 307 | C4: 10945 | D4: 7573
A5: 4 | B5: 392 | C5: 11172 | D5: 8014
A6: 3 | B6: 401 | C6: 13751 | D6: 8755
A7: 2 | B7: 504 | C7: 14165 | D7: 9715
A8: 1 | B8: 1557 | C8: 13879 | D8: 14414
A9: Total | B9: =SUM(B2:B8) -> 5551 | C9: =SUM(C3:C8) -> 74477 | D9: =SUM(D3:D8) -> 55599

Sheet In person instead
A1: Absentee Voters Voting In Person Instead
A2: Nov 2, 2021 ▪ General Election
A4: Date | B4: Total | C4: Surrendered Ballot | D4: No Ballot ("Goldenrod")
A5: Total | B5: =SUM(B6:B49) -> 1700 | C5: =SUM(C6:C49) -> 635 | D5: =SUM(D6:D49) -> 1065
A6: 44456 | B6: =SUM(C6:S6) -> 38 | C6: 0 | D6: 38
A7: 44457 | B7: =SUM(C7:S7) -> 23 | C7: 0 | D7: 23
A8: 44458
A9: 44459 | B9: =SUM(C9:D9) -> 28 | C9: 2 | D9: 26
A10: 44460 | B10: =SUM(C10:D10) -> 11 | C10: 6 | D10: 5
A11: 44461 | B11: =SUM(C11:D11) -> 5 | C11: 2 | D11: 3
A12: 44462 | B12: =SUM(C12:D12) -> 5 | C12: 1 | D12: 4
A13: 44463 | B13: =SUM(C13:D13) -> 14 | C13: 9 | D13: 5
A14: 44464
A15: 44465
A16: 44466 | B16: =SUM(C16:D16) -> 17 | C16: 8 | D16: 9
A17: 44467 | B17: =SUM(C17:D17) -> 12 | C17: 7 | D17: 5
A18: 44468 | B18: =SUM(C18:D18) -> 18 | C18: 11 | D18: 7
A19: 44469 | B19: =SUM(C19:D19) -> 9 | C19: 3 | D19: 6
A20: 44470 | B20: =SUM(C20:D20) -> 13 | C20: 6 | D20: 7
A21: 44471
A22: 44472
A23: 44473 | B23: =SUM(C23:D23) -> 14 | C23: 6 | D23: 8
A24: 44474 | B24: =SUM(C24:D24) -> 11 | C24: 6 | D24: 5
A25: 44475 | B25: =SUM(C25:D25) -> 9 | C25: 7 | D25: 2
A26: 44476 | B26: 11 | C26: 4 | D26: 7
A27: 44477 | B27: =SUM(C27:D27) -> 16 | C27: 7 | D27: 9
A28: 44478
A29: 44479
A30: 44480 | B30: =SUM(C30:D30) -> 16 | C30: 7 | D30: 9
A31: 44481 | B31: =SUM(C31:D31) -> 26 | C31: 11 | D31: 15
A32: 44482 | B32: =SUM(C32:D32) -> 26 | C32: 14 | D32: 12
A33: 44483 | B33: =SUM(C33:D33) -> 26 | C33: 9 | D33: 17
A34: 44484 | B34: =SUM(C34:D34) -> 31 | C34: 14 | D34: 17
A35: 44485
A36: 44486
A37: 44487 | B37: =SUM(C37:D37) -> 29 | C37: 13 | D37: 16
A38: 44488 | B38: =SUM(C38:D38) -> 28 | C38: 9 | D38: 19
A39: 44489 | B39: =SUM(C39:D39) -> 14 | C39: 5 | D39: 9
A40: 44490 | B40: =SUM(C40:D40) -> 101 | C40: 37 | D40: 64
A41: 44491 | B41: =SUM(C41:D41) -> 139 | C41: =4+4+3+2+1+7+0+4+0+2+9+5+0+2+3+4 -> 50 | D41: =13+10+9+3+5+4+5+0+7+2+13+8+0+4+2+4 -> 89
...

Sheet Voter Stmt Curing
A1: Statement of Absentee Voter
A2: Ballots Requiring Curing
A3: Reason | B3: Total for curing | C3: Cured | D3: Not cured | E3: % requiring curing of total AB returned | F3: Cure rate
A4: Total | B4: =SUM(B5:B10) -> 1464 | C4: =SUM(C5:C10) -> 811 | D4: =B4-C4 -> 653 | E4: =B4/Summary!E9 -> 0.021761427 | F4: =C4/B4 -> 0.55396175
A5: Missing voter signature only | B5: 44 | C5: 24 | D5: 20
A6: Missing witness signature only | B6: 839 | C6: 484 | D6: 355
A7: Missing name only | B7: 48 | C7: 30 | D7: 18
A8: Missing address only | B8: 228 | C8: 101 | D8: 127
A9: Combinations | B9: 127 | C9: 67 | D9: 60
A10: Blank | B10: 178 | C10: 105 | D10: 73

Sheet Potential return
A1: Looking at Potential Ballots to be Returned | G1: Nov. 1 2021
B2: Mailed/ emailed | C2: In person instead | D2: Mailed not voted in person | E2: Returned | F2: Still out there | G2: % Remaining Out There
A3: Domestic | B3: =Mailed!C6 -> 75522 | C3: ='In person instead'!B5 -> 1700 | D3: =B3-C3 -> 73822 | E3: ='Returned mail'!C6+'Returned Drop Box'!C6 -> 65118 | F3: =D3-E3 -> 8704 | G3: =F3/D3 -> 0.11790523
A4: UOCAVA | B4: =Mailed!D6+Mailed!E6 -> 6717 | C4: 0 | E4: ='Returned mail'!D6+'Returned mail'!E6+'Returned Drop Box'!D6+'Returned Drop Box'!E6 -> 2157 | F4: =B4-E4 -> 4560 | G4: =F4/B4 -> 0.6788745
A5: tottal | B5: =SUM(B3:B4) -> 82239 | C5: =SUM(C3:C4) -> 1700 | D5: =B5-C5 -> 80539 | E5: =SUM(E3:E4) -> 67275 | F5: =SUM(F3:F4) -> 13264 | G5: =F5/D5 -> 0.1646904
A7: Return rates of total mailed | B7: Domestic | C7: UOCAVA | D7: Total w/25% UOCAVA | E7: Remaining | F7: Totdal w/30% UOCAVA | G7: Remaining
A8: 0.75 | B8: =$D$3*A8 -> 55366.5 | D8: =B8+$C$14 -> 57045.75 | E8: =D8-$E$5 -> -10229.25 | F8: =B8+$C$16 -> 57381.6 | G8: =F8-$E$3 -> -7736.4
A9: 0.78 | B9: =$D$3*A9 -> 57581.16 | D9: =B9+$C$14 -> 59260.41 | E9: =D9-$E$5 -> -8014.59 | F9: =B9+$C$16 -> 59596.26 | G9: =F9-$E$3 -> -5521.74
A10: 0.79 | B10: =$D$3*A10 -> 58319.38 | D10: =B10+$C$14 -> 59998.63 | E10: =D10-$E$5 -> -7276.37 | F10: =B10+$C$16 -> 60334.48 | G10: =F10-$E$3 -> -4783.52
A11: 0.8 | B11: =$D$3*A11 -> 59057.6 | D11: =B11+$C$14 -> 60736.85 | E11: =D11-$E$5 -> -6538.15 | F11: =B11+$C$16 -> 61072.7 | G11: =F11-$E$3 -> -4045.3
A12: 0.82 | B12: =$D$3*A12 -> 60534.04 | D12: =B12+$C$14 -> 62213.29 | E12: =D12-$E$5 -> -5061.71 | F12: =B12+$C$16 -> 62549.14 | G12: =F12-$E$3 -> -2568.86
A13: 0.85 | B13: =$D$3*A13 -> 62748.7 | D13: =B13+$C$14 -> 64427.95 | E13: =D13-$E$5 -> -2847.05 | F13: =B13+$C$16 -> 64763.8 | G13: =F13-$E$3 -> -354.2
A14: 0.25 | C14: =$B$4*A14 -> 1679.25
A15: 0.28 | C15: =$B$4*A15 -> 1880.76
A16: 0.3 | C16: =$B$4*A16 -> 2015.1
A19: Return | B19: 2017 | C19: 2020
A20: Domestic | B20: 0.79 | C20: 0.84 | D20: Approx. because UOCAVAs not broken out for dropbox returns
A21: UOCAVA | B21: 0.26 | C21: 0.79
A22: Total | B22: 0.67 | C22: 0.84

Sheet For SOR
A1: Early Voting (in person)
A2: June 8, 2021 ▪ Democratic Primary Election
B4: Delegate District | C4: Total
B5: 34 | C5: 825
A6: Total | B6: 36 | C6: 1314
B7: 38 | C7: 859
B8: 45 | C8: 88
B9: 49 | C9: 177
B10: 86 | C10: 995
B11: No DD Race | C11: 6666
B12: Total | C12: =SUM(C5:C11) -> 10924
A14: Burke | B14: 34 | C14: 1
B15: 36 | C15: 0
B16: 38 | C16: 0
B17: 45 | C17: 0
B18: 49 | C18: 0
B19: 86 | C19: 0
B20: None | C20: 313
B21: Total | C21: 314
A23: Centreville | B23: 34 | C23: 1
B24: 36 | C24: 1
B25: 38 | C25: 0
B26: 45 | C26: 0
B27: 49 | C27: 0
B28: 86 | C28: 0
B29: None | C29: 175
B30: Total | C30: 177
A32: Franconia | B32: 34 | C32: 0
B33: 36 | C33: 0
B34: 38 | C34: 4
B35: 45 | C35: 3
B36: 49 | C36: 1
B37: 86 | C37: 0
B38: None | C38: 532
B39: Total | C39: 540
A41: Government Center | B41: 34 | C41: 85
B42: 36 | C42: 171
B43: 38 | C43: 80
B44: 45 | C44: 5
B45: 49 | C45: 26
...

Sheet Early Voting Trad
B3: Total | K3: Government Center | S3: Mount Vernon | AA3: North County | AI3: Burke | AQ3: Centreville | AY3: Franconia | BG3: Great Falls | BO3: Herndon | BW3: Laurel Hills | CE3: Mason | CM3: McLean | CU3: Providence | DC3: Sully | DK3: Thomas Jefferson | DS3: Tysons Pimmit | EA3: West Springfield
A4: Delegate District | B4: 34 | C4: 36 | D4: 38 | E4: 45 | F4: 49 | G4: 86 | H4: None | I4: Total | K4: 34 | L4: 36 | M4: 38 | N4: 45 | O4: 49 | P4: 86 | Q4: None | R4: Total | S4: 34 | T4: 36 | U4: 38 | V4: 45 | W4: 49 | X4: 86 | Y4: None | Z4: Total | AA4: 34 | AB4: 36 | AC4: 38 | AD4: 45 | AE4: 49 | AF4: 86 | AG4: None | AH4: Total | AI4: 34 | AJ4: 36 | AK4: 38 | AL4: 45 | AM4: 49 | AN4: 86 | AO4: None | AP4: Total | AQ4: 34 | AR4: 36 | AS4: 38 | AT4: 45 | AU4: 49 | AV4: 86 | AW4: None | AX4: Total | AY4: 34 | AZ4: 36 | BA4: 38 | BB4: 45 | BC4: 49 | BD4: 86 | BE4: None | BF4: Total | BG4: 34 | BH4: 36 | BI4: 38 | BJ4: 45 | BK4: 49 | BL4: 86 | BM4: None | BN4: Total | BO4: 34 | BP4: 36 | BQ4: 38 | BR4: 45 | BS4: 49 | BT4: 86 | BU4: None | BV4: Total | BW4: 34 | BX4: 36 | BY4: 38 | BZ4: 45 | CA4: 49 | CB4: 86 | CC4: None | CD4: Total | CE4: 34 | CF4: 36 | CG4: 38 | CH4: 45 | CI4: 49 | CJ4: 86 | CK4: None | CL4: Total | CM4: 34 | CN4: 36 | CO4: 38 | CP4: 45 | CQ4: 49 | CR4: 86 | CS4: None | CT4: Total | CU4: 34 | CV4: 36 | CW4: 38 | CX4: 45 | CY4: 49 | CZ4: 86 | DA4: None | DB4: Total | DC4: 34 | DD4: 36 | DE4: 38 | DF4: 45 | DG4: 49 | DH4: 86 | DI4: None | DJ4: Total | DK4: 34 | DL4: 36 | DM4: 38 | DN4: 45 | DO4: 49 | DP4: 86 | DQ4: None | DR4: Total | DS4: 34 | DT4: 36 | DU4: 38 | DV4: 45 | DW4: 49 | DX4: 86 | DY4: None | DZ4: Total | EA4: 34 | EB4: 36 | EC4: 38 | ED4: 45 | EE4: 49 | EF4: 86 | EG4: None | EH4: Total
A5: Total | B5: =SUM(B6:B50) -> 0 | C5: =SUM(C6:C50) -> 0 | D5: =SUM(D6:D50) -> 0 | E5: =SUM(E6:E50) -> 0 | F5: =SUM(F6:F50) -> 0 | G5: =SUM(G6:G50) -> 0 | H5: =SUM(H6:H50) -> 67 | I5: =SUM(B5:H5) -> 67 | K5: =SUM(K6:K50) -> 0 | L5: =SUM(L6:L50) -> 0 | M5: =SUM(M6:M50) -> 0 | N5: =SUM(N6:N50) -> 0 | O5: =SUM(O6:O50) -> 0 | P5: =SUM(P6:P50) -> 0 | Q5: =SUM(Q6:Q50) -> 67 | R5: =SUM(K5:Q5) -> 67 | S5: =SUM(S6:S50) -> 0 | T5: =SUM(T6:T50) -> 0 | U5: =SUM(U6:U50) -> 0 | V5: =SUM(V6:V50) -> 0 | W5: =SUM(W6:W50) -> 0 | X5: =SUM(X6:X50) -> 0 | Y5: =SUM(Y6:Y50) -> 0 | Z5: =SUM(S5:Y5) -> 0 | AA5: =SUM(AA6:AA50) -> 0 | AB5: =SUM(AB6:AB50) -> 0 | AC5: =SUM(AC6:AC50) -> 0 | AD5: =SUM(AD6:AD50) -> 0 | AE5: =SUM(AE6:AE50) -> 0 | AF5: =SUM(AF6:AF50) -> 0 | AG5: =SUM(AG6:AG50) -> 0 | AH5: =SUM(AA5:AG5) -> 0 | AI5: =SUM(AI6:AI50) -> 0 | AJ5: =SUM(AJ6:AJ50) -> 0 | AK5: =SUM(AK6:AK50) -> 0 | AL5: =SUM(AL6:AL50) -> 0 | AM5: =SUM(AM6:AM50) -> 0 | AN5: =SUM(AN6:AN50) -> 0 | AO5: =SUM(AO6:AO50) -> 0 | AP5: =SUM(AP6:AP50) -> 0 | ... EG5: =SUM(EG6:EG50) -> 0 | EH5: =SUM(EA5:EG5) -> 0
A6: 44308 | B6: =K6+S6+AA6+AI6+AQ6+AY6+BG6+BO6+BW6+CE6+CM6+CU6+DC6+DK6+DS6+EA6 -> 0 | C6: =L6+T6+AB6+AJ6+AR6+AZ6+BH6+BP6+BX6+CF6+CN6+CV6+DD6+DL6+DT6+EB6 -> 0 | D6: =M6+U6+AC6+AK6+AS6+BA6+BI6+BQ6+BY6+CG6+CO6+CW6+DE6+DM6+DU6+EC6 -> 0 | E6: =N6+V6+AD6+AL6+AT6+BB6+BJ6+BR6+BZ6+CH6+CP6+CX6+DF6+DN6+DV6+ED6 -> 0 | F6: =O6+W6+AE6+AM6+AU6+BC6+BK6+BS6+CA6+CI6+CQ6+CY6+DG6+DO6+DW6+EE6 -> 0 | G6: =P6+X6+AF6+AN6+AV6+BD6+BL6+BT6+CB6+CJ6+CR6+CZ6+DH6+DP6+DX6+EF6 -> 0 | H6: =Q6+Y6+AG6+AO6+AW6+BE6+BM6+BU6+CC6+CK6+CS6+DA6+DI6+DQ6+DY6+EG6 -> 0 | I6: =SUM(B6:H6) -> 0 | K6: 0 | L6: 0 | M6: 0 | N6: 0 | O6: 0 | P6: 0 | Q6: 0 | R6: =SUM(K6:Q6) -> 0 | S6: 0 | T6: 0 | U6: 0 | V6: 0 | W6: 0 | X6: 0 | Y6: 0 | Z6: =SUM(S6:Y6) -> 0 | AA6: 0 | AB6: 0 | AC6: 0 | AD6: 0 | AE6: 0 | AF6: 0 | AG6: 0 | AH6: =SUM(AA6:AG6) -> 0 | AP6: =SUM(AI6:AO6) -> 0 | AX6: =SUM(AQ6:AW6) -> 0 | BF6: =SUM(AY6:BE6) -> 0 | BN6: =SUM(BG6:BM6) -> 0 | BV6: =SUM(BO6:BU6) -> 0 | CD6: =SUM(BW6:CC6) -> 0 | CL6: =SUM(CE6:CK6) -> 0 | CT6: =SUM(CM6:CS6) -> 0 | DB6: =SUM(CU6:DA6) -> 0 | DJ6: =SUM(DC6:DI6) -> 0 | DR6: =SUM(DK6:DQ6) -> 0 | DZ6: =SUM(DS6:DY6) -> 0 | EH6: =SUM(EA6:EG6) -> 0
A7: 44309 | B7: =K7+S7+AA7+AI7+AQ7+AY7+BG7+BO7+BW7+CE7+CM7+CU7+DC7+DK7+DS7+EA7 -> 0 | C7: =L7+T7+AB7+AJ7+AR7+AZ7+BH7+BP7+BX7+CF7+CN7+CV7+DD7+DL7+DT7+EB7 -> 0 | D7: =M7+U7+AC7+AK7+AS7+BA7+BI7+BQ7+BY7+CG7+CO7+CW7+DE7+DM7+DU7+EC7 -> 0 | E7: =N7+V7+AD7+AL7+AT7+BB7+BJ7+BR7+BZ7+CH7+CP7+CX7+DF7+DN7+DV7+ED7 -> 0 | F7: =O7+W7+AE7+AM7+AU7+BC7+BK7+BS7+CA7+CI7+CQ7+CY7+DG7+DO7+DW7+EE7 -> 0 | G7: =P7+X7+AF7+AN7+AV7+BD7+BL7+BT7+CB7+CJ7+CR7+CZ7+DH7+DP7+DX7+EF7 -> 0 | H7: =Q7+Y7+AG7+AO7+AW7+BE7+BM7+BU7+CC7+CK7+CS7+DA7+DI7+DQ7+DY7+EG7 -> 67 | I7: =SUM(B7:H7) -> 67 | K7: 0 | L7: 0 | M7: 0 | N7: 0 | O7: 0 | P7: 0 | Q7: 67 | R7: =SUM(K7:Q7) -> 67 | S7: 0 | T7: 0 | U7: 0 | V7: 0 | W7: 0 | X7: 0 | Y7: 0 | Z7: =SUM(S7:Y7) -> 0 | AA7: 0 | AB7: 0 | AC7: 0 | AD7: 0 | AE7: 0 | AF7: 0 | AG7: 0 | AH7: =SUM(AA7:AG7) -> 0 | AP7: =SUM(AI7:AO7) -> 0 | AX7: =SUM(AQ7:AW7) -> 0 | BF7: =SUM(AY7:BE7) -> 0 | BN7: =SUM(BG7:BM7) -> 0 | BV7: =SUM(BO7:BU7) -> 0 | CD7: =SUM(BW7:CC7) -> 0 | CL7: =SUM(CE7:CK7) -> 0 | CT7: =SUM(CM7:CS7) -> 0 | DB7: =SUM(CU7:DA7) -> 0 | DJ7: =SUM(DC7:DI7) -> 0 | DR7: =SUM(DK7:DQ7) -> 0 | DZ7: =SUM(DS7:DY7) -> 0 | EH7: =SUM(EA7:EG7) -> 0
A8: 44310 | B8: =K8+S8+AA8+AI8+AQ8+AY8+BG8+BO8+BW8+CE8+CM8+CU8+DC8+DK8+DS8+EA8 -> 0 | C8: =L8+T8+AB8+AJ8+AR8+AZ8+BH8+BP8+BX8+CF8+CN8+CV8+DD8+DL8+DT8+EB8 -> 0 | D8: =M8+U8+AC8+AK8+AS8+BA8+BI8+BQ8+BY8+CG8+CO8+CW8+DE8+DM8+DU8+EC8 -> 0 | E8: =N8+V8+AD8+AL8+AT8+BB8+BJ8+BR8+BZ8+CH8+CP8+CX8+DF8+DN8+DV8+ED8 -> 0 | F8: =O8+W8+AE8+AM8+AU8+BC8+BK8+BS8+CA8+CI8+CQ8+CY8+DG8+DO8+DW8+EE8 -> 0 | G8: =P8+X8+AF8+AN8+AV8+BD8+BL8+BT8+CB8+CJ8+CR8+CZ8+DH8+DP8+DX8+EF8 -> 0 | H8: =Q8+Y8+AG8+AO8+AW8+BE8+BM8+BU8+CC8+CK8+CS8+DA8+DI8+DQ8+DY8+EG8 -> 0 | I8: =SUM(B8:H8) -> 0 | R8: =SUM(K8:Q8) -> 0 | Z8: =SUM(S8:Y8) -> 0 | AH8: =SUM(AA8:AG8) -> 0 | AP8: =SUM(AI8:AO8) -> 0 | AX8: =SUM(AQ8:AW8) -> 0 | BF8: =SUM(AY8:BE8) -> 0 | BN8: =SUM(BG8:BM8) -> 0 | BV8: =SUM(BO8:BU8) -> 0 | CD8: =SUM(BW8:CC8) -> 0 | CL8: =SUM(CE8:CK8) -> 0 | CT8: =SUM(CM8:CS8) -> 0 | DB8: =SUM(CU8:DA8) -> 0 | DJ8: =SUM(DC8:DI8) -> 0 | DR8: =SUM(DK8:DQ8) -> 0 | DZ8: =SUM(DS8:DY8) -> 0 | EH8: =SUM(EA8:EG8) -> 0
A9: 44311
A10: 44312 | B10: =K10+S10+AA10+AI10+AQ10+AY10+BG10+BO10+BW10+CE10+CM10+CU10+DC10+DK10+DS10+EA10 -> 0 | C10: =L10+T10+AB10+AJ10+AR10+AZ10+BH10+BP10+BX10+CF10+CN10+CV10+DD10+DL10+DT10+EB10 -> 0 | D10: =M10+U10+AC10+AK10+AS10+BA10+BI10+BQ10+BY10+CG10+CO10+CW10+DE10+DM10+DU10+EC10 -> 0 | E10: =N10+V10+AD10+AL10+AT10+BB10+BJ10+BR10+BZ10+CH10+CP10+CX10+DF10+DN10+DV10+ED10 -> 0 | F10: =O10+W10+AE10+AM10+AU10+BC10+BK10+BS10+CA10+CI10+CQ10+CY10+DG10+DO10+DW10+EE10 -> 0 | G10: =P10+X10+AF10+AN10+AV10+BD10+BL10+BT10+CB10+CJ10+CR10+CZ10+DH10+DP10+DX10+EF10 -> 0 | H10: =Q10+Y10+AG10+AO10+AW10+BE10+BM10+BU10+CC10+CK10+CS10+DA10+DI10+DQ10+DY10+EG10 -> 0 | I10: =SUM(B10:H10) -> 0 | R10: =SUM(K10:Q10) -> 0 | Z10: =SUM(S10:Y10) -> 0 | AH10: =SUM(AA10:AG10) -> 0 | AP10: =SUM(AI10:AO10) -> 0 | AX10: =SUM(AQ10:AW10) -> 0 | BF10: =SUM(AY10:BE10) -> 0 | BN10: =SUM(BG10:BM10) -> 0 | BV10: =SUM(BO10:BU10) -> 0 | CD10: =SUM(BW10:CC10) -> 0 | CL10: =SUM(CE10:CK10) -> 0 | CT10: =SUM(CM10:CS10) -> 0 | DB10: =SUM(CU10:DA10) -> 0 | DJ10: =SUM(DC10:DI10) -> 0 | DR10: =SUM(DK10:DQ10) -> 0 | DZ10: =SUM(DS10:DY10) -> 0 | EH10: =SUM(EA10:EG10) -> 0
A11: 44313 | B11: =K11+S11+AA11+AI11+AQ11+AY11+BG11+BO11+BW11+CE11+CM11+CU11+DC11+DK11+DS11+EA11 -> 0 | C11: =L11+T11+AB11+AJ11+AR11+AZ11+BH11+BP11+BX11+CF11+CN11+CV11+DD11+DL11+DT11+EB11 -> 0 | D11: =M11+U11+AC11+AK11+AS11+BA11+BI11+BQ11+BY11+CG11+CO11+CW11+DE11+DM11+DU11+EC11 -> 0 | E11: =N11+V11+AD11+AL11+AT11+BB11+BJ11+BR11+BZ11+CH11+CP11+CX11+DF11+DN11+DV11+ED11 -> 0 | F11: =O11+W11+AE11+AM11+AU11+BC11+BK11+BS11+CA11+CI11+CQ11+CY11+DG11+DO11+DW11+EE11 -> 0 | G11: =P11+X11+AF11+AN11+AV11+BD11+BL11+BT11+CB11+CJ11+CR11+CZ11+DH11+DP11+DX11+EF11 -> 0 | H11: =Q11+Y11+AG11+AO11+AW11+BE11+BM11+BU11+CC11+CK11+CS11+DA11+DI11+DQ11+DY11+EG11 -> 0 | I11: =SUM(B11:H11) -> 0 | R11: =SUM(K11:Q11) -> 0 | Z11: =SUM(S11:Y11) -> 0 | AH11: =SUM(AA11:AG11) -> 0 | AP11: =SUM(AI11:AO11) -> 0 | AX11: =SUM(AQ11:AW11) -> 0 | BF11: =SUM(AY11:BE11) -> 0 | BN11: =SUM(BG11:BM11) -> 0 | BV11: =SUM(BO11:BU11) -> 0 | CD11: =SUM(BW11:CC11) -> 0 | CL11: =SUM(CE11:CK11) -> 0 | CT11: =SUM(CM11:CS11) -> 0 | DB11: =SUM(CU11:DA11) -> 0 | DJ11: =SUM(DC11:DI11) -> 0 | DR11: =SUM(DK11:DQ11) -> 0 | DZ11: =SUM(DS11:DY11) -> 0 | EH11: =SUM(EA11:EG11) -> 0
A12: 44314 | B12: =K12+S12+AA12+AI12+AQ12+AY12+BG12+BO12+BW12+CE12+CM12+CU12+DC12+DK12+DS12+EA12 -> 0 | C12: =L12+T12+AB12+AJ12+AR12+AZ12+BH12+BP12+BX12+CF12+CN12+CV12+DD12+DL12+DT12+EB12 -> 0 | D12: =M12+U12+AC12+AK12+AS12+BA12+BI12+BQ12+BY12+CG12+CO12+CW12+DE12+DM12+DU12+EC12 -> 0 | E12: =N12+V12+AD12+AL12+AT12+BB12+BJ12+BR12+BZ12+CH12+CP12+CX12+DF12+DN12+DV12+ED12 -> 0 | F12: =O12+W12+AE12+AM12+AU12+BC12+BK12+BS12+CA12+CI12+CQ12+CY12+DG12+DO12+DW12+EE12 -> 0 | G12: =P12+X12+AF12+AN12+AV12+BD12+BL12+BT12+CB12+CJ12+CR12+CZ12+DH12+DP12+DX12+EF12 -> 0 | H12: =Q12+Y12+AG12+AO12+AW12+BE12+BM12+BU12+CC12+CK12+CS12+DA12+DI12+DQ12+DY12+EG12 -> 0 | I12: =SUM(B12:H12) -> 0 | R12: =SUM(K12:Q12) -> 0 | Z12: =SUM(S12:Y12) -> 0 | AH12: =SUM(AA12:AG12) -> 0 | AP12: =SUM(AI12:AO12) -> 0 | AX12: =SUM(AQ12:AW12) -> 0 | BF12: =SUM(AY12:BE12) -> 0 | BN12: =SUM(BG12:BM12) -> 0 | BV12: =SUM(BO12:BU12) -> 0 | CD12: =SUM(BW12:CC12) -> 0 | CL12: =SUM(CE12:CK12) -> 0 | CT12: =SUM(CM12:CS12) -> 0 | DB12: =SUM(CU12:DA12) -> 0 | DJ12: =SUM(DC12:DI12) -> 0 | DR12: =SUM(DK12:DQ12) -> 0 | DZ12: =SUM(DS12:DY12) -> 0 | EH12: =SUM(EA12:EG12) -> 0
A13: 44315 | B13: =K13+S13+AA13+AI13+AQ13+AY13+BG13+BO13+BW13+CE13+CM13+CU13+DC13+DK13+DS13+EA13 -> 0 | C13: =L13+T13+AB13+AJ13+AR13+AZ13+BH13+BP13+BX13+CF13+CN13+CV13+DD13+DL13+DT13+EB13 -> 0 | D13: =M13+U13+AC13+AK13+AS13+BA13+BI13+BQ13+BY13+CG13+CO13+CW13+DE13+DM13+DU13+EC13 -> 0 | E13: =N13+V13+AD13+AL13+AT13+BB13+BJ13+BR13+BZ13+CH13+CP13+CX13+DF13+DN13+DV13+ED13 -> 0 | F13: =O13+W13+AE13+AM13+AU13+BC13+BK13+BS13+CA13+CI13+CQ13+CY13+DG13+DO13+DW13+EE13 -> 0 | G13: =P13+X13+AF13+AN13+AV13+BD13+BL13+BT13+CB13+CJ13+CR13+CZ13+DH13+DP13+DX13+EF13 -> 0 | H13: =Q13+Y13+AG13+AO13+AW13+BE13+BM13+BU13+CC13+CK13+CS13+DA13+DI13+DQ13+DY13+EG13 -> 0 | I13: =SUM(B13:H13) -> 0 | R13: =SUM(K13:Q13) -> 0 | Z13: =SUM(S13:Y13) -> 0 | AH13: =SUM(AA13:AG13) -> 0 | AP13: =SUM(AI13:AO13) -> 0 | AX13: =SUM(AQ13:AW13) -> 0 | BF13: =SUM(AY13:BE13) -> 0 | BN13: =SUM(BG13:BM13) -> 0 | BV13: =SUM(BO13:BU13) -> 0 | CD13: =SUM(BW13:CC13) -> 0 | CL13: =SUM(CE13:CK13) -> 0 | CT13: =SUM(CM13:CS13) -> 0 | DB13: =SUM(CU13:DA13) -> 0 | DJ13: =SUM(DC13:DI13) -> 0 | DR13: =SUM(DK13:DQ13) -> 0 | DZ13: =SUM(DS13:DY13) -> 0 | EH13: =SUM(EA13:EG13) -> 0
A14: 44316 | B14: =K14+S14+AA14+AI14+AQ14+AY14+BG14+BO14+BW14+CE14+CM14+CU14+DC14+DK14+DS14+EA14 -> 0 | C14: =L14+T14+AB14+AJ14+AR14+AZ14+BH14+BP14+BX14+CF14+CN14+CV14+DD14+DL14+DT14+EB14 -> 0 | D14: =M14+U14+AC14+AK14+AS14+BA14+BI14+BQ14+BY14+CG14+CO14+CW14+DE14+DM14+DU14+EC14 -> 0 | E14: =N14+V14+AD14+AL14+AT14+BB14+BJ14+BR14+BZ14+CH14+CP14+CX14+DF14+DN14+DV14+ED14 -> 0 | F14: =O14+W14+AE14+AM14+AU14+BC14+BK14+BS14+CA14+CI14+CQ14+CY14+DG14+DO14+DW14+EE14 -> 0 | G14: =P14+X14+AF14+AN14+AV14+BD14+BL14+BT14+CB14+CJ14+CR14+CZ14+DH14+DP14+DX14+EF14 -> 0 | H14: =Q14+Y14+AG14+AO14+AW14+BE14+BM14+BU14+CC14+CK14+CS14+DA14+DI14+DQ14+DY14+EG14 -> 0 | I14: =SUM(B14:H14) -> 0 | R14: =SUM(K14:Q14) -> 0 | Z14: =SUM(S14:Y14) -> 0 | AH14: =SUM(AA14:AG14) -> 0 | AP14: =SUM(AI14:AO14) -> 0 | AX14: =SUM(AQ14:AW14) -> 0 | BF14: =SUM(AY14:BE14) -> 0 | BN14: =SUM(BG14:BM14) -> 0 | BV14: =SUM(BO14:BU14) -> 0 | CD14: =SUM(BW14:CC14) -> 0 | CL14: =SUM(CE14:CK14) -> 0 | CT14: =SUM(CM14:CS14) -> 0 | DB14: =SUM(CU14:DA14) -> 0 | DJ14: =SUM(DC14:DI14) -> 0 | DR14: =SUM(DK14:DQ14) -> 0 | DZ14: =SUM(DS14:DY14) -> 0 | EH14: =SUM(EA14:EG14) -> 0
A15: 44317 | B15: =K15+S15+AA15+AI15+AQ15+AY15+BG15+BO15+BW15+CE15+CM15+CU15+DC15+DK15+DS15+EA15 -> 0 | C15: =L15+T15+AB15+AJ15+AR15+AZ15+BH15+BP15+BX15+CF15+CN15+CV15+DD15+DL15+DT15+EB15 -> 0 | D15: =M15+U15+AC15+AK15+AS15+BA15+BI15+BQ15+BY15+CG15+CO15+CW15+DE15+DM15+DU15+EC15 -> 0 | E15: =N15+V15+AD15+AL15+AT15+BB15+BJ15+BR15+BZ15+CH15+CP15+CX15+DF15+DN15+DV15+ED15 -> 0 | F15: =O15+W15+AE15+AM15+AU15+BC15+BK15+BS15+CA15+CI15+CQ15+CY15+DG15+DO15+DW15+EE15 -> 0 | G15: =P15+X15+AF15+AN15+AV15+BD15+BL15+BT15+CB15+CJ15+CR15+CZ15+DH15+DP15+DX15+EF15 -> 0 | H15: =Q15+Y15+AG15+AO15+AW15+BE15+BM15+BU15+CC15+CK15+CS15+DA15+DI15+DQ15+DY15+EG15 -> 0 | I15: =SUM(B15:H15) -> 0 | R15: =SUM(K15:Q15) -> 0 | Z15: =SUM(S15:Y15) -> 0 | AH15: =SUM(AA15:AG15) -> 0 | AP15: =SUM(AI15:AO15) -> 0 | AX15: =SUM(AQ15:AW15) -> 0 | BF15: =SUM(AY15:BE15) -> 0 | BN15: =SUM(BG15:BM15) -> 0 | BV15: =SUM(BO15:BU15) -> 0 | CD15: =SUM(BW15:CC15) -> 0 | CL15: =SUM(CE15:CK15) -> 0 | CT15: =SUM(CM15:CS15) -> 0 | DB15: =SUM(CU15:DA15) -> 0 | DJ15: =SUM(DC15:DI15) -> 0 | DR15: =SUM(DK15:DQ15) -> 0 | DZ15: =SUM(DS15:DY15) -> 0 | EH15: =SUM(EA15:EG15) -> 0
A16: 44318
A17: 44319 | B17: =K17+S17+AA17+AI17+AQ17+AY17+BG17+BO17+BW17+CE17+CM17+CU17+DC17+DK17+DS17+EA17 -> 0 | C17: =L17+T17+AB17+AJ17+AR17+AZ17+BH17+BP17+BX17+CF17+CN17+CV17+DD17+DL17+DT17+EB17 -> 0 | D17: =M17+U17+AC17+AK17+AS17+BA17+BI17+BQ17+BY17+CG17+CO17+CW17+DE17+DM17+DU17+EC17 -> 0 | E17: =N17+V17+AD17+AL17+AT17+BB17+BJ17+BR17+BZ17+CH17+CP17+CX17+DF17+DN17+DV17+ED17 -> 0 | F17: =O17+W17+AE17+AM17+AU17+BC17+BK17+BS17+CA17+CI17+CQ17+CY17+DG17+DO17+DW17+EE17 -> 0 | G17: =P17+X17+AF17+AN17+AV17+BD17+BL17+BT17+CB17+CJ17+CR17+CZ17+DH17+DP17+DX17+EF17 -> 0 | H17: =Q17+Y17+AG17+AO17+AW17+BE17+BM17+BU17+CC17+CK17+CS17+DA17+DI17+DQ17+DY17+EG17 -> 0 | I17: =SUM(B17:H17) -> 0 | R17: =SUM(K17:Q17) -> 0 | Z17: =SUM(S17:Y17) -> 0 | AH17: =SUM(AA17:AG17) -> 0 | AP17: =SUM(AI17:AO17) -> 0 | AX17: =SUM(AQ17:AW17) -> 0 | BF17: =SUM(AY17:BE17) -> 0 | BN17: =SUM(BG17:BM17) -> 0 | BV17: =SUM(BO17:BU17) -> 0 | CD17: =SUM(BW17:CC17) -> 0 | CL17: =SUM(CE17:CK17) -> 0 | CT17: =SUM(CM17:CS17) -> 0 | DB17: =SUM(CU17:DA17) -> 0 | DJ17: =SUM(DC17:DI17) -> 0 | DR17: =SUM(DK17:DQ17) -> 0 | DZ17: =SUM(DS17:DY17) -> 0 | EH17: =SUM(EA17:EG17) -> 0
A18: 44320 | B18: =K18+S18+AA18+AI18+AQ18+AY18+BG18+BO18+BW18+CE18+CM18+CU18+DC18+DK18+DS18+EA18 -> 0 | C18: =L18+T18+AB18+AJ18+AR18+AZ18+BH18+BP18+BX18+CF18+CN18+CV18+DD18+DL18+DT18+EB18 -> 0 | D18: =M18+U18+AC18+AK18+AS18+BA18+BI18+BQ18+BY18+CG18+CO18+CW18+DE18+DM18+DU18+EC18 -> 0 | E18: =N18+V18+AD18+AL18+AT18+BB18+BJ18+BR18+BZ18+CH18+CP18+CX18+DF18+DN18+DV18+ED18 -> 0 | F18: =O18+W18+AE18+AM18+AU18+BC18+BK18+BS18+CA18+CI18+CQ18+CY18+DG18+DO18+DW18+EE18 -> 0 | G18: =P18+X18+AF18+AN18+AV18+BD18+BL18+BT18+CB18+CJ18+CR18+CZ18+DH18+DP18+DX18+EF18 -> 0 | H18: =Q18+Y18+AG18+AO18+AW18+BE18+BM18+BU18+CC18+CK18+CS18+DA18+DI18+DQ18+DY18+EG18 -> 0 | I18: =SUM(B18:H18) -> 0 | R18: =SUM(K18:Q18) -> 0 | Z18: =SUM(S18:Y18) -> 0 | AH18: =SUM(AA18:AG18) -> 0 | AP18: =SUM(AI18:AO18) -> 0 | AX18: =SUM(AQ18:AW18) -> 0 | BF18: =SUM(AY18:BE18) -> 0 | BN18: =SUM(BG18:BM18) -> 0 | BV18: =SUM(BO18:BU18) -> 0 | CD18: =SUM(BW18:CC18) -> 0 | CL18: =SUM(CE18:CK18) -> 0 | CT18: =SUM(CM18:CS18) -> 0 | DB18: =SUM(CU18:DA18) -> 0 | DJ18: =SUM(DC18:DI18) -> 0 | DR18: =SUM(DK18:DQ18) -> 0 | DZ18: =SUM(DS18:DY18) -> 0 | EH18: =SUM(EA18:EG18) -> 0
A19: 44321 | B19: =K19+S19+AA19+AI19+AQ19+AY19+BG19+BO19+BW19+CE19+CM19+CU19+DC19+DK19+DS19+EA19 -> 0 | C19: =L19+T19+AB19+AJ19+AR19+AZ19+BH19+BP19+BX19+CF19+CN19+CV19+DD19+DL19+DT19+EB19 -> 0 | D19: =M19+U19+AC19+AK19+AS19+BA19+BI19+BQ19+BY19+CG19+CO19+CW19+DE19+DM19+DU19+EC19 -> 0 | E19: =N19+V19+AD19+AL19+AT19+BB19+BJ19+BR19+BZ19+CH19+CP19+CX19+DF19+DN19+DV19+ED19 -> 0 | F19: =O19+W19+AE19+AM19+AU19+BC19+BK19+BS19+CA19+CI19+CQ19+CY19+DG19+DO19+DW19+EE19 -> 0 | G19: =P19+X19+AF19+AN19+AV19+BD19+BL19+BT19+CB19+CJ19+CR19+CZ19+DH19+DP19+DX19+EF19 -> 0 | H19: =Q19+Y19+AG19+AO19+AW19+BE19+BM19+BU19+CC19+CK19+CS19+DA19+DI19+DQ19+DY19+EG19 -> 0 | I19: =SUM(B19:H19) -> 0 | R19: =SUM(K19:Q19) -> 0 | Z19: =SUM(S19:Y19) -> 0 | AH19: =SUM(AA19:AG19) -> 0 | AP19: =SUM(AI19:AO19) -> 0 | AX19: =SUM(AQ19:AW19) -> 0 | BF19: =SUM(AY19:BE19) -> 0 | BN19: =SUM(BG19:BM19) -> 0 | BV19: =SUM(BO19:BU19) -> 0 | CD19: =SUM(BW19:CC19) -> 0 | CL19: =SUM(CE19:CK19) -> 0 | CT19: =SUM(CM19:CS19) -> 0 | DB19: =SUM(CU19:DA19) -> 0 | DJ19: =SUM(DC19:DI19) -> 0 | DR19: =SUM(DK19:DQ19) -> 0 | DZ19: =SUM(DS19:DY19) -> 0 | EH19: =SUM(EA19:EG19) -> 0
A20: 44322 | B20: =K20+S20+AA20+AI20+AQ20+AY20+BG20+BO20+BW20+CE20+CM20+CU20+DC20+DK20+DS20+EA20 -> 0 | C20: =L20+T20+AB20+AJ20+AR20+AZ20+BH20+BP20+BX20+CF20+CN20+CV20+DD20+DL20+DT20+EB20 -> 0 | D20: =M20+U20+AC20+AK20+AS20+BA20+BI20+BQ20+BY20+CG20+CO20+CW20+DE20+DM20+DU20+EC20 -> 0 | E20: =N20+V20+AD20+AL20+AT20+BB20+BJ20+BR20+BZ20+CH20+CP20+CX20+DF20+DN20+DV20+ED20 -> 0 | F20: =O20+W20+AE20+AM20+AU20+BC20+BK20+BS20+CA20+CI20+CQ20+CY20+DG20+DO20+DW20+EE20 -> 0 | G20: =P20+X20+AF20+AN20+AV20+BD20+BL20+BT20+CB20+CJ20+CR20+CZ20+DH20+DP20+DX20+EF20 -> 0 | H20: =Q20+Y20+AG20+AO20+AW20+BE20+BM20+BU20+CC20+CK20+CS20+DA20+DI20+DQ20+DY20+EG20 -> 0 | I20: =SUM(B20:H20) -> 0 | R20: =SUM(K20:Q20) -> 0 | Z20: =SUM(S20:Y20) -> 0 | AH20: =SUM(AA20:AG20) -> 0 | AP20: =SUM(AI20:AO20) -> 0 | AX20: =SUM(AQ20:AW20) -> 0 | BF20: =SUM(AY20:BE20) -> 0 | BN20: =SUM(BG20:BM20) -> 0 | BV20: =SUM(BO20:BU20) -> 0 | CD20: =SUM(BW20:CC20) -> 0 | CL20: =SUM(CE20:CK20) -> 0 | CT20: =SUM(CM20:CS20) -> 0 | DB20: =SUM(CU20:DA20) -> 0 | DJ20: =SUM(DC20:DI20) -> 0 | DR20: =SUM(DK20:DQ20) -> 0 | DZ20: =SUM(DS20:DY20) -> 0 | EH20: =SUM(EA20:EG20) -> 0
A21: 44323 | B21: =K21+S21+AA21+AI21+AQ21+AY21+BG21+BO21+BW21+CE21+CM21+CU21+DC21+DK21+DS21+EA21 -> 0 | C21: =L21+T21+AB21+AJ21+AR21+AZ21+BH21+BP21+BX21+CF21+CN21+CV21+DD21+DL21+DT21+EB21 -> 0 | D21: =M21+U21+AC21+AK21+AS21+BA21+BI21+BQ21+BY21+CG21+CO21+CW21+DE21+DM21+DU21+EC21 -> 0 | E21: =N21+V21+AD21+AL21+AT21+BB21+BJ21+BR21+BZ21+CH21+CP21+CX21+DF21+DN21+DV21+ED21 -> 0 | F21: =O21+W21+AE21+AM21+AU21+BC21+BK21+BS21+CA21+CI21+CQ21+CY21+DG21+DO21+DW21+EE21 -> 0 | G21: =P21+X21+AF21+AN21+AV21+BD21+BL21+BT21+CB21+CJ21+CR21+CZ21+DH21+DP21+DX21+EF21 -> 0 | H21: =Q21+Y21+AG21+AO21+AW21+BE21+BM21+BU21+CC21+CK21+CS21+DA21+DI21+DQ21+DY21+EG21 -> 0 | I21: =SUM(B21:H21) -> 0 | R21: =SUM(K21:Q21) -> 0 | Z21: =SUM(S21:Y21) -> 0 | AH21: =SUM(AA21:AG21) -> 0 | AP21: =SUM(AI21:AO21) -> 0 | AX21: =SUM(AQ21:AW21) -> 0 | BF21: =SUM(AY21:BE21) -> 0 | BN21: =SUM(BG21:BM21) -> 0 | BV21: =SUM(BO21:BU21) -> 0 | CD21: =SUM(BW21:CC21) -> 0 | CL21: =SUM(CE21:CK21) -> 0 | CT21: =SUM(CM21:CS21) -> 0 | DB21: =SUM(CU21:DA21) -> 0 | DJ21: =SUM(DC21:DI21) -> 0 | DR21: =SUM(DK21:DQ21) -> 0 | DZ21: =SUM(DS21:DY21) -> 0 | EH21: =SUM(EA21:EG21) -> 0
A22: 44324
A23: 44325
A24: 44326 | B24: =K24+S24+AA24+AI24+AQ24+AY24+BG24+BO24+BW24+CE24+CM24+CU24+DC24+DK24+DS24+EA24 -> 0 | C24: =L24+T24+AB24+AJ24+AR24+AZ24+BH24+BP24+BX24+CF24+CN24+CV24+DD24+DL24+DT24+EB24 -> 0 | D24: =M24+U24+AC24+AK24+AS24+BA24+BI24+BQ24+BY24+CG24+CO24+CW24+DE24+DM24+DU24+EC24 -> 0 | E24: =N24+V24+AD24+AL24+AT24+BB24+BJ24+BR24+BZ24+CH24+CP24+CX24+DF24+DN24+DV24+ED24 -> 0 | F24: =O24+W24+AE24+AM24+AU24+BC24+BK24+BS24+CA24+CI24+CQ24+CY24+DG24+DO24+DW24+EE24 -> 0 | G24: =P24+X24+AF24+AN24+AV24+BD24+BL24+BT24+CB24+CJ24+CR24+CZ24+DH24+DP24+DX24+EF24 -> 0 | H24: =Q24+Y24+AG24+AO24+AW24+BE24+BM24+BU24+CC24+CK24+CS24+DA24+DI24+DQ24+DY24+EG24 -> 0 | I24: =SUM(B24:H24) -> 0 | R24: =SUM(K24:Q24) -> 0 | Z24: =SUM(S24:Y24) -> 0 | AH24: =SUM(AA24:AG24) -> 0 | AP24: =SUM(AI24:AO24) -> 0 | AX24: =SUM(AQ24:AW24) -> 0 | BF24: =SUM(AY24:BE24) -> 0 | BN24: =SUM(BG24:BM24) -> 0 | BV24: =SUM(BO24:BU24) -> 0 | CD24: =SUM(BW24:CC24) -> 0 | CL24: =SUM(CE24:CK24) -> 0 | CT24: =SUM(CM24:CS24) -> 0 | DB24: =SUM(CU24:DA24) -> 0 | DJ24: =SUM(DC24:DI24) -> 0 | DR24: =SUM(DK24:DQ24) -> 0 | DZ24: =SUM(DS24:DY24) -> 0 | EH24: =SUM(EA24:EG24) -> 0
A25: 44327 | B25: =K25+S25+AA25+AI25+AQ25+AY25+BG25+BO25+BW25+CE25+CM25+CU25+DC25+DK25+DS25+EA25 -> 0 | C25: =L25+T25+AB25+AJ25+AR25+AZ25+BH25+BP25+BX25+CF25+CN25+CV25+DD25+DL25+DT25+EB25 -> 0 | D25: =M25+U25+AC25+AK25+AS25+BA25+BI25+BQ25+BY25+CG25+CO25+CW25+DE25+DM25+DU25+EC25 -> 0 | E25: =N25+V25+AD25+AL25+AT25+BB25+BJ25+BR25+BZ25+CH25+CP25+CX25+DF25+DN25+DV25+ED25 -> 0 | F25: =O25+W25+AE25+AM25+AU25+BC25+BK25+BS25+CA25+CI25+CQ25+CY25+DG25+DO25+DW25+EE25 -> 0 | G25: =P25+X25+AF25+AN25+AV25+BD25+BL25+BT25+CB25+CJ25+CR25+CZ25+DH25+DP25+DX25+EF25 -> 0 | H25: =Q25+Y25+AG25+AO25+AW25+BE25+BM25+BU25+CC25+CK25+CS25+DA25+DI25+DQ25+DY25+EG25 -> 0 | I25: =SUM(B25:H25) -> 0 | R25: =SUM(K25:Q25) -> 0 | Z25: =SUM(S25:Y25) -> 0 | AH25: =SUM(AA25:AG25) -> 0 | AP25: =SUM(AI25:AO25) -> 0 | AX25: =SUM(AQ25:AW25) -> 0 | BF25: =SUM(AY25:BE25) -> 0 | BN25: =SUM(BG25:BM25) -> 0 | BV25: =SUM(BO25:BU25) -> 0 | CD25: =SUM(BW25:CC25) -> 0 | CL25: =SUM(CE25:CK25) -> 0 | CT25: =SUM(CM25:CS25) -> 0 | DB25: =SUM(CU25:DA25) -> 0 | DJ25: =SUM(DC25:DI25) -> 0 | DR25: =SUM(DK25:DQ25) -> 0 | DZ25: =SUM(DS25:DY25) -> 0 | EH25: =SUM(EA25:EG25) -> 0
A26: 44328 | B26: =K26+S26+AA26+AI26+AQ26+AY26+BG26+BO26+BW26+CE26+CM26+CU26+DC26+DK26+DS26+EA26 -> 0 | C26: =L26+T26+AB26+AJ26+AR26+AZ26+BH26+BP26+BX26+CF26+CN26+CV26+DD26+DL26+DT26+EB26 -> 0 | D26: =M26+U26+AC26+AK26+AS26+BA26+BI26+BQ26+BY26+CG26+CO26+CW26+DE26+DM26+DU26+EC26 -> 0 | E26: =N26+V26+AD26+AL26+AT26+BB26+BJ26+BR26+BZ26+CH26+CP26+CX26+DF26+DN26+DV26+ED26 -> 0 | F26: =O26+W26+AE26+AM26+AU26+BC26+BK26+BS26+CA26+CI26+CQ26+CY26+DG26+DO26+DW26+EE26 -> 0 | G26: =P26+X26+AF26+AN26+AV26+BD26+BL26+BT26+CB26+CJ26+CR26+CZ26+DH26+DP26+DX26+EF26 -> 0 | H26: =Q26+Y26+AG26+AO26+AW26+BE26+BM26+BU26+CC26+CK26+CS26+DA26+DI26+DQ26+DY26+EG26 -> 0 | I26: =SUM(B26:H26) -> 0 | R26: =SUM(K26:Q26) -> 0 | Z26: =SUM(S26:Y26) -> 0 | AH26: =SUM(AA26:AG26) -> 0 | AP26: =SUM(AI26:AO26) -> 0 | AX26: =SUM(AQ26:AW26) -> 0 | BF26: =SUM(AY26:BE26) -> 0 | BN26: =SUM(BG26:BM26) -> 0 | BV26: =SUM(BO26:BU26) -> 0 | CD26: =SUM(BW26:CC26) -> 0 | CL26: =SUM(CE26:CK26) -> 0 | CT26: =SUM(CM26:CS26) -> 0 | DB26: =SUM(CU26:DA26) -> 0 | DJ26: =SUM(DC26:DI26) -> 0 | DR26: =SUM(DK26:DQ26) -> 0 | DZ26: =SUM(DS26:DY26) -> 0 | EH26: =SUM(EA26:EG26) -> 0
A27: 44329 | B27: =K27+S27+AA27+AI27+AQ27+AY27+BG27+BO27+BW27+CE27+CM27+CU27+DC27+DK27+DS27+EA27 -> 0 | C27: =L27+T27+AB27+AJ27+AR27+AZ27+BH27+BP27+BX27+CF27+CN27+CV27+DD27+DL27+DT27+EB27 -> 0 | D27: =M27+U27+AC27+AK27+AS27+BA27+BI27+BQ27+BY27+CG27+CO27+CW27+DE27+DM27+DU27+EC27 -> 0 | E27: =N27+V27+AD27+AL27+AT27+BB27+BJ27+BR27+BZ27+CH27+CP27+CX27+DF27+DN27+DV27+ED27 -> 0 | F27: =O27+W27+AE27+AM27+AU27+BC27+BK27+BS27+CA27+CI27+CQ27+CY27+DG27+DO27+DW27+EE27 -> 0 | G27: =P27+X27+AF27+AN27+AV27+BD27+BL27+BT27+CB27+CJ27+CR27+CZ27+DH27+DP27+DX27+EF27 -> 0 | H27: =Q27+Y27+AG27+AO27+AW27+BE27+BM27+BU27+CC27+CK27+CS27+DA27+DI27+DQ27+DY27+EG27 -> 0 | I27: =SUM(B27:H27) -> 0 | R27: =SUM(K27:Q27) -> 0 | Z27: =SUM(S27:Y27) -> 0 | AH27: =SUM(AA27:AG27) -> 0 | AP27: =SUM(AI27:AO27) -> 0 | AX27: =SUM(AQ27:AW27) -> 0 | BF27: =SUM(AY27:BE27) -> 0 | BN27: =SUM(BG27:BM27) -> 0 | BV27: =SUM(BO27:BU27) -> 0 | CD27: =SUM(BW27:CC27) -> 0 | CL27: =SUM(CE27:CK27) -> 0 | CT27: =SUM(CM27:CS27) -> 0 | DB27: =SUM(CU27:DA27) -> 0 | DJ27: =SUM(DC27:DI27) -> 0 | DR27: =SUM(DK27:DQ27) -> 0 | DZ27: =SUM(DS27:DY27) -> 0 | EH27: =SUM(EA27:EG27) -> 0
A28: 44330 | B28: =K28+S28+AA28+AI28+AQ28+AY28+BG28+BO28+BW28+CE28+CM28+CU28+DC28+DK28+DS28+EA28 -> 0 | C28: =L28+T28+AB28+AJ28+AR28+AZ28+BH28+BP28+BX28+CF28+CN28+CV28+DD28+DL28+DT28+EB28 -> 0 | D28: =M28+U28+AC28+AK28+AS28+BA28+BI28+BQ28+BY28+CG28+CO28+CW28+DE28+DM28+DU28+EC28 -> 0 | E28: =N28+V28+AD28+AL28+AT28+BB28+BJ28+BR28+BZ28+CH28+CP28+CX28+DF28+DN28+DV28+ED28 -> 0 | F28: =O28+W28+AE28+AM28+AU28+BC28+BK28+BS28+CA28+CI28+CQ28+CY28+DG28+DO28+DW28+EE28 -> 0 | G28: =P28+X28+AF28+AN28+AV28+BD28+BL28+BT28+CB28+CJ28+CR28+CZ28+DH28+DP28+DX28+EF28 -> 0 | H28: =Q28+Y28+AG28+AO28+AW28+BE28+BM28+BU28+CC28+CK28+CS28+DA28+DI28+DQ28+DY28+EG28 -> 0 | I28: =SUM(B28:H28) -> 0 | R28: =SUM(K28:Q28) -> 0 | Z28: =SUM(S28:Y28) -> 0 | AH28: =SUM(AA28:AG28) -> 0 | AP28: =SUM(AI28:AO28) -> 0 | AX28: =SUM(AQ28:AW28) -> 0 | BF28: =SUM(AY28:BE28) -> 0 | BN28: =SUM(BG28:BM28) -> 0 | BV28: =SUM(BO28:BU28) -> 0 | CD28: =SUM(BW28:CC28) -> 0 | CL28: =SUM(CE28:CK28) -> 0 | CT28: =SUM(CM28:CS28) -> 0 | DB28: =SUM(CU28:DA28) -> 0 | DJ28: =SUM(DC28:DI28) -> 0 | DR28: =SUM(DK28:DQ28) -> 0 | DZ28: =SUM(DS28:DY28) -> 0 | EH28: =SUM(EA28:EG28) -> 0
A29: 44331
A30: 44332
A31: 44333 | B31: =K31+S31+AA31+AI31+AQ31+AY31+BG31+BO31+BW31+CE31+CM31+CU31+DC31+DK31+DS31+EA31 -> 0 | C31: =L31+T31+AB31+AJ31+AR31+AZ31+BH31+BP31+BX31+CF31+CN31+CV31+DD31+DL31+DT31+EB31 -> 0 | D31: =M31+U31+AC31+AK31+AS31+BA31+BI31+BQ31+BY31+CG31+CO31+CW31+DE31+DM31+DU31+EC31 -> 0 | E31: =N31+V31+AD31+AL31+AT31+BB31+BJ31+BR31+BZ31+CH31+CP31+CX31+DF31+DN31+DV31+ED31 -> 0 | F31: =O31+W31+AE31+AM31+AU31+BC31+BK31+BS31+CA31+CI31+CQ31+CY31+DG31+DO31+DW31+EE31 -> 0 | G31: =P31+X31+AF31+AN31+AV31+BD31+BL31+BT31+CB31+CJ31+CR31+CZ31+DH31+DP31+DX31+EF31 -> 0 | H31: =Q31+Y31+AG31+AO31+AW31+BE31+BM31+BU31+CC31+CK31+CS31+DA31+DI31+DQ31+DY31+EG31 -> 0 | I31: =SUM(B31:H31) -> 0 | R31: =SUM(K31:Q31) -> 0 | Z31: =SUM(S31:Y31) -> 0 | AH31: =SUM(AA31:AG31) -> 0 | AP31: =SUM(AI31:AO31) -> 0 | AX31: =SUM(AQ31:AW31) -> 0 | BF31: =SUM(AY31:BE31) -> 0 | BN31: =SUM(BG31:BM31) -> 0 | BV31: =SUM(BO31:BU31) -> 0 | CD31: =SUM(BW31:CC31) -> 0 | CL31: =SUM(CE31:CK31) -> 0 | CT31: =SUM(CM31:CS31) -> 0 | DB31: =SUM(CU31:DA31) -> 0 | DJ31: =SUM(DC31:DI31) -> 0 | DR31: =SUM(DK31:DQ31) -> 0 | DZ31: =SUM(DS31:DY31) -> 0 | EH31: =SUM(EA31:EG31) -> 0
A32: 44334 | B32: =K32+S32+AA32+AI32+AQ32+AY32+BG32+BO32+BW32+CE32+CM32+CU32+DC32+DK32+DS32+EA32 -> 0 | C32: =L32+T32+AB32+AJ32+AR32+AZ32+BH32+BP32+BX32+CF32+CN32+CV32+DD32+DL32+DT32+EB32 -> 0 | D32: =M32+U32+AC32+AK32+AS32+BA32+BI32+BQ32+BY32+CG32+CO32+CW32+DE32+DM32+DU32+EC32 -> 0 | E32: =N32+V32+AD32+AL32+AT32+BB32+BJ32+BR32+BZ32+CH32+CP32+CX32+DF32+DN32+DV32+ED32 -> 0 | F32: =O32+W32+AE32+AM32+AU32+BC32+BK32+BS32+CA32+CI32+CQ32+CY32+DG32+DO32+DW32+EE32 -> 0 | G32: =P32+X32+AF32+AN32+AV32+BD32+BL32+BT32+CB32+CJ32+CR32+CZ32+DH32+DP32+DX32+EF32 -> 0 | H32: =Q32+Y32+AG32+AO32+AW32+BE32+BM32+BU32+CC32+CK32+CS32+DA32+DI32+DQ32+DY32+EG32 -> 0 | I32: =SUM(B32:H32) -> 0 | R32: =SUM(K32:Q32) -> 0 | Z32: =SUM(S32:Y32) -> 0 | AH32: =SUM(AA32:AG32) -> 0 | AP32: =SUM(AI32:AO32) -> 0 | AX32: =SUM(AQ32:AW32) -> 0 | BF32: =SUM(AY32:BE32) -> 0 | BN32: =SUM(BG32:BM32) -> 0 | BV32: =SUM(BO32:BU32) -> 0 | CD32: =SUM(BW32:CC32) -> 0 | CL32: =SUM(CE32:CK32) -> 0 | CT32: =SUM(CM32:CS32) -> 0 | DB32: =SUM(CU32:DA32) -> 0 | DJ32: =SUM(DC32:DI32) -> 0 | DR32: =SUM(DK32:DQ32) -> 0 | DZ32: =SUM(DS32:DY32) -> 0 | EH32: =SUM(EA32:EG32) -> 0
A33: 44335 | B33: =K33+S33+AA33+AI33+AQ33+AY33+BG33+BO33+BW33+CE33+CM33+CU33+DC33+DK33+DS33+EA33 -> 0 | C33: =L33+T33+AB33+AJ33+AR33+AZ33+BH33+BP33+BX33+CF33+CN33+CV33+DD33+DL33+DT33+EB33 -> 0 | D33: =M33+U33+AC33+AK33+AS33+BA33+BI33+BQ33+BY33+CG33+CO33+CW33+DE33+DM33+DU33+EC33 -> 0 | E33: =N33+V33+AD33+AL33+AT33+BB33+BJ33+BR33+BZ33+CH33+CP33+CX33+DF33+DN33+DV33+ED33 -> 0 | F33: =O33+W33+AE33+AM33+AU33+BC33+BK33+BS33+CA33+CI33+CQ33+CY33+DG33+DO33+DW33+EE33 -> 0 | G33: =P33+X33+AF33+AN33+AV33+BD33+BL33+BT33+CB33+CJ33+CR33+CZ33+DH33+DP33+DX33+EF33 -> 0 | H33: =Q33+Y33+AG33+AO33+AW33+BE33+BM33+BU33+CC33+CK33+CS33+DA33+DI33+DQ33+DY33+EG33 -> 0 | I33: =SUM(B33:H33) -> 0 | R33: =SUM(K33:Q33) -> 0 | Z33: =SUM(S33:Y33) -> 0 | AH33: =SUM(AA33:AG33) -> 0 | AP33: =SUM(AI33:AO33) -> 0 | AX33: =SUM(AQ33:AW33) -> 0 | BF33: =SUM(AY33:BE33) -> 0 | BN33: =SUM(BG33:BM33) -> 0 | BV33: =SUM(BO33:BU33) -> 0 | CD33: =SUM(BW33:CC33) -> 0 | CL33: =SUM(CE33:CK33) -> 0 | CT33: =SUM(CM33:CS33) -> 0 | DB33: =SUM(CU33:DA33) -> 0 | DJ33: =SUM(DC33:DI33) -> 0 | DR33: =SUM(DK33:DQ33) -> 0 | DZ33: =SUM(DS33:DY33) -> 0 | EH33: =SUM(EA33:EG33) -> 0
A34: 44336 | B34: =K34+S34+AA34+AI34+AQ34+AY34+BG34+BO34+BW34+CE34+CM34+CU34+DC34+DK34+DS34+EA34 -> 0 | C34: =L34+T34+AB34+AJ34+AR34+AZ34+BH34+BP34+BX34+CF34+CN34+CV34+DD34+DL34+DT34+EB34 -> 0 | D34: =M34+U34+AC34+AK34+AS34+BA34+BI34+BQ34+BY34+CG34+CO34+CW34+DE34+DM34+DU34+EC34 -> 0 | E34: =N34+V34+AD34+AL34+AT34+BB34+BJ34+BR34+BZ34+CH34+CP34+CX34+DF34+DN34+DV34+ED34 -> 0 | F34: =O34+W34+AE34+AM34+AU34+BC34+BK34+BS34+CA34+CI34+CQ34+CY34+DG34+DO34+DW34+EE34 -> 0 | G34: =P34+X34+AF34+AN34+AV34+BD34+BL34+BT34+CB34+CJ34+CR34+CZ34+DH34+DP34+DX34+EF34 -> 0 | H34: =Q34+Y34+AG34+AO34+AW34+BE34+BM34+BU34+CC34+CK34+CS34+DA34+DI34+DQ34+DY34+EG34 -> 0 | I34: =SUM(B34:H34) -> 0 | R34: =SUM(K34:Q34) -> 0 | Z34: =SUM(S34:Y34) -> 0 | AH34: =SUM(AA34:AG34) -> 0 | AP34: =SUM(AI34:AO34) -> 0 | AX34: =SUM(AQ34:AW34) -> 0 | BF34: =SUM(AY34:BE34) -> 0 | BN34: =SUM(BG34:BM34) -> 0 | BV34: =SUM(BO34:BU34) -> 0 | CD34: =SUM(BW34:CC34) -> 0 | CL34: =SUM(CE34:CK34) -> 0 | CT34: =SUM(CM34:CS34) -> 0 | DB34: =SUM(CU34:DA34) -> 0 | DJ34: =SUM(DC34:DI34) -> 0 | DR34: =SUM(DK34:DQ34) -> 0 | DZ34: =SUM(DS34:DY34) -> 0 | EH34: =SUM(EA34:EG34) -> 0
A35: 44337 | B35: =K35+S35+AA35+AI35+AQ35+AY35+BG35+BO35+BW35+CE35+CM35+CU35+DC35+DK35+DS35+EA35 -> 0 | C35: =L35+T35+AB35+AJ35+AR35+AZ35+BH35+BP35+BX35+CF35+CN35+CV35+DD35+DL35+DT35+EB35 -> 0 | D35: =M35+U35+AC35+AK35+AS35+BA35+BI35+BQ35+BY35+CG35+CO35+CW35+DE35+DM35+DU35+EC35 -> 0 | E35: =N35+V35+AD35+AL35+AT35+BB35+BJ35+BR35+BZ35+CH35+CP35+CX35+DF35+DN35+DV35+ED35 -> 0 | F35: =O35+W35+AE35+AM35+AU35+BC35+BK35+BS35+CA35+CI35+CQ35+CY35+DG35+DO35+DW35+EE35 -> 0 | G35: =P35+X35+AF35+AN35+AV35+BD35+BL35+BT35+CB35+CJ35+CR35+CZ35+DH35+DP35+DX35+EF35 -> 0 | H35: =Q35+Y35+AG35+AO35+AW35+BE35+BM35+BU35+CC35+CK35+CS35+DA35+DI35+DQ35+DY35+EG35 -> 0 | I35: =SUM(B35:H35) -> 0 | R35: =SUM(K35:Q35) -> 0 | Z35: =SUM(S35:Y35) -> 0 | AH35: =SUM(AA35:AG35) -> 0 | AP35: =SUM(AI35:AO35) -> 0 | AX35: =SUM(AQ35:AW35) -> 0 | BF35: =SUM(AY35:BE35) -> 0 | BN35: =SUM(BG35:BM35) -> 0 | BV35: =SUM(BO35:BU35) -> 0 | CD35: =SUM(BW35:CC35) -> 0 | CL35: =SUM(CE35:CK35) -> 0 | CT35: =SUM(CM35:CS35) -> 0 | DB35: =SUM(CU35:DA35) -> 0 | DJ35: =SUM(DC35:DI35) -> 0 | DR35: =SUM(DK35:DQ35) -> 0 | DZ35: =SUM(DS35:DY35) -> 0 | EH35: =SUM(EA35:EG35) -> 0
A36: 44338
A37: 44339
A38: 44340 | B38: =K38+S38+AA38+AI38+AQ38+AY38+BG38+BO38+BW38+CE38+CM38+CU38+DC38+DK38+DS38+EA38 -> 0 | C38: =L38+T38+AB38+AJ38+AR38+AZ38+BH38+BP38+BX38+CF38+CN38+CV38+DD38+DL38+DT38+EB38 -> 0 | D38: =M38+U38+AC38+AK38+AS38+BA38+BI38+BQ38+BY38+CG38+CO38+CW38+DE38+DM38+DU38+EC38 -> 0 | E38: =N38+V38+AD38+AL38+AT38+BB38+BJ38+BR38+BZ38+CH38+CP38+CX38+DF38+DN38+DV38+ED38 -> 0 | F38: =O38+W38+AE38+AM38+AU38+BC38+BK38+BS38+CA38+CI38+CQ38+CY38+DG38+DO38+DW38+EE38 -> 0 | G38: =P38+X38+AF38+AN38+AV38+BD38+BL38+BT38+CB38+CJ38+CR38+CZ38+DH38+DP38+DX38+EF38 -> 0 | H38: =Q38+Y38+AG38+AO38+AW38+BE38+BM38+BU38+CC38+CK38+CS38+DA38+DI38+DQ38+DY38+EG38 -> 0 | I38: =SUM(B38:H38) -> 0 | R38: =SUM(K38:Q38) -> 0 | Z38: =SUM(S38:Y38) -> 0 | AH38: =SUM(AA38:AG38) -> 0 | AP38: =SUM(AI38:AO38) -> 0 | AX38: =SUM(AQ38:AW38) -> 0 | BF38: =SUM(AY38:BE38) -> 0 | BN38: =SUM(BG38:BM38) -> 0 | BV38: =SUM(BO38:BU38) -> 0 | CD38: =SUM(BW38:CC38) -> 0 | CL38: =SUM(CE38:CK38) -> 0 | CT38: =SUM(CM38:CS38) -> 0 | DB38: =SUM(CU38:DA38) -> 0 | DJ38: =SUM(DC38:DI38) -> 0 | DR38: =SUM(DK38:DQ38) -> 0 | DZ38: =SUM(DS38:DY38) -> 0 | EH38: =SUM(EA38:EG38) -> 0
A39: 44341 | B39: =K39+S39+AA39+AI39+AQ39+AY39+BG39+BO39+BW39+CE39+CM39+CU39+DC39+DK39+DS39+EA39 -> 0 | C39: =L39+T39+AB39+AJ39+AR39+AZ39+BH39+BP39+BX39+CF39+CN39+CV39+DD39+DL39+DT39+EB39 -> 0 | D39: =M39+U39+AC39+AK39+AS39+BA39+BI39+BQ39+BY39+CG39+CO39+CW39+DE39+DM39+DU39+EC39 -> 0 | E39: =N39+V39+AD39+AL39+AT39+BB39+BJ39+BR39+BZ39+CH39+CP39+CX39+DF39+DN39+DV39+ED39 -> 0 | F39: =O39+W39+AE39+AM39+AU39+BC39+BK39+BS39+CA39+CI39+CQ39+CY39+DG39+DO39+DW39+EE39 -> 0 | G39: =P39+X39+AF39+AN39+AV39+BD39+BL39+BT39+CB39+CJ39+CR39+CZ39+DH39+DP39+DX39+EF39 -> 0 | H39: =Q39+Y39+AG39+AO39+AW39+BE39+BM39+BU39+CC39+CK39+CS39+DA39+DI39+DQ39+DY39+EG39 -> 0 | I39: =SUM(B39:H39) -> 0 | R39: =SUM(K39:Q39) -> 0 | Z39: =SUM(S39:Y39) -> 0 | AH39: =SUM(AA39:AG39) -> 0 | AP39: =SUM(AI39:AO39) -> 0 | AX39: =SUM(AQ39:AW39) -> 0 | BF39: =SUM(AY39:BE39) -> 0 | BN39: =SUM(BG39:BM39) -> 0 | BV39: =SUM(BO39:BU39) -> 0 | CD39: =SUM(BW39:CC39) -> 0 | CL39: =SUM(CE39:CK39) -> 0 | CT39: =SUM(CM39:CS39) -> 0 | DB39: =SUM(CU39:DA39) -> 0 | DJ39: =SUM(DC39:DI39) -> 0 | DR39: =SUM(DK39:DQ39) -> 0 | DZ39: =SUM(DS39:DY39) -> 0 | EH39: =SUM(EA39:EG39) -> 0
