Workbook

Sheet Summary
A1: Fairfax County
A2: General Election
A3: November 3, 2020
A5: Absentee Ballot Report
A7: Congressional District | B7: Mailed | C7: Returned by mail | D7: Dropbox | E7: In Person | F7: Returned | G7: total
A8: 8 | B8: =Mailout!I53 -> 82008 | C8: ='Return by Mail'!L57 -> 41644 | D8: ='Return by Dropbox'!C53 -> 24107 | E8: ='In-Person Daily by Satellite'!C50 -> 56362 | F8: =SUM(C8:D8) -> 65751 | G8: =SUM(E8:F8) -> 122113
A9: 10 | B9: =Mailout!M53 -> 51935 | C9: ='Return by Mail'!Q57 -> 32275 | D9: ='Return by Dropbox'!D53 -> 17231 | E9: ='In-Person Daily by Satellite'!D50 -> 41940 | F9: =SUM(C9:D9) -> 49506 | G9: =SUM(E9:F9) -> 91446
A10: 11 | B10: =Mailout!Q53 -> 130890 | C10: ='Return by Mail'!V57 -> 64853 | D10: ='Return by Dropbox'!E53 -> 42611 | E10: ='In-Person Daily by Satellite'!E50 -> 91803 | F10: =SUM(C10:D10) -> 107464 | G10: =SUM(E10:F10) -> 199267
A11: 11-Herndon | B11: =Mailout!U53 -> 4078 | C11: ='Return by Mail'!AA57 -> 2237 | D11: ='Return by Dropbox'!F53 -> 1218 | E11: ='In-Person Daily by Satellite'!F50 -> 3491 | F11: =SUM(C11:D11) -> 3455 | G11: =SUM(E11:F11) -> 6946 | J11: =SUM(D8:D11) -> 85167
A12: Total | B12: =SUM(B8:B11) -> 268911 | C12: =SUM(C8:C11) -> 141009 | D12: ='Return by Dropbox'!B5 -> 85292 | E12: =SUM(E8:E11) -> 193596 | F12: =SUM(C12:D12) -> 226301 | G12: =SUM(G8:G11) -> 419772
G13: Plus 20 for group of uocavas
B14: Total Ballots Cast | D14: =SUM(C12:E12) -> 419897
A16: Total Returned Absentee Ballots | D16: =C12+D12 -> 226301
C17: % Returned | D17: =D16/B12 -> 0.84154609
A18: Total Absentee-by-mail voters voting early in person | D18: ='G''rods & Surrendered'!E2 -> 17633
A19: % Returned ballots & cancelled to vote in person | D19: =(D16+D18)/B12 -> 0.90711797
D24: .

Sheet Mailout
A1: Mailed Absentee Ballots
A3: November 3 2020 ▪ General Election
B5: Total Mailed | E5: =E53 -> 268982 | F5: CD 8 | J5: CD 10 | N5: CD 11 | R5: Herndon
A6: Date | B6: Domestic | C6: UOCAVA mail | D6: UOCAVA E-mail, all styles | E6: Total | F6: Domestic | G6: UOCAVA | H6: UOCAVA E-mail, all styles | I6: Total | J6: Domestic | K6: UOCAVA | L6: UOCAVA E-mail, all styles | M6: Total | N6: Domestic | O6: UOCAVA | P6: UOCAVA E-mail, all styles | Q6: Total | R6: Domestic | S6: UOCAVA | T6: UOCAVA E-mail, all styles | U6: Total
A7: 44092 | B7: =SUM(F7,J7,N7,R7) -> 58211 | C7: =SUM(G7,K7,O7,S7) -> 0 | D7: =SUM(H7,L7,P7,T7) -> 5515 | E7: =SUM(I7,M7,Q7,U7) -> 63726 | F7: 18100 | G7: 0 | H7: 1849 | I7: =SUM(F7:H7) -> 19949 | J7: 11968 | K7: 0 | L7: 922 | M7: =SUM(J7:L7) -> 12890 | N7: 27308 | O7: 0 | P7: 2689 | Q7: =SUM(N7:P7) -> 29997 | R7: 835 | S7: 0 | T7: 55 | U7: =SUM(R7:T7) -> 890 | AW7: =SUM(AG7:AG25,AH7:AH25) -> 0
A8: 44093 | B8: =SUM(F8,J8,N8,R8) -> 87450 | C8: =SUM(G8,K8,O8,S8) -> 2173 | D8: =SUM(H8,L8,P8,T8) -> 78 | E8: =SUM(I8,M8,Q8,U8) -> 89701 | F8: =760+6071+10705+2118+5793 -> 25447 | G8: =170+590 -> 760 | H8: 31 | I8: =SUM(F8:H8) -> 26238 | J8: =332+9114+3875+1180+1662 -> 16163 | K8: =164+168 -> 332 | L8: 16 | M8: =SUM(J8:L8) -> 16511 | N8: =1071+13283+17566+5896+3+6660 -> 44479 | O8: =620+451 -> 1071 | P8: 18 | Q8: =SUM(N8:P8) -> 45568 | R8: =12+356+181+792+20 -> 1361 | S8: 10 | T8: 13 | U8: =SUM(R8:T8) -> 1384
A9: 44094
A10: 44095 | B10: =SUM(F10,J10,N10,R10) -> 4102 | C10: =SUM(G10,K10,O10,S10) -> 0 | D10: =SUM(H10,L10,P10,T10) -> 35 | E10: =SUM(I10,M10,Q10,U10) -> 4137 | F10: 1316 | G10: 0 | H10: 9 | I10: =SUM(F10:H10) -> 1325 | J10: 1080 | K10: 0 | L10: 3 | M10: =SUM(J10:L10) -> 1083 | N10: 1614 | O10: 0 | P10: 23 | Q10: =SUM(N10:P10) -> 1637 | R10: 92 | S10: 0 | T10: 0 | U10: =SUM(R10:T10) -> 92
A11: 44096 | B11: =SUM(F11,J11,N11,R11) -> 5222 | C11: =SUM(G11,K11,O11,S11) -> 2 | D11: =SUM(H11,L11,P11,T11) -> 138 | E11: =SUM(I11,M11,Q11,U11) -> 5362 | F11: =901+676 -> 1577 | G11: 1 | H11: 57 | I11: =SUM(F11:H11) -> 1635 | J11: =966+0 -> 966 | K11: 0 | L11: 13 | M11: =SUM(J11:L11) -> 979 | N11: =929+1735 -> 2664 | O11: 1 | P11: 65 | Q11: =SUM(N11:P11) -> 2730 | R11: 15 | S11: 0 | T11: 3 | U11: =SUM(R11:T11) -> 18
A12: 44097 | B12: =SUM(F12,J12,N12,R12) -> 5128 | C12: =SUM(G12,K12,O12,S12) -> 112 | D12: =SUM(H12,L12,P12,T12) -> 53 | E12: =SUM(I12,M12,Q12,U12) -> 5293 | F12: =281+1183 -> 1464 | G12: 34 | H12: 5 | I12: =SUM(F12:H12) -> 1503 | J12: 873 | K12: 23 | L12: 14 | M12: =SUM(J12:L12) -> 910 | N12: =735+1941 -> 2676 | O12: 55 | P12: 34 | Q12: =SUM(N12:P12) -> 2765 | R12: =61+54 -> 115 | S12: 0 | T12: 0 | U12: =SUM(R12:T12) -> 115
A13: 44098 | B13: =SUM(F13,J13,N13,R13) -> 2676 | C13: =SUM(G13,K13,O13,S13) -> 13 | D13: =SUM(H13,L13,P13,T13) -> 224 | E13: =SUM(I13,M13,Q13,U13) -> 2913 | F13: 841 | G13: 6 | H13: 76 | I13: =SUM(F13:H13) -> 923 | J13: 466 | K13: 2 | L13: 31 | M13: =SUM(J13:L13) -> 499 | N13: 1285 | O13: 5 | P13: 114 | Q13: =SUM(N13:P13) -> 1404 | R13: 84 | S13: 0 | T13: 3 | U13: =SUM(R13:T13) -> 87
A14: 44099 | B14: =SUM(F14,J14,N14,R14) -> 5958 | C14: =SUM(G14,K14,O14,S14) -> 22 | D14: =SUM(H14,L14,P14,T14) -> 172 | E14: =SUM(I14,M14,Q14,U14) -> 6152 | F14: =1799+4 -> 1803 | G14: 9 | H14: 58 | I14: =SUM(F14:H14) -> 1870 | J14: =1307+1 -> 1308 | K14: 4 | L14: 27 | M14: =SUM(J14:L14) -> 1339 | N14: =2789+2 -> 2791 | O14: 9 | P14: 83 | Q14: =SUM(N14:P14) -> 2883 | R14: =56+0 -> 56 | S14: 0 | T14: 4 | U14: =SUM(R14:T14) -> 60
A15: 44100
A16: 44101
A17: 44102 | B17: =SUM(F17,J17,N17,R17) -> 8072 | C17: =SUM(G17,K17,O17,S17) -> 10 | D17: =SUM(H17,L17,P17,T17) -> 134 | E17: =SUM(I17,M17,Q17,U17) -> 8216 | F17: =1169+1281 -> 2450 | G17: 1 | H17: 47 | I17: =SUM(F17:H17) -> 2498 | J17: =918+230 -> 1148 | K17: 0 | L17: 17 | M17: =SUM(J17:L17) -> 1165 | N17: =2437+1840 -> 4277 | O17: 9 | P17: 69 | Q17: =SUM(N17:P17) -> 4355 | R17: =108+89 -> 197 | S17: 0 | T17: 1 | U17: =SUM(R17:T17) -> 198
A18: 44103 | B18: =SUM(F18,J18,N18,R18) -> 8481 | C18: =SUM(G18,K18,O18,S18) -> 58 | D18: =SUM(H18,L18,P18,T18) -> 165 | E18: =SUM(B18:D18) -> 8704 | F18: =1886+7+819+1 -> 2713 | G18: 15 | H18: 61 | I18: =SUM(F18:H18) -> 2789 | J18: =1278+453 -> 1731 | K18: 10 | L18: 25 | M18: =SUM(J18:L18) -> 1766 | N18: =2780+1193 -> 3973 | O18: 33 | P18: 75 | Q18: =SUM(N18:P18) -> 4081 | R18: =28+36 -> 64 | S18: 0 | T18: 4 | U18: =SUM(R18:T18) -> 68
A19: 44104 | B19: =SUM(F19,J19,N19,R19) -> 4659 | C19: =SUM(G19,K19,O19,S19) -> 66 | D19: =SUM(H19,L19,P19,T19) -> 146 | E19: =SUM(B19:D19) -> 4871 | F19: =667+1+943 -> 1611 | G19: 21 | H19: 41 | I19: =SUM(F19:H19) -> 1673 | J19: =368+410 -> 778 | K19: 13 | L19: 22 | M19: =SUM(J19:L19) -> 813 | N19: =907+1+1278+1 -> 2187 | O19: 32 | P19: 79 | Q19: =SUM(N19:P19) -> 2298 | R19: =39+44 -> 83 | S19: 0 | T19: 4 | U19: =SUM(R19:T19) -> 87
A20: 44105 | B20: =SUM(F20,J20,N20,R20) -> 3805 | C20: =SUM(G20,K20,O20,S20) -> 25 | D20: =SUM(H20,L20,P20,T20) -> 170 | E20: =SUM(B20:D20) -> 4000 | F20: 1157 | G20: 8 | H20: 63 | I20: =SUM(F20:H20) -> 1228 | J20: 767 | K20: 9 | L20: 26 | M20: =SUM(J20:L20) -> 802 | N20: 1817 | O20: 8 | P20: 77 | Q20: =SUM(N20:P20) -> 1902 | R20: 64 | S20: 0 | T20: 4 | U20: =SUM(R20:T20) -> 68
A21: 44106 | B21: =SUM(F21,J21,N21,R21) -> 4691 | C21: =SUM(G21,K21,O21,S21) -> 33 | D21: =SUM(H21,L21,P21,T21) -> 97 | E21: =SUM(B21:D21) -> 4821 | F21: 1364 | G21: 8 | H21: 38 | I21: =SUM(F21:H21) -> 1410 | J21: 1077 | K21: 9 | L21: 17 | M21: =SUM(J21:L21) -> 1103 | N21: 2192 | O21: 16 | P21: 39 | Q21: =SUM(N21:P21) -> 2247 | R21: 58 | S21: 0 | T21: 3 | U21: =SUM(R21:T21) -> 61
A22: 44107 | B22: =SUM(F22,J22,N22,R22) -> 0 | C22: =SUM(G22,K22,O22,S22) -> 0 | D22: =SUM(H22,L22,P22,T22) -> 99 | E22: =SUM(B22:D22) -> 99 | F22: 0 | G22: 0 | H22: 38 | I22: =SUM(F22:H22) -> 38 | J22: 0 | K22: 0 | L22: 17 | M22: =SUM(J22:L22) -> 17 | N22: 0 | O22: 0 | P22: 39 | Q22: =SUM(N22:P22) -> 39 | R22: 0 | S22: 0 | T22: 5 | U22: =SUM(R22:T22) -> 5
A23: 44108
A24: 44109 | B24: =SUM(F24,J24,N24,R24) -> 5819 | C24: =SUM(G24,K24,O24,S24) -> 41 | D24: =SUM(H24,L24,P24,T24) -> 0 | E24: =SUM(B24:D24) -> 5860 | F24: 1586 | G24: 13 | H24: 0 | I24: =SUM(F24:H24) -> 1599 | J24: 1090 | K24: 9 | L24: 0 | M24: =SUM(J24:L24) -> 1099 | N24: 3055 | O24: 18 | P24: 0 | Q24: =SUM(N24:P24) -> 3073 | R24: 88 | S24: 1 | T24: 0 | U24: =SUM(R24:T24) -> 89
A25: 44110 | B25: =SUM(F25,J25,N25,R25) -> 7279 | C25: =SUM(G25,K25,O25,S25) -> 66 | D25: =SUM(H25,L25,P25,T25) -> 192 | E25: =SUM(B25:D25) -> 7537 | F25: 2378 | G25: 23 | H25: 49 | I25: =SUM(F25:H25) -> 2450 | J25: 1746 | K25: 7 | L25: 35 | M25: =SUM(J25:L25) -> 1788 | N25: 3048 | O25: 36 | P25: 106 | Q25: =SUM(N25:P25) -> 3190 | R25: 107 | S25: 0 | T25: 2 | U25: =SUM(R25:T25) -> 109
A26: 44111 | B26: =SUM(F26,J26,N26,R26) -> 4974 | C26: =SUM(G26,K26,O26,S26) -> 36 | D26: =SUM(H26,L26,P26,T26) -> 111 | E26: =SUM(B26:D26) -> 5121 | F26: 1022 | G26: 12 | H26: 36 | I26: =SUM(F26:H26) -> 1070 | J26: 1231 | K26: 5 | L26: 16 | M26: =SUM(J26:L26) -> 1252 | N26: 2597 | O26: 19 | P26: 56 | Q26: =SUM(N26:P26) -> 2672 | R26: 124 | S26: 0 | T26: 3 | U26: =SUM(R26:T26) -> 127
A27: 44112 | B27: =SUM(F27,J27,N27,R27) -> 2743 | C27: =SUM(G27,K27,O27,S27) -> 57 | D27: =SUM(H27,L27,P27,T27) -> 112 | E27: =SUM(B27:D27) -> 2912 | F27: 742 | G27: 17 | H27: 34 | I27: =SUM(F27:H27) -> 793 | J27: 389 | K27: 6 | L27: 24 | M27: =SUM(J27:L27) -> 419 | N27: 1603 | O27: 34 | P27: 53 | Q27: =SUM(N27:P27) -> 1690 | R27: 9 | S27: 0 | T27: 1 | U27: =SUM(R27:T27) -> 10
A28: 44113 | B28: =SUM(F28,J28,N28,R28) -> 4036 | C28: =SUM(G28,K28,O28,S28) -> 53 | D28: =SUM(H28,L28,P28,T28) -> 65 | E28: =SUM(B28:D28) -> 4154 | F28: 962 | G28: 22 | H28: 30 | I28: =SUM(F28:H28) -> 1014 | J28: 899 | K28: 9 | L28: 10 | M28: =SUM(J28:L28) -> 918 | N28: 2116 | O28: 19 | P28: 25 | Q28: =SUM(N28:P28) -> 2160 | R28: 59 | S28: 3 | T28: 0 | U28: =SUM(R28:T28) -> 62
A29: 44114
A30: 44115
A31: 44116
A32: 44117 | B32: =SUM(F32,J32,N32,R32) -> 5471 | C32: =SUM(G32,K32,O32,S32) -> 51 | D32: =SUM(H32,L32,P32,T32) -> 202 | E32: =SUM(B32:D32) -> 5724 | F32: 2156 | G32: 23 | H32: =36+42 -> 78 | I32: =SUM(F32:H32) -> 2257 | J32: 1077 | K32: 9 | L32: =15+19 -> 34 | M32: =SUM(J32:L32) -> 1120 | N32: 2145 | O32: 19 | P32: =44+46 -> 90 | Q32: =SUM(N32:P32) -> 2254 | R32: 93 | S32: 0 | T32: 0 | U32: =SUM(R32:T32) -> 93
A33: 44118 | B33: =SUM(F33,J33,N33,R33) -> 2921 | C33: =SUM(G33,K33,O33,S33) -> 22 | D33: =SUM(H33,L33,P33,T33) -> 66 | E33: =SUM(B33:D33) -> 3009 | F33: 927 | G33: 7 | H33: 19 | I33: =SUM(F33:H33) -> 953 | J33: 337 | K33: 6 | L33: 10 | M33: =SUM(J33:L33) -> 353 | N33: 1634 | O33: 9 | P33: 37 | Q33: =SUM(N33:P33) -> 1680 | R33: 23 | S33: 0 | T33: 0 | U33: =SUM(R33:T33) -> 23
A34: 44119 | B34: =SUM(F34,J34,N34,R34) -> 2092 | C34: =SUM(G34,K34,O34,S34) -> 22 | D34: =SUM(H34,L34,P34,T34) -> 116 | E34: =SUM(B34:D34) -> 2230 | F34: 239 | G34: 12 | H34: 30 | I34: =SUM(F34:H34) -> 281 | J34: 550 | K34: 8 | L34: 23 | M34: =SUM(J34:L34) -> 581 | N34: 1261 | O34: 2 | P34: 62 | Q34: =SUM(N34:P34) -> 1325 | R34: 42 | S34: 0 | T34: 1 | U34: =SUM(R34:T34) -> 43
A35: 44120 | B35: =SUM(F35,J35,N35,R35) -> 3958 | C35: =SUM(G35,K35,O35,S35) -> 28 | D35: =SUM(H35,L35,P35,T35) -> 93 | E35: =SUM(B35:D35) -> 4079 | F35: 1567 | G35: 8 | H35: 20 | I35: =SUM(F35:H35) -> 1595 | J35: 674 | K35: 7 | L35: 16 | M35: =SUM(J35:L35) -> 697 | N35: 1662 | O35: 13 | P35: 54 | Q35: =SUM(N35:P35) -> 1729 | R35: 55 | S35: 0 | T35: 3 | U35: =SUM(R35:T35) -> 58
A36: 44121
A37: 44122
A38: 44123 | B38: =SUM(F38,J38,N38,R38) -> 4553 | C38: =SUM(G38,K38,O38,S38) -> 31 | D38: =SUM(H38,L38,P38,T38) -> 94 | E38: =SUM(B38:D38) -> 4678 | F38: 1689 | G38: 12 | H38: 38 | I38: =SUM(F38:H38) -> 1739 | J38: 862 | K38: 5 | L38: 14 | M38: =SUM(J38:L38) -> 881 | N38: 1904 | O38: 14 | P38: 42 | Q38: =SUM(N38:P38) -> 1960 | R38: 98 | S38: 0 | T38: 0 | U38: =SUM(R38:T38) -> 98
A39: 44124 | B39: =SUM(F39,J39,N39,R39) -> 3043 | C39: =SUM(G39,K39,O39,S39) -> 21 | D39: =SUM(H39,L39,P39,T39) -> 80 | E39: =SUM(B39:D39) -> 3144 | F39: 831 | G39: 9 | H39: 37 | I39: =SUM(F39:H39) -> 877 | J39: 622 | K39: 4 | L39: 12 | M39: =SUM(J39:L39) -> 638 | N39: 1545 | O39: 7 | P39: 31 | Q39: =SUM(N39:P39) -> 1583 | R39: 45 | S39: 1 | T39: 0 | U39: =SUM(R39:T39) -> 46
A40: 44125 | B40: =SUM(F40,J40,N40,R40) -> 2661 | C40: =SUM(G40,K40,O40,S40) -> 46 | D40: =SUM(H40,L40,P40,T40) -> 79 | E40: =SUM(B40:D40) -> 2786 | F40: 820 | G40: 27 | H40: 34 | I40: =SUM(F40:H40) -> 881 | J40: 671 | K40: 11 | L40: 12 | M40: =SUM(J40:L40) -> 694 | N40: 1123 | O40: 8 | P40: 32 | Q40: =SUM(N40:P40) -> 1163 | R40: 47 | S40: 0 | T40: 1 | U40: =SUM(R40:T40) -> 48
A41: 44126 | B41: =SUM(F41,J41,N41,R41) -> 2800 | C41: =SUM(G41,K41,O41,S41) -> 22 | D41: =SUM(H41,L41,P41,T41) -> 74 | E41: =SUM(B41:D41) -> 2896 | F41: 1121 | G41: 7 | H41: 22 | I41: =SUM(F41:H41) -> 1150 | J41: 341 | K41: 1 | L41: 14 | M41: =SUM(J41:L41) -> 356 | N41: 1315 | O41: 14 | P41: 38 | Q41: =SUM(N41:P41) -> 1367 | R41: 23 | S41: 0 | T41: 0 | U41: =SUM(R41:T41) -> 23
A42: 44127 | B42: =SUM(F42,J42,N42,R42) -> 2510 | C42: =SUM(G42,K42,O42,S42) -> 16 | D42: =SUM(H42,L42,P42,T42) -> 58 | E42: =SUM(B42:D42) -> 2584 | F42: 859 | G42: 5 | H42: =10+11 -> 21 | I42: =SUM(F42:H42) -> 885 | J42: 431 | K42: 3 | L42: =5+5 -> 10 | M42: =SUM(J42:L42) -> 444 | N42: 1178 | O42: 7 | P42: =16+10 -> 26 | Q42: =SUM(N42:P42) -> 1211 | R42: 42 | S42: 1 | T42: 1 | U42: =SUM(R42:T42) -> 44
...

Sheet Return by Mail
A1: Returned Absentee Ballots
A3: November 3, 2020 ▪ General Election
B5: Total Returned by Mail | F5: =F57 -> 141051 | H5: CD 8 | L5: =L57 -> 41644 | M5: CD 10 | Q5: =Q57 -> 32275 | R5: CD 11 | V5: =V57 -> 64853 | W5: CD 11-Herndon | AA5: =AA57 -> 2237
A6: Date | B6: Domestic | C6: UOCAVA | D6: E-mail UOCAVA | E6: FWAB | F6: Total | G6: Unused/ undeliverable | H6: Domestic | I6: UOCAVA | J6: E-mail UOCAVA | K6: FWAB | L6: Total | M6: Domestic | N6: UOCAVA | O6: E-mail UOCAVA | P6: FWAB | Q6: Total | R6: Domestic | S6: UOCAVA | T6: E-mail UOCAVA | U6: FWAB | V6: Total | W6: Domestic | X6: UOCAVA | Y6: E-mail UOCAVA | Z6: FWAB | AA6: Total
A7: 44092 | B7: =SUM(H7,M7,R7,W7) -> 0 | C7: =SUM(I7,N7,S7,X7) -> 0 | D7: =SUM(J7,O7,T7,Y7) -> 0 | E7: =SUM(K7,P7,U7,Z7) -> 0 | F7: =SUM(B7:E7) -> 0 | G7: 0 | H7: 0 | I7: 0 | J7: 0 | K7: 0 | L7: =SUM(H7:K7) -> 0 | M7: 0 | N7: 0 | O7: 0 | P7: 0 | Q7: =SUM(M7:P7) -> 0 | R7: 0 | S7: 0 | T7: 0 | U7: 0 | V7: =SUM(R7:U7) -> 0 | W7: 0 | X7: 0 | Y7: 0 | Z7: 0 | AA7: =SUM(W7:Z7) -> 0
A8: 44093 | B8: =SUM(H8,M8,R8,W8) -> 27 | C8: =SUM(I8,N8,S8,X8) -> 0 | D8: =SUM(J8,O8,T8,Y8) -> 4 | E8: =SUM(K8,P8,U8,Z8) -> 0 | F8: =SUM(B8:E8) -> 31 | G8: 0 | H8: 7 | I8: 0 | J8: 3 | K8: 0 | L8: =SUM(H8:K8) -> 10 | M8: 6 | N8: 0 | O8: 0 | P8: 0 | Q8: =SUM(M8:P8) -> 6 | R8: 14 | S8: 0 | T8: 1 | U8: 0 | V8: =SUM(R8:U8) -> 15 | W8: 0 | X8: 0 | Y8: 0 | Z8: 0 | AA8: =SUM(W8:Z8) -> 0
A9: 44094 | L9: =SUM(H9:K9) -> 0 | Q9: =SUM(M9:P9) -> 0 | AA9: =SUM(W9:Z9) -> 0
A10: 44095 | B10: =SUM(H10,M10,R10,W10) -> 377 | C10: =SUM(I10,N10,S10,X10) -> 0 | D10: =SUM(J10,O10,T10,Y10) -> 69 | E10: =SUM(K10,P10,U10,Z10) -> 0 | F10: =SUM(B10:E10) -> 446 | G10: =2+1+0 -> 3 | H10: =139+4 -> 143 | I10: 0 | J10: 42 | K10: 0 | L10: =SUM(H10:K10) -> 185 | M10: =55+6 -> 61 | N10: 0 | O10: 9 | P10: 0 | Q10: =SUM(M10:P10) -> 70 | R10: =164+6 -> 170 | S10: 0 | T10: 18 | U10: 0 | V10: =SUM(R10:U10) -> 188 | W10: 3 | X10: 0 | Y10: 0 | Z10: 0 | AA10: =SUM(W10:Z10) -> 3
A11: 44096 | B11: =SUM(H11,M11,R11,W11) -> 250 | C11: =SUM(I11,N11,S11,X11) -> 0 | D11: =SUM(J11,O11,T11,Y11) -> 34 | E11: =SUM(K11,P11,U11,Z11) -> 0 | F11: =SUM(B11:E11) -> 284 | G11: 4 | H11: 81 | I11: 0 | J11: 13 | K11: 0 | L11: =SUM(H11:K11) -> 94 | M11: 41 | N11: 0 | O11: 6 | P11: 0 | Q11: =SUM(M11:P11) -> 47 | R11: 125 | S11: 0 | T11: 15 | U11: 0 | V11: =SUM(R11:U11) -> 140 | W11: 3 | X11: 0 | Y11: 0 | Z11: 0 | AA11: =SUM(W11:Z11) -> 3
A12: 44097 | B12: =SUM(H12,M12,R12,W12) -> 1240 | C12: =SUM(I12,N12,S12,X12) -> 0 | D12: =SUM(J12,O12,T12,Y12) -> 0 | E12: =SUM(K12,P12,U12,Z12) -> 0 | F12: =SUM(B12:E12) -> 1240 | G12: 2 | H12: 356 | I12: 0 | J12: 0 | K12: 0 | L12: =SUM(H12:K12) -> 356 | M12: 217 | N12: 0 | O12: 0 | P12: 0 | Q12: =SUM(M12:P12) -> 217 | R12: 657 | S12: 0 | T12: 0 | U12: 0 | V12: =SUM(R12:U12) -> 657 | W12: 10 | X12: 0 | Y12: 0 | Z12: 0 | AA12: =SUM(W12:Z12) -> 10
A13: 44098 | B13: =SUM(H13,M13,R13,W13) -> 4008 | C13: =SUM(I13,N13,S13,X13) -> 6 | D13: =SUM(J13,O13,T13,Y13) -> 211 | E13: =SUM(K13,P13,U13,Z13) -> 0 | F13: =SUM(B13:E13) -> 4225 | G13: 15 | H13: =1052+5 -> 1057 | I13: 1 | J13: =38+45 -> 83 | K13: 0 | L13: =SUM(H13:K13) -> 1141 | M13: 814 | N13: 1 | O13: =15+20 -> 35 | P13: 0 | Q13: =SUM(M13:P13) -> 850 | R13: 2059 | S13: 4 | T13: =40+53 -> 93 | U13: 0 | V13: =SUM(R13:U13) -> 2156 | W13: 78 | X13: 0 | Y13: 0 | Z13: 0 | AA13: =SUM(W13:Z13) -> 78
A14: 44099 | B14: =SUM(H14,M14,R14,W14) -> 3870 | C14: =SUM(I14,N14,S14,X14) -> 12 | D14: =SUM(J14,O14,T14,Y14) -> 78 | E14: =SUM(K14,P14,U14,Z14) -> 0 | F14: =SUM(B14:E14) -> 3960 | G14: 7 | H14: 1021 | I14: 2 | J14: 31 | K14: 0 | L14: =SUM(H14:K14) -> 1054 | M14: 809 | N14: 0 | O14: 14 | P14: 0 | Q14: =SUM(M14:P14) -> 823 | R14: =1995-6-1 -> 1988 | S14: 10 | T14: 33 | U14: 0 | V14: =SUM(R14:U14) -> 2031 | W14: =51+1 -> 52 | X14: 0 | Y14: 0 | Z14: 0 | AA14: =SUM(W14:Z14) -> 52
A15: 44100 | B15: =SUM(H15,M15,R15,W15) -> 4970 | C15: =SUM(I15,N15,S15,X15) -> 10 | D15: =SUM(J15,O15,T15,Y15) -> 88 | E15: =SUM(K15,P15,U15,Z15) -> 0 | F15: =SUM(B15:E15) -> 5068 | G15: 8 | H15: =1565-7 -> 1558 | I15: 7 | J15: 38 | K15: 0 | L15: =SUM(H15:K15) -> 1603 | M15: 949 | N15: 0 | O15: 14 | P15: 0 | Q15: =SUM(M15:P15) -> 963 | R15: 2387 | S15: 3 | T15: 36 | U15: 0 | V15: =SUM(R15:U15) -> 2426 | W15: 76 | X15: 0 | Y15: 0 | Z15: 0 | AA15: =SUM(W15:Z15) -> 76
A16: 44101
A17: 44102 | B17: =SUM(H17,M17,R17,W17) -> 8218 | C17: =SUM(I17,N17,S17,X17) -> 33 | D17: =SUM(J17,O17,T17,Y17) -> 12 | E17: =SUM(K17,P17,U17,Z17) -> 0 | F17: =SUM(B17:E17) -> 8263 | G17: =55+11 -> 66 | H17: =2540+6-9 -> 2537 | I17: 12 | J17: 7 | K17: 0 | L17: =SUM(H17:K17) -> 2556 | M17: =1532+7-17 -> 1522 | N17: 3 | O17: 0 | P17: 0 | Q17: =SUM(M17:P17) -> 1525 | R17: =4050+13-29 -> 4034 | S17: 18 | T17: 5 | U17: 0 | V17: =SUM(R17:U17) -> 4057 | W17: =124+1 -> 125 | X17: 0 | Y17: 0 | Z17: 0 | AA17: =SUM(W17:Z17) -> 125
A18: 44103 | B18: =SUM(H18,M18,R18,W18) -> 457 | C18: =SUM(I18,N18,S18,X18) -> 18 | D18: =SUM(J18,O18,T18,Y18) -> 300 | E18: =SUM(K18,P18,U18,Z18) -> 0 | F18: =SUM(B18:E18) -> 775 | G18: 4 | H18: 151 | I18: 1 | J18: 84 | K18: 0 | L18: =SUM(H18:K18) -> 236 | M18: =125-2 -> 123 | N18: 0 | O18: 54 | P18: 0 | Q18: =SUM(M18:P18) -> 177 | R18: 179 | S18: 17 | T18: 159 | U18: 0 | V18: =SUM(R18:U18) -> 355 | W18: 4 | X18: 0 | Y18: 3 | Z18: 0 | AA18: =SUM(W18:Z18) -> 7
A19: 44104 | B19: =SUM(H19,M19,R19,W19) -> 7108 | C19: =SUM(I19,N19,S19,X19) -> 54 | D19: =SUM(J19,O19,T19,Y19) -> 224 | E19: =SUM(K19,P19,U19,Z19) -> 0 | F19: =SUM(B19:E19) -> 7386 | G19: =31+6 -> 37 | H19: =2024+1-2 -> 2023 | I19: =12+8 -> 20 | J19: 65 | K19: 0 | L19: =SUM(H19:K19) -> 2108 | M19: =1290+4-1 -> 1293 | N19: =5+2 -> 7 | O19: 28 | P19: 0 | Q19: =SUM(M19:P19) -> 1328 | R19: =3679+4-3-5 -> 3675 | S19: =16+11 -> 27 | T19: 129 | U19: 0 | V19: =SUM(R19:U19) -> 3831 | W19: =112+5 -> 117 | X19: 0 | Y19: 2 | Z19: 0 | AA19: =SUM(W19:Z19) -> 119
A20: 44105 | B20: =SUM(H20,M20,R20,W20) -> 3806 | C20: =SUM(I20,N20,S20,X20) -> 34 | D20: =SUM(J20,O20,T20,Y20) -> 167 | E20: =SUM(K20,P20,U20,Z20) -> 0 | F20: =SUM(B20:E20) -> 4007 | G20: 40 | H20: =1114-2 -> 1112 | I20: 12 | J20: 64 | K20: 0 | L20: =SUM(H20:K20) -> 1188 | M20: =742-4 -> 738 | N20: 0 | O20: 23 | P20: 0 | Q20: =SUM(M20:P20) -> 761 | R20: =1923-4-3 -> 1916 | S20: 22 | T20: 80 | U20: 0 | V20: =SUM(R20:U20) -> 2018 | W20: =37+3 -> 40 | X20: 0 | Y20: 0 | Z20: 0 | AA20: =SUM(W20:Z20) -> 40
A21: 44106 | B21: =SUM(H21,M21,R21,W21) -> 3610 | C21: =SUM(I21,N21,S21,X21) -> 31 | D21: =SUM(J21,O21,T21,Y21) -> 228 | E21: =SUM(K21,P21,U21,Z21) -> 0 | F21: =SUM(B21:E21) -> 3869 | G21: =51+10 -> 61 | H21: =1154-4 -> 1150 | I21: 12 | J21: 68 | K21: 0 | L21: =SUM(H21:K21) -> 1230 | M21: =665-2 -> 663 | N21: 4 | O21: 28 | P21: 0 | Q21: =SUM(M21:P21) -> 695 | R21: =1753-4-1 -> 1748 | S21: 15 | T21: 131 | U21: 0 | V21: =SUM(R21:U21) -> 1894 | W21: 49 | X21: 0 | Y21: 1 | Z21: 0 | AA21: =SUM(W21:Z21) -> 50
A22: 44107 | B22: =SUM(H22,M22,R22,W22) -> 3608 | C22: =SUM(I22,N22,S22,X22) -> 4 | D22: =SUM(J22,O22,T22,Y22) -> 116 | E22: =SUM(K22,P22,U22,Z22) -> 0 | F22: =SUM(B22:E22) -> 3728 | G22: 56 | H22: 1125 | I22: 1 | J22: 36 | K22: 0 | L22: =SUM(H22:K22) -> 1162 | M22: 638 | N22: 0 | O22: 23 | P22: 0 | Q22: =SUM(M22:P22) -> 661 | R22: 1781 | S22: 3 | T22: 57 | U22: 0 | V22: =SUM(R22:U22) -> 1841 | W22: =63+1 -> 64 | X22: 0 | Y22: 0 | Z22: 0 | AA22: =SUM(W22:Z22) -> 64
A23: 44108
A24: 44109 | B24: =SUM(H24,M24,R24,W24) -> 5628 | C24: =SUM(I24,N24,S24,X24) -> 3 | D24: =SUM(J24,O24,T24,Y24) -> 200 | E24: =SUM(K24,P24,U24,Z24) -> 0 | F24: =SUM(B24:E24) -> 5831 | G24: =52+8 -> 60 | H24: =1755-2 -> 1753 | I24: =2-1 -> 1 | J24: 60 | K24: 0 | L24: =SUM(H24:K24) -> 1814 | M24: =1117-1 -> 1116 | N24: 0 | O24: 31 | P24: 0 | Q24: =SUM(M24:P24) -> 1147 | R24: =2697-5-1 -> 2691 | S24: 2 | T24: 107 | U24: 0 | V24: =SUM(R24:U24) -> 2800 | W24: =72-5+1 -> 68 | X24: 0 | Y24: 2 | Z24: 0 | AA24: =SUM(W24:Z24) -> 70
A25: 44110 | B25: =SUM(H25,M25,R25,W25) -> 434 | C25: =SUM(I25,N25,S25,X25) -> 55 | D25: =SUM(J25,O25,T25,Y25) -> 308 | E25: =SUM(K25,P25,U25,Z25) -> 0 | F25: =SUM(B25:E25) -> 797 | G25: 25 | H25: =91-2 -> 89 | I25: 19 | J25: 95 | K25: 0 | L25: =SUM(H25:K25) -> 203 | M25: 128 | N25: 7 | O25: 58 | P25: 0 | Q25: =SUM(M25:P25) -> 193 | R25: 211 | S25: 26 | T25: 154 | U25: 0 | V25: =SUM(R25:U25) -> 391 | W25: 6 | X25: 3 | Y25: 1 | Z25: 0 | AA25: =SUM(W25:Z25) -> 10
A26: 44111 | B26: =SUM(H26,M26,R26,W26) -> 5221 | C26: =SUM(I26,N26,S26,X26) -> 100 | D26: =SUM(J26,O26,T26,Y26) -> 223 | E26: 0 | F26: =SUM(B26:E26) -> 5544 | G26: =5+14 -> 19 | H26: =1589-5 -> 1584 | I26: 43 | J26: 84 | K26: 0 | L26: =SUM(H26:K26) -> 1711 | M26: =1110-2 -> 1108 | N26: 13 | O26: 34 | P26: 0 | Q26: =SUM(M26:P26) -> 1155 | R26: =2431-7 -> 2424 | S26: 44 | T26: 105 | U26: 0 | V26: =SUM(R26:U26) -> 2573 | W26: 105 | X26: 0 | Y26: 0 | Z26: 0 | AA26: =SUM(W26:Z26) -> 105
A27: 44112 | B27: =SUM(H27,M27,R27,W27) -> 3839 | C27: =SUM(I27,N27,S27,X27) -> 49 | D27: =SUM(J27,O27,T27,Y27) -> 244 | E27: 0 | F27: =SUM(B27:E27) -> 4132 | G27: =4+56 -> 60 | H27: =1206-1 -> 1205 | I27: =18-1 -> 17 | J27: 90 | K27: 0 | L27: =SUM(H27:K27) -> 1312 | M27: =745-1 -> 744 | N27: 9 | O27: 36 | P27: 0 | Q27: =SUM(M27:P27) -> 789 | R27: =1829-2-2 -> 1825 | S27: 23 | T27: 117 | U27: 0 | V27: =SUM(R27:U27) -> 1965 | W27: =63+2 -> 65 | X27: 0 | Y27: 1 | Z27: 0 | AA27: =SUM(W27:Z27) -> 66
A28: 44113 | B28: =SUM(H28,M28,R28,W28) -> 3450 | C28: =SUM(I28,N28,S28,X28) -> 12 | D28: =SUM(J28,O28,T28,Y28) -> 202 | E28: 0 | F28: =SUM(B28:E28) -> 3664 | G28: 36 | H28: =1011-1 -> 1010 | I28: 6 | J28: 62 | K28: 0 | L28: =SUM(H28:K28) -> 1078 | M28: 716 | N28: 1 | O28: 32 | P28: 0 | Q28: =SUM(M28:P28) -> 749 | R28: 1671 | S28: 5 | T28: 105 | U28: 0 | V28: =SUM(R28:U28) -> 1781 | W28: 53 | X28: 0 | Y28: 3 | Z28: 0 | AA28: =SUM(W28:Z28) -> 56
A29: 44114 | B29: =SUM(H29,M29,R29,W29) -> 2904 | C29: =SUM(I29,N29,S29,X29) -> 182 | D29: =SUM(J29,O29,T29,Y29) -> 173 | E29: 0 | F29: =SUM(B29:E29) -> 3259 | G29: 2 | H29: 965 | I29: 41 | J29: 57 | K29: 0 | L29: =SUM(H29:K29) -> 1063 | M29: 536 | N29: 75 | O29: 26 | P29: 0 | Q29: =SUM(M29:P29) -> 637 | R29: =1353-1 -> 1352 | S29: 66 | T29: 90 | U29: 0 | V29: =SUM(R29:U29) -> 1508 | W29: =50+1 -> 51 | X29: 0 | Y29: 0 | Z29: 0 | AA29: =SUM(W29:Z29) -> 51
A30: 44115
A31: 44116 | L31: =SUM(H31:K31) -> 0 | Q31: =SUM(M31:P31) -> 0 | V31: =SUM(R31:U31) -> 0 | AA31: =SUM(W31:Z31) -> 0
A32: 44117 | B32: =SUM(H32,M32,R32,W32) -> 5797 | C32: =SUM(I32,N32,S32,X32) -> 111 | D32: =SUM(J32,O32,T32,Y32) -> 83 | E32: 0 | F32: =SUM(B32:E32) -> 5991 | G32: =94+5 -> 99 | H32: 1906 | I32: 41 | J32: 31 | K32: 0 | L32: =SUM(H32:K32) -> 1978 | M32: 1137 | N32: 20 | O32: 13 | P32: 0 | Q32: =SUM(M32:P32) -> 1170 | R32: =2692-1 -> 2691 | S32: 50 | T32: 39 | U32: 0 | V32: =SUM(R32:U32) -> 2780 | W32: =62+1 -> 63 | X32: 0 | Y32: 0 | Z32: 0 | AA32: =SUM(W32:Z32) -> 63
A33: 44118 | B33: =SUM(H33,M33,R33,W33) -> 236 | C33: =SUM(I33,N33,S33,X33) -> 84 | D33: =SUM(J33,O33,T33,Y33) -> 455 | E33: 0 | F33: =SUM(B33:E33) -> 775 | G33: =3+23 -> 26 | H33: 56 | I33: 30 | J33: 164 | K33: 0 | L33: =SUM(H33:K33) -> 250 | M33: 74 | N33: 4 | O33: 67 | P33: 0 | Q33: =SUM(M33:P33) -> 145 | R33: 102 | S33: 50 | T33: 221 | U33: 0 | V33: =SUM(R33:U33) -> 373 | W33: 4 | X33: 0 | Y33: 3 | Z33: 0 | AA33: =SUM(W33:Z33) -> 7
A34: 44119 | B34: =SUM(H34,M34,R34,W34) -> 5434 | C34: =SUM(I34,N34,S34,X34) -> 98 | D34: =SUM(J34,O34,T34,Y34) -> 181 | E34: =SUM(K34,P34,U34,Z34) -> 0 | F34: =SUM(B34:E34) -> 5713 | G34: 2 | H34: =1618 -> 1618 | I34: =26+2 -> 28 | J34: 55 | K34: 0 | L34: =SUM(H34:K34) -> 1701 | M34: 1168 | N34: 13 | O34: 33 | P34: 0 | Q34: =SUM(M34:P34) -> 1214 | R34: =2551-2 -> 2549 | S34: 57 | T34: 93 | U34: 0 | V34: =SUM(R34:U34) -> 2699 | W34: =97+2 -> 99 | X34: 0 | Y34: 0 | Z34: 0 | AA34: =SUM(W34:Z34) -> 99
A35: 44120 | B35: =SUM(H35,M35,R35,W35) -> 4765 | C35: =SUM(I35,N35,S35,X35) -> 108 | D35: =SUM(J35,O35,T35,Y35) -> 307 | E35: =SUM(K35,P35,U35,Z35) -> 0 | F35: =SUM(B35:E35) -> 5180 | G35: =87+5 -> 92 | H35: 1567 | I35: 41 | J35: 110 | K35: 0 | L35: =SUM(H35:K35) -> 1718 | M35: =960-1 -> 959 | N35: 21 | O35: 58 | P35: 0 | Q35: =SUM(M35:P35) -> 1038 | R35: =2158-4-7 -> 2147 | S35: 46 | T35: 137 | U35: 0 | V35: =SUM(R35:U35) -> 2330 | W35: =85+7 -> 92 | X35: 0 | Y35: 2 | Z35: 0 | AA35: =SUM(W35:Z35) -> 94
A36: 44121 | B36: =SUM(H36,M36,R36,W36) -> 3769 | C36: =SUM(I36,N36,S36,X36) -> 6 | D36: =SUM(J36,O36,T36,Y36) -> 100 | E36: =SUM(K36,P36,U36,Z36) -> 0 | F36: =SUM(B36:E36) -> 3875 | G36: 41 | H36: =1117-1 -> 1116 | I36: 0 | J36: =11+26 -> 37 | K36: 0 | L36: =SUM(H36:K36) -> 1153 | M36: =715-1 -> 714 | N36: 0 | O36: =2+13 -> 15 | P36: 0 | Q36: =SUM(M36:P36) -> 729 | R36: =1683-2-2 -> 1679 | S36: 6 | T36: =21+27 -> 48 | U36: 0 | V36: =SUM(R36:U36) -> 1733 | W36: =258+2 -> 260 | X36: 0 | Y36: 0 | Z36: 0 | AA36: =SUM(W36:Z36) -> 260
A37: 44122
A38: 44123 | B38: =SUM(H38,M38,R38,W38) -> 5284 | C38: =SUM(I38,N38,S38,X38) -> 222 | D38: =SUM(J38,O38,T38,Y38) -> 205 | E38: =SUM(K38,P38,U38,Z38) -> 0 | F38: =SUM(B38:E38) -> 5711 | G38: =5+35 -> 40 | H38: =1595-2 -> 1593 | I38: 66 | J38: 61 | K38: 0 | L38: =SUM(H38:K38) -> 1720 | M38: 1342 | N38: 41 | O38: 41 | P38: 0 | Q38: =SUM(M38:P38) -> 1424 | R38: =2292-3 -> 2289 | S38: 113 | T38: 103 | U38: 0 | V38: =SUM(R38:U38) -> 2505 | W38: 60 | X38: 2 | Y38: 0 | Z38: 0 | AA38: =SUM(W38:Z38) -> 62
A39: 44124 | B39: =SUM(H39,M39,R39,W39) -> 310 | C39: =SUM(I39,N39,S39,X39) -> 26 | D39: =SUM(J39,O39,T39,Y39) -> 370 | E39: =SUM(K39,P39,U39,Z39) -> 0 | F39: =SUM(B39:E39) -> 706 | G39: 5 | H39: =122-4 -> 118 | I39: 8 | J39: 111 | K39: 0 | L39: =SUM(H39:K39) -> 237 | M39: 70 | N39: 0 | O39: 78 | P39: 0 | Q39: =SUM(M39:P39) -> 148 | R39: =120-1 -> 119 | S39: 18 | T39: 175 | U39: 0 | V39: =SUM(R39:U39) -> 312 | W39: 3 | X39: 0 | Y39: 6 | Z39: 0 | AA39: =SUM(W39:Z39) -> 9
A40: 44125 | B40: =SUM(H40,M40,R40,W40) -> 4156 | C40: =SUM(I40,N40,S40,X40) -> 107 | D40: =SUM(J40,O40,T40,Y40) -> 201 | E40: =SUM(K40,P40,U40,Z40) -> 0 | F40: =SUM(B40:E40) -> 4464 | G40: 31 | H40: =1217-4 -> 1213 | I40: 20 | J40: 65 | K40: 0 | L40: =SUM(H40:K40) -> 1298 | M40: =834-1 -> 833 | N40: 15 | O40: 29 | P40: 0 | Q40: =SUM(M40:P40) -> 877 | R40: =2045-5 -> 2040 | S40: 71 | T40: 103 | U40: 0 | V40: =SUM(R40:U40) -> 2214 | W40: 70 | X40: 1 | Y40: 4 | Z40: 0 | AA40: =SUM(W40:Z40) -> 75
A41: 44126 | B41: =SUM(H41,M41,R41,W41) -> 3161 | C41: =SUM(I41,N41,S41,X41) -> 16 | D41: =SUM(J41,O41,T41,Y41) -> 123 | E41: =SUM(K41,P41,U41,Z41) -> 0 | F41: =SUM(B41:E41) -> 3300 | G41: 5 | H41: 957 | I41: 3 | J41: 56 | K41: 0 | L41: =SUM(H41:K41) -> 1016 | M41: 650 | N41: 7 | O41: 16 | P41: 0 | Q41: =SUM(M41:P41) -> 673 | R41: 1497 | S41: 6 | T41: 49 | U41: 0 | V41: =SUM(R41:U41) -> 1552 | W41: 57 | X41: 0 | Y41: 2 | Z41: 0 | AA41: =SUM(W41:Z41) -> 59
A42: 44127 | B42: =SUM(H42,M42,R42,W42) -> 3007 | C42: =SUM(I42,N42,S42,X42) -> 146 | D42: =SUM(J42,O42,T42,Y42) -> 281 | E42: =SUM(K42,P42,U42,Z42) -> 0 | F42: =SUM(B42:E42) -> 3434 | G42: =16+6 -> 22 | H42: =901-2 -> 899 | I42: 45 | J42: 97 | K42: 0 | L42: =SUM(H42:K42) -> 1041 | M42: =668-1 -> 667 | N42: 22 | O42: 50 | P42: 0 | Q42: =SUM(M42:P42) -> 739 | R42: =1394-3 -> 1391 | S42: 77 | T42: 130 | U42: 0 | V42: =SUM(R42:U42) -> 1598 | W42: 50 | X42: 2 | Y42: 4 | Z42: 0 | AA42: =SUM(W42:Z42) -> 56
...

Sheet Return by Dropbox
A1: Mailed Ballots Returned to Dropboxes -- by Satellite
A2: November 3 2020 General Election
B4: Total Dropbox* | C4: Total | H4: Government Center | M4: =M53 -> 43138 | N4: Fairfax City /Falls Church/ Alex City | R4: =R53 -> 114 | S4: Centreville | W4: =W53 -> 2080 | X4: Franconia | AB4: =AB53 -> 5425 | AC4: Great Falls | AG4: =AG53 -> 601 | AH4: Herndon | AL4: =AL53 -> 3109 | AM4: Laurel Hill | AQ4: =AQ53 -> 1831 | AR4: Mason | AV4: =AV53 -> 3055 | AW4: McLean | BA4: =BA53 -> 3269 | BB4: Mt Vernon | BF4: =BF53 -> 5099 | BG4: North County | BK4: =BK53 -> 3720 | BL4: Providence | BP4: =BP53 -> 2076 | BQ4: Sully | BU4: =BU53 -> 1403 | BV4: Thomas Jefferson | BZ4: =BZ53 -> 1833 | CA4: Tysons Pimmit | CE4: =CE53 -> 2824 | CF4: West Springfield | CJ4: =CJ53 -> 5725
A5: Date | B5: =B53 -> 85292 | C5: CD 8 | D5: CD 10 | E5: CD 11 | F5: CD 11-Herndon | G5: UOCAVA | H5: CD 8 | I5: CD 10 | J5: CD 11 | K5: Herndon | L5: UOCAVA | M5: Total | N5: CD 8 | O5: CD 10 | P5: CD11 | Q5: Herndon | R5: Total | S5: CD 8 | T5: CD 10 | U5: CD11 | V5: Herndon | W5: Total | X5: CD 8 | Y5: CD 10 | Z5: CD11 | AA5: Herndon | AB5: Total | AC5: CD 8 | AD5: CD 10 | AE5: CD11 | AF5: Herndon | AG5: Total | AH5: CD 8 | AI5: CD 10 | AJ5: CD11 | AK5: Herndon | AL5: Total | AM5: CD 8 | AN5: CD 10 | AO5: CD11 | AP5: Herndon | AQ5: Total | AR5: CD 8 | AS5: CD 10 | AT5: CD11 | AU5: Herndon | AV5: Total | AW5: CD 8 | AX5: CD 10 | AY5: CD11 | AZ5: Herndon | BA5: Total | BB5: CD 8 | BC5: CD 10 | BD5: CD11 | BE5: Herndon | BG5: CD 8 | BH5: CD 10 | BI5: CD11 | BJ5: Herndon | BK5: Total | BL5: CD 8 | BM5: CD 10 | BN5: CD11 | BO5: Herndon | BP5: Total | BQ5: CD 8 | BR5: CD 10 | BS5: CD11 | BT5: Herndon | BU5: Total | BV5: CD 8 | BW5: CD 10 | BX5: CD11 | BY5: Herndon | BZ5: Total | CA5: CD 8 | CB5: CD 10 | CC5: CD11 | CD5: Herndon | CE5: Total | CF5: CD 8 | CG5: CD 10 | CH5: CD 11 | CI5: Herndon | CJ5: Total
A6: 44092 | B6: =SUM(C6:G6) -> 1 | C6: =H6 -> 0 | D6: =I6 -> 0 | E6: =J6 -> 1 | F6: =K6 -> 0 | G6: =L6 -> 0 | H6: 0 | I6: 0 | J6: 1 | K6: 0 | L6: 0 | M6: =SUM(H6:L6) -> 1
A7: 44093 | B7: =SUM(C7:G7) -> 26 | C7: =H7 -> 7 | D7: =I7 -> 6 | E7: =J7 -> 13 | F7: =K7 -> 0 | G7: =L7 -> 0 | H7: 7 | I7: 6 | J7: 13 | K7: 0 | L7: 0 | M7: =SUM(H7:L7) -> 26
A8: 44094
A9: 44095 | B9: =SUM(C9:G9) -> 137 | C9: =H9 -> 13 | D9: =I9 -> 32 | E9: =J9 -> 91 | F9: =K9 -> 1 | G9: =L9 -> 0 | H9: 13 | I9: 32 | J9: 91 | K9: 1 | L9: 0 | M9: =SUM(H9:L9) -> 137
A10: 44096 | B10: =SUM(C10:G10) -> 457 | C10: =H10 -> 71 | D10: =I10 -> 99 | E10: =J10 -> 281 | F10: =K10 -> 6 | G10: =L10 -> 0 | H10: 71 | I10: 99 | J10: 281 | K10: 6 | L10: 0 | M10: =SUM(H10:L10) -> 457
A11: 44097 | B11: =SUM(C11:G11) -> 561 | C11: =H11 -> 78 | D11: =I11 -> 140 | E11: =J11 -> 338 | F11: =K11 -> 2 | G11: =L11 -> 3 | H11: 78 | I11: 140 | J11: 338 | K11: 2 | L11: 3 | M11: =SUM(H11:L11) -> 561
A12: 44098 | B12: =SUM(C12:G12) -> 852 | C12: =H12 -> 134 | D12: =I12 -> 197 | E12: =J12 -> 507 | F12: =K12 -> 7 | G12: =L12 -> 7 | H12: 134 | I12: 197 | J12: 507 | K12: 7 | L12: 7 | M12: =SUM(H12:L12) -> 852
A13: 44099 | B13: =SUM(C13:G13) -> 1289 | C13: =H13 -> 215 | D13: =I13 -> 283 | E13: =J13 -> 777 | F13: =K13 -> 13 | G13: =L13 -> 1 | H13: 215 | I13: 283 | J13: 777 | K13: 13 | L13: 1 | M13: =SUM(H13:L13) -> 1289
A14: 44100 | B14: =SUM(C14:G14) -> 302 | C14: =H14 -> 40 | D14: =I14 -> 63 | E14: =J14 -> 196 | F14: =K14 -> 3 | G14: =L14 -> 0 | H14: =31+9 -> 40 | I14: =36+27 -> 63 | J14: =167+29 -> 196 | K14: 3 | L14: 0 | M14: =SUM(H14:L14) -> 302
A15: 44101 | B15: =SUM(C15:G15) -> 57 | C15: =H15 -> 4 | D15: =I15 -> 15 | E15: =J15 -> 36 | F15: =K15 -> 0 | G15: =L15 -> 2 | H15: 4 | I15: 15 | J15: 36 | K15: 0 | L15: 2 | M15: =SUM(H15:L15) -> 57
A16: 44102 | B16: =SUM(C16:G16) -> 1380 | C16: =H16 -> 249 | D16: =I16 -> 307 | E16: =J16 -> 820 | F16: =K16 -> 4 | G16: =L16 -> 0 | H16: =81+168 -> 249 | I16: =90+217 -> 307 | J16: =210+610 -> 820 | K16: 4 | L16: 0 | M16: =SUM(H16:L16) -> 1380
A17: 44103 | B17: =SUM(C17:G17) -> 1097 | C17: =H17+N17 -> 178 | D17: =I17+O17 -> 253 | E17: =J17+P17 -> 658 | F17: =K17+Q17 -> 7 | G17: =L17 -> 1 | H17: =50+126 -> 176 | I17: =60+191 -> 251 | J17: =211+426 -> 637 | K17: =3+4 -> 7 | L17: 1 | M17: =SUM(H17:L17) -> 1072 | N17: 2 | O17: 2 | P17: 21 | Q17: 0 | R17: =SUM(N17:Q17) -> 25
A18: 44104 | B18: =SUM(C18:G18) -> 1177 | C18: =H18+N18 -> 167 | D18: =I18+O18 -> 257 | E18: =J18+P18 -> 734 | F18: =K18+Q18 -> 17 | G18: =L18 -> 2 | H18: =47+116 -> 163 | I18: =103+152 -> 255 | J18: =244+473 -> 717 | K18: =3+14 -> 17 | L18: 2 | M18: =SUM(H18:L18) -> 1154 | N18: 4 | O18: 2 | P18: 17 | Q18: 0 | R18: =SUM(N18:Q18) -> 23
A19: 44105 | B19: =SUM(C19:G19) -> 1072 | C19: =H19 -> 191 | D19: =I19 -> 244 | E19: =J19 -> 626 | F19: =K19 -> 8 | G19: =L19+Q19 -> 3 | H19: =55+136 -> 191 | I19: =89+155 -> 244 | J19: =203+423 -> 626 | K19: =5+3 -> 8 | L19: 3 | M19: =SUM(H19:L19) -> 1072 | R19: =SUM(N19:Q19) -> 0
A20: 44106 | B20: =SUM(C20:G20) -> 1406 | C20: =H20 -> 231 | D20: =I20 -> 327 | E20: =J20 -> 837 | F20: =K20 -> 10 | G20: =L20+Q20 -> 1 | H20: =82+149 -> 231 | I20: =116+211 -> 327 | J20: =276+561 -> 837 | K20: =4+6 -> 10 | L20: 1 | M20: =SUM(H20:L20) -> 1406
A21: 44107 | B21: =SUM(C21:G21) -> 380 | C21: =H21 -> 60 | D21: =I21 -> 53 | E21: =J21 -> 258 | F21: =K21 -> 9 | G21: =L21+Q21 -> 0 | H21: =41+19 -> 60 | I21: =22+31 -> 53 | J21: =177+81 -> 258 | K21: =5+4 -> 9 | L21: 0 | M21: =SUM(H21:L21) -> 380
A22: 44108 | B22: =SUM(C22:G22) -> 388 | C22: =H22 -> 67 | D22: =I22 -> 73 | E22: =J22 -> 243 | F22: =K22 -> 5 | G22: =L22+Q22 -> 0 | H22: 67 | I22: 73 | J22: 243 | K22: 5 | L22: 0 | M22: =SUM(H22:L22) -> 388
A23: 44109 | B23: =SUM(C23:G23) -> 1137 | C23: =H23+N23 -> 204 | D23: =I23+O23 -> 319 | E23: =J23+P23 -> 604 | F23: =K23+Q23 -> 9 | G23: =L23+Q23 -> 1 | H23: 194 | I23: 313 | J23: 602 | K23: 9 | L23: 1 | M23: =SUM(H23:L23) -> 1119 | N23: 10 | O23: 6 | P23: 2 | Q23: 0 | R23: =SUM(N23:Q23) -> 18
A24: 44110 | B24: =SUM(C24:G24) -> 1513 | C24: =H24 -> 205 | D24: =I24 -> 364 | E24: =J24 -> 934 | F24: =K24+P24 -> 8 | G24: =L24 -> 2 | H24: =3+98+104 -> 205 | I24: =73+130+161 -> 364 | J24: =202+376+356 -> 934 | K24: =5+3 -> 8 | L24: 2 | M24: =SUM(H24:L24) -> 1513
A25: 44111 | B25: =SUM(C25:G25) -> 1311 | C25: =H25+N25 -> 235 | D25: =I25+O25 -> 293 | E25: =J25+P25 -> 779 | F25: =K25+Q25 -> 4 | G25: =L25 -> 0 | H25: =113+118 -> 231 | I25: =194+99 -> 293 | J25: =457+322 -> 779 | K25: 4 | L25: 0 | M25: =SUM(H25:L25) -> 1307 | N25: 4 | O25: 0 | P25: 0 | Q25: 0 | R25: =SUM(N25:Q25) -> 4
A26: 44112 | B26: =SUM(C26:G26) -> 950 | C26: =H26 -> 151 | D26: =I26 -> 223 | E26: =J26 -> 572 | F26: =K26 -> 4 | G26: =L26 -> 0 | H26: =67+84 -> 151 | I26: =102+121 -> 223 | J26: =222+350 -> 572 | K26: =2+2 -> 4 | L26: 0 | M26: =SUM(H26:L26) -> 950
A27: 44113 | B27: =SUM(C27:G27) -> 1271 | C27: =H27 -> 198 | D27: =I27 -> 305 | E27: =J27 -> 764 | F27: =K27 -> 4 | G27: =L27 -> 0 | H27: =94+104 -> 198 | I27: =152+153 -> 305 | J27: =288+476 -> 764 | K27: 4 | L27: 0 | M27: =SUM(H27:L27) -> 1271
A28: 44114 | B28: =SUM(C28:G28) -> 763 | C28: =H28 -> 132 | D28: =I28 -> 186 | E28: =J28 -> 440 | F28: =K28 -> 5 | G28: =L28 -> 0 | H28: 132 | I28: 186 | J28: 440 | K28: 5 | L28: 0 | M28: =SUM(H28:L28) -> 763
A29: 44115
A30: 44116 | B30: =SUM(C30:G30) -> 1443 | C30: =H30 -> 206 | D30: =I30 -> 341 | E30: =J30 -> 877 | F30: =K30 -> 19 | G30: =L30 -> 0 | H30: 206 | I30: 341 | J30: 877 | K30: 19 | L30: 0 | M30: =SUM(H30:L30) -> 1443
A31: 44117 | B31: =SUM(C31:G31) -> 1581 | C31: =H31 -> 250 | D31: =I31 -> 382 | E31: =J31 -> 942 | F31: =K31 -> 7 | G31: =L31 -> 0 | H31: =17+104+82+47 -> 250 | I31: =49+92+138+103 -> 382 | J31: =84+278+336+244 -> 942 | K31: =2+0+5+0 -> 7 | L31: 0 | M31: =SUM(H31:L31) -> 1581
A32: 44118 | B32: =SUM(C32:G32) -> 3912 | C32: =SUM(H32,S32,X32,AC32,AH32,N32,AM32,AR32,AW32,BB32,BG32,BL32,BQ32,BV32,CA32,CF32) -> 1655 | D32: =SUM(I32,T32,Y32,AD32,AI32,AN32,AS32,O32,AX32,BC32,BH32,BM32,BR32,BW32,CB32,CG32) -> 539 | E32: =SUM(J32,P32,U32,Z32,AE32,AJ32,AO32,AT32,AY32,BD32,BI32,BN32,BS32,BX32,CC32,CH32) -> 1627 | F32: =SUM(K32,Q32,V32,AA32,AF32,AK32,AP32,AU32,AZ32,BE32,BJ32,BO32,BT32,BY32,CD32,CI32) -> 91 | G32: =L32 -> 0 | H32: =11+64 -> 75 | I32: =30+87 -> 117 | J32: =42+242 -> 284 | K32: =0+4 -> 4 | L32: 0 | M32: =SUM(H32:L32) -> 480 | R32: =SUM(N32:Q32) -> 0 | S32: 6 | T32: 52 | U32: 70 | V32: 0 | W32: =SUM(S32:V32) -> 128 | X32: 530 | Y32: 1 | Z32: 16 | AA32: 0 | AB32: =SUM(X32:AA32) -> 547 | AG32: =SUM(AC32:AF32) -> 0 | AH32: 1 | AI32: 73 | AJ32: 106 | AK32: 84 | AL32: =SUM(AH32:AK32) -> 264 | AM32: 33 | AN32: 36 | AO32: 69 | AP32: 0 | AQ32: =SUM(AM32:AP32) -> 138 | AR32: 173 | AS32: 0 | AT32: 120 | AU32: 0 | AV32: =SUM(AR32:AU32) -> 293 | AW32: 95 | AX32: 108 | AY32: 39 | AZ32: 0 | BA32: =SUM(AW32:AZ32) -> 242 | BB32: 524 | BC32: 1 | BD32: 5 | BE32: 0 | BF32: =SUM(BB32:BE32) -> 530 | BG32: 0 | BH32: 38 | BI32: 301 | BJ32: 3 | BK32: =SUM(BG32:BJ32) -> 342 | BL32: 5 | BM32: 0 | BN32: 171 | BO32: 0 | BP32: =SUM(BL32:BO32) -> 176 | BQ32: 0 | BR32: 64 | BS32: 6 | BT32: 0 | BU32: =SUM(BQ32:BT32) -> 70 | BV32: 85 | BW32: 0 | BX32: 58 | BY32: 0 | BZ32: =SUM(BV32:BY32) -> 143 | CA32: 95 | CB32: 6 | CC32: 60 | CD32: 0 | CE32: =SUM(CA32:CD32) -> 161 | CF32: 33 | CG32: 43 | CH32: 322 | CI32: 0 | CJ32: =SUM(CF32:CI32) -> 398
A33: 44119 | B33: =SUM(C33:G33) -> 4141 | C33: =SUM(H33,S33,X33,AC33,AH33,N33,AM33,AR33,AW33,BB33,BG33,BL33,BQ33,BV33,CA33,CF33) -> 1368 | D33: =SUM(I33,T33,Y33,AD33,AI33,AN33,AS33,O33,AX33,BC33,BH33,BM33,BR33,BW33,CB33,CG33) -> 755 | E33: =SUM(J33,P33,U33,Z33,AE33,AJ33,AO33,AT33,AY33,BD33,BI33,BN33,BS33,BX33,CC33,CH33) -> 1955 | F33: =SUM(K33,Q33,V33,AA33,AF33,AK33,AP33,AU33,AZ33,BE33,BJ33,BO33,BT33,BY33,CD33,CI33) -> 61 | G33: =L33 -> 2 | H33: =91+54 -> 145 | I33: =196+103 -> 299 | J33: =415+227 -> 642 | K33: 9 | L33: 2 | M33: =SUM(H33:L33) -> 1097 | N33: =12+7 -> 19 | O33: 2 | P33: 6 | Q33: 0 | R33: =SUM(N33:Q33) -> 27 | S33: 0 | T33: 38 | U33: 38 | V33: 0 | W33: =SUM(S33:V33) -> 76 | X33: 235 | Y33: 0 | Z33: 13 | AA33: 0 | AB33: =SUM(X33:AA33) -> 248 | AG33: 0 | AH33: 0 | AI33: 54 | AJ33: 87 | AK33: 47 | AL33: =SUM(AH33:AK33) -> 188 | AM33: 33 | AN33: 27 | AO33: 62 | AP33: 0 | AQ33: =SUM(AM33:AP33) -> 122 | AR33: 150 | AS33: 0 | AT33: 129 | AU33: 0 | AV33: =SUM(AR33:AU33) -> 279 | AW33: 129 | AX33: 166 | AY33: 34 | AZ33: 3 | BA33: =SUM(AW33:AZ33) -> 332 | BB33: 348 | BC33: 2 | BD33: 5 | BE33: 0 | BF33: =SUM(BB33:BE33) -> 355 | BG33: 2 | BH33: 39 | BI33: 229 | BJ33: 2 | BK33: =SUM(BG33:BJ33) -> 272 | BL33: 2 | BM33: 1 | BN33: 144 | BO33: 0 | BP33: =SUM(BL33:BO33) -> 147 | BQ33: 1 | BR33: 77 | BS33: 10 | BT33: 0 | BU33: =SUM(BQ33:BT33) -> 88 | BV33: 93 | BW33: 0 | BX33: 54 | BY33: 0 | BZ33: =SUM(BV33:BY33) -> 147 | CA33: 156 | CB33: 9 | CC33: 135 | CD33: 0 | CE33: =SUM(CA33:CD33) -> 300 | CF33: 55 | CG33: 41 | CH33: 367 | CI33: 0 | CJ33: =SUM(CF33:CI33) -> 463
A34: 44120 | B34: =SUM(C34:G34) -> 3178 | C34: =SUM(H34,S34,X34,AC34,AH34,N34,AM34,AR34,AW34,BB34,BG34,BL34,BQ34,BV34,CA34,CF34) -> 1232 | D34: =SUM(I34,T34,Y34,AD34,AI34,AN34,AS34,O34,AX34,BC34,BH34,BM34,BR34,BW34,CB34,CG34) -> 510 | E34: =SUM(J34,P34,U34,Z34,AE34,AJ34,AO34,AT34,AY34,BD34,BI34,BN34,BS34,BX34,CC34,CH34) -> 1420 | F34: =SUM(K34,Q34,V34,AA34,AF34,AK34,AP34,AU34,AZ34,BE34,BJ34,BO34,BT34,BY34,CD34,CI34) -> 16 | G34: =L34 -> 0 | H34: =42+51+33 -> 126 | I34: =117+114+112 -> 343 | J34: =103+238+225 -> 566 | K34: =3+0+2 -> 5 | L34: 0 | M34: =SUM(H34:L34) -> 1040 | N34: 0 | O34: 0 | P34: 0 | Q34: 0 | R34: 0 | S34: 1 | T34: 11 | U34: 16 | V34: 0 | W34: =SUM(S34:V34) -> 28 | X34: 378 | Y34: 5 | Z34: 21 | AA34: 0 | AB34: =SUM(X34:AA34) -> 404 | AG34: 0 | AH34: 0 | AI34: 8 | AJ34: 22 | AK34: 11 | AL34: =SUM(AH34:AK34) -> 41 | AM34: 12 | AN34: 17 | AO34: 26 | AP34: 0 | AQ34: =SUM(AM34:AP34) -> 55 | AR34: 100 | AS34: 0 | AT34: 153 | AU34: 0 | AV34: =SUM(AR34:AU34) -> 253 | AW34: 89 | AX34: 73 | AY34: 25 | AZ34: 0 | BA34: =SUM(AW34:AZ34) -> 187 | BB34: 322 | BC34: 0 | BD34: 1 | BE34: 0 | BF34: =SUM(BB34:BE34) -> 323 | BG34: 0 | BH34: 1 | BI34: 13 | BJ34: 0 | BK34: =SUM(BG34:BJ34) -> 14 | BL34: 2 | BM34: 0 | BN34: 135 | BO34: 0 | BP34: =SUM(BL34:BO34) -> 137 | BQ34: 1 | BR34: 22 | BS34: 2 | BT34: 0 | BU34: =SUM(BQ34:BT34) -> 25 | BV34: 73 | BW34: 0 | BX34: 70 | BY34: 0 | BZ34: =SUM(BV34:BY34) -> 143 | CA34: 86 | CB34: 3 | CC34: 77 | CD34: 0 | CE34: =SUM(CA34:CD34) -> 166 | CF34: 42 | CG34: 27 | CH34: 293 | CI34: 0 | CJ34: =SUM(CF34:CI34) -> 362
A35: 44121 | B35: =SUM(C35:G35) -> 4830 | C35: =SUM(H35,S35,X35,AC35,AH35,N35,AM35,AR35,AW35,BB35,BG35,BL35,BQ35,BV35,CA35,CF35) -> 1506 | D35: =SUM(I35,T35,Y35,AD35,AI35,AN35,AS35,O35,AX35,BC35,BH35,BM35,BR35,BW35,CB35,CG35) -> 1083 | E35: =SUM(J35,P35,U35,Z35,AE35,AJ35,AO35,AT35,AY35,BD35,BI35,BN35,BS35,BX35,CC35,CH35) -> 2113 | F35: =SUM(K35,Q35,V35,AA35,AF35,AK35,AP35,AU35,AZ35,BE35,BJ35,BO35,BT35,BY35,CD35,CI35) -> 128 | G35: =L35 -> 0 | H35: =33 -> 33 | I35: =112 -> 112 | J35: 225 | K35: 2 | L35: 0 | M35: =SUM(H35:L35) -> 372 | N35: 9 | O35: 0 | P35: 0 | Q35: 0 | R35: =SUM(N35:Q35) -> 9 | S35: 2 | T35: 137 | U35: 162 | V35: 0 | W35: =SUM(S35:V35) -> 301 | X35: 406 | Y35: 1 | Z35: 21 | AA35: 0 | AB35: =SUM(X35:AA35) -> 428 | AC35: 2 | AD35: 238 | AE35: 15 | AF35: 0 | AG35: 265 | AH35: 1 | AI35: 133 | AJ35: 175 | AK35: 120 | AL35: =SUM(AH35:AK35) -> 429 | AM35: 32 | AN35: 53 | AO35: 63 | AP35: 0 | AQ35: =SUM(AM35:AP35) -> 148 | AR35: 113 | AS35: 0 | AT35: 131 | AU35: 0 | AV35: =SUM(AR35:AU35) -> 244 | AW35: 149 | AX35: 140 | AY35: 48 | AZ35: 0 | BA35: =SUM(AW35:AZ35) -> 337 | BB35: 450 | BC35: 0 | BD35: 4 | BE35: 0 | BF35: =SUM(BB35:BE35) -> 454 | BG35: 0 | BH35: 71 | BI35: 516 | BJ35: 6 | BK35: =SUM(BG35:BJ35) -> 593 | BL35: 8 | BM35: 1 | BN35: 187 | BO35: 0 | BP35: =SUM(BL35:BO35) -> 196 | BQ35: 1 | BR35: 149 | BS35: 26 | BT35: 0 | BU35: =SUM(BQ35:BT35) -> 176 | BV35: 72 | BW35: 2 | BX35: 53 | BY35: 0 | BZ35: =SUM(BV35:BY35) -> 127 | CA35: =115+58 -> 173 | CB35: =16+5 -> 21 | CC35: =105+31 -> 136 | CD35: 0 | CE35: =SUM(CA35:CD35) -> 330 | CF35: 55 | CG35: 25 | CH35: 351 | CI35: 0 | CJ35: =SUM(CF35:CI35) -> 431
A36: 44122 | B36: =SUM(C36:G36) -> 1171 | C36: =SUM(H36,S36,X36,AC36,AH36,N36,AM36,AR36,AW36,BB36,BG36,BL36,BQ36,BV36,CA36,CF36) -> 177 | D36: =SUM(I36,T36,Y36,AD36,AI36,AN36,AS36,O36,AX36,BC36,BH36,BM36,BR36,BW36,CB36,CG36) -> 262 | E36: =SUM(J36,P36,U36,Z36,AE36,AJ36,AO36,AT36,AY36,BD36,BI36,BN36,BS36,BX36,CC36,CH36) -> 720 | F36: =SUM(K36,Q36,V36,AA36,AF36,AK36,AP36,AU36,AZ36,BE36,BJ36,BO36,BT36,BY36,CD36,CI36) -> 7 | G36: =L36 -> 5 | H36: =67+66+44 -> 177 | I36: =87+83+92 -> 262 | J36: =228+258+234 -> 720 | K36: =7+0 -> 7 | L36: 5 | M36: =SUM(H36:L36) -> 1171
A37: 44123 | B37: =SUM(C37:G37) -> 3041 | C37: =SUM(H37,S37,X37,AC37,AH37,N37,AM37,AR37,AW37,BB37,BG37,BL37,BQ37,BV37,CA37,CF37) -> 784 | D37: =SUM(I37,T37,Y37,AD37,AI37,AN37,AS37,O37,AX37,BC37,BH37,BM37,BR37,BW37,CB37,CG37) -> 548 | E37: =SUM(J37,P37,U37,Z37,AE37,AJ37,AO37,AT37,AY37,BD37,BI37,BN37,BS37,BX37,CC37,CH37) -> 1669 | F37: =SUM(K37,Q37,V37,AA37,AF37,AK37,AP37,AU37,AZ37,BE37,BJ37,BO37,BT37,BY37,CD37,CI37) -> 39 | G37: =L37 -> 1 | H37: =35+32+43+39-18 -> 131 | I37: =54+23+124+128-53 -> 276 | J37: =115+309+257+221-90 -> 812 | K37: =2+0+4+1-1 -> 6 | L37: 1 | M37: =SUM(H37:L37) -> 1226 | N37: 0 | O37: 0 | P37: 0 | Q37: 0 | R37: 0 | S37: 0 | T37: 43 | U37: 75 | V37: 0 | W37: =SUM(S37:V37) -> 118 | X37: 197 | Y37: 3 | Z37: 5 | AA37: 0 | AB37: =SUM(X37:AA37) -> 205 | AH37: 0 | AI37: 33 | AJ37: 20 | AK37: 33 | AL37: =SUM(AH37:AK37) -> 86 | AM37: 8 | AN37: 8 | AO37: 15 | AP37: 0 | AQ37: =SUM(AM37:AP37) -> 31 | AR37: 66 | AS37: 0 | AT37: 79 | AU37: 0 | AV37: =SUM(AR37:AU37) -> 145 | AW37: 64 | AX37: 66 | AY37: 30 | AZ37: 0 | BA37: =SUM(AW37:AZ37) -> 160 | BB37: 170 | BC37: 0 | BD37: 4 | BE37: 0 | BF37: =SUM(BB37:BE37) -> 174 | BG37: 8 | BH37: 25 | BI37: 113 | BJ37: 0 | BK37: =SUM(BG37:BJ37) -> 146 | BL37: 3 | BM37: 1 | BN37: 124 | BO37: 0 | BP37: =SUM(BL37:BO37) -> 128 | BQ37: 1 | BR37: 58 | BS37: 6 | BT37: 0 | BU37: =SUM(BQ37:BT37) -> 65 | BV37: 55 | BW37: 1 | BX37: 34 | BY37: 0 | BZ37: =SUM(BV37:BY37) -> 90 | CA37: 49 | CB37: 11 | CC37: 43 | CD37: 0 | CE37: =SUM(CA37:CD37) -> 103 | CF37: 32 | CG37: 23 | CH37: 309 | CI37: 0 | CJ37: =SUM(CF37:CI37) -> 364
A38: 44124 | B38: =SUM(C38:G38) -> 3041 | C38: =SUM(H38,S38,X38,AC38,AH38,N38,AM38,AR38,AW38,BB38,BG38,BL38,BQ38,BV38,CA38,CF38) -> 1017 | D38: =SUM(I38,T38,Y38,AD38,AI38,AN38,AS38,O38,AX38,BC38,BH38,BM38,BR38,BW38,CB38,CG38) -> 526 | E38: =SUM(J38,P38,U38,Z38,AE38,AJ38,AO38,AT38,AY38,BD38,BI38,BN38,BS38,BX38,CC38,CH38) -> 1438 | F38: =SUM(K38,Q38,V38,AA38,AF38,AK38,AP38,AU38,AZ38,BE38,BJ38,BO38,BT38,BY38,CD38,CI38) -> 57 | G38: =L38 -> 3 | H38: =18+56-6 -> 68 | I38: =53+112 -> 165 | J38: =90+294 -> 384 | K38: =1+1 -> 2 | L38: 3 | M38: =SUM(H38:L38) -> 622 | N38: 6 | O38: 0 | P38: 0 | Q38: 0 | R38: 6 | S38: 2 | T38: 49 | U38: 44 | V38: 0 | W38: =SUM(S38:V38) -> 95 | X38: 132 | Y38: 0 | Z38: 13 | AA38: 0 | AB38: =SUM(X38:AA38) -> 145 | AH38: 0 | AI38: 51 | AJ38: 89 | AK38: 54 | AL38: =SUM(AH38:AK38) -> 194 | AM38: 31 | AN38: 34 | AO38: 54 | AP38: 0 | AQ38: =SUM(AM38:AP38) -> 119 | AR38: 130 | AS38: 0 | AT38: 125 | AU38: 0 | AV38: =SUM(AR38:AU38) -> 255 | AW38: 85 | AX38: 79 | AY38: 12 | AZ38: 0 | BA38: =SUM(AW38:AZ38) -> 176 | BB38: 396 | BC38: 2 | BD38: 2 | BE38: 0 | BF38: =SUM(BB38:BE38) -> 400 | BG38: 0 | BH38: 35 | BI38: 201 | BJ38: 1 | BK38: =SUM(BG38:BJ38) -> 237 | BL38: 5 | BM38: 4 | BN38: 106 | BO38: 0 | BP38: =SUM(BL38:BO38) -> 115 | BQ38: 1 | BR38: 56 | BS38: 8 | BT38: 0 | BU38: =SUM(BQ38:BT38) -> 65 | BV38: 31 | BW38: 1 | BX38: 37 | BY38: 0 | BZ38: =SUM(BV38:BY38) -> 69 | CA38: 99 | CB38: 15 | CC38: 96 | CD38: 0 | CE38: =SUM(CA38:CD38) -> 210 | CF38: 31 | CG38: 35 | CH38: 267 | CI38: 0 | CJ38: =SUM(CF38:CI38) -> 333
A39: 44125 | B39: =SUM(C39:G39) -> 2462 | C39: =SUM(H39,S39,X39,AC39,AH39,N39,AM39,AR39,AW39,BB39,BG39,BL39,BQ39,BV39,CA39,CF39) -> 915 | D39: =SUM(I39,T39,Y39,AD39,AI39,AN39,AS39,O39,AX39,BC39,BH39,BM39,BR39,BW39,CB39,CG39) -> 425 | E39: =SUM(J39,P39,U39,Z39,AE39,AJ39,AO39,AT39,AY39,BD39,BI39,BN39,BS39,BX39,CC39,CH39) -> 1055 | F39: =SUM(K39,Q39,V39,AA39,AF39,AK39,AP39,AU39,AZ39,BE39,BJ39,BO39,BT39,BY39,CD39,CI39) -> 67 | G39: =L39 -> 0 | H39: =40+40 -> 80 | I39: =76+80 -> 156 | J39: =183 -> 183 | K39: =5+1 -> 6 | L39: 0 | M39: =SUM(H39:L39) -> 425 | N39: 0 | O39: 0 | P39: 0 | Q39: 0 | R39: 0 | S39: 0 | T39: 12 | U39: 14 | V39: 0 | W39: =SUM(S39:V39) -> 26 | X39: 353 | Y39: 6 | Z39: 14 | AA39: 0 | AB39: =SUM(X39:AA39) -> 373 | AH39: 3 | AI39: 57 | AJ39: 106 | AK39: 59 | AL39: =SUM(AH39:AK39) -> 225 | AM39: 20 | AN39: 16 | AO39: 21 | AP39: 0 | AQ39: =SUM(AM39:AP39) -> 57 | AR39: 64 | AS39: 1 | AT39: 82 | AU39: 0 | AV39: =SUM(AR39:AU39) -> 147 | AW39: 70 | AX39: 70 | AY39: 18 | AZ39: 0 | BA39: =SUM(AW39:AZ39) -> 158 | BB39: 192 | BC39: 0 | BD39: 0 | BE39: 0 | BF39: =SUM(BB39:BE39) -> 192 | BG39: 1 | BH39: 54 | BI39: 245 | BJ39: 2 | BK39: =SUM(BG39:BJ39) -> 302 | BL39: 1 | BM39: 7 | BN39: 87 | BO39: 0 | BP39: =SUM(BL39:BO39) -> 95 | BQ39: 0 | BR39: 12 | BS39: 0 | BT39: 0 | BU39: =SUM(BQ39:BT39) -> 12 | BV39: 37 | BW39: 0 | BX39: 26 | BY39: 0 | BZ39: =SUM(BV39:BY39) -> 63 | CA39: 69 | CB39: 4 | CC39: 62 | CD39: 0 | CE39: =SUM(CA39:CD39) -> 135 | CF39: 25 | CG39: 30 | CH39: 197 | CI39: 0 | CJ39: =SUM(CF39:CI39) -> 252
A40: 44126 | B40: =SUM(C40:G40) -> 3178 | C40: =SUM(H40,S40,X40,AC40,AH40,N40,AM40,AR40,AW40,BB40,BG40,BL40,BQ40,BV40,CA40,CF40) -> 937 | D40: =SUM(I40,T40,Y40,AD40,AI40,AN40,AS40,O40,AX40,BC40,BH40,BM40,BR40,BW40,CB40,CG40) -> 634 | E40: =SUM(J40,P40,U40,Z40,AE40,AJ40,AO40,AT40,AY40,BD40,BI40,BN40,BS40,BX40,CC40,CH40) -> 1563 | F40: =SUM(K40,Q40,V40,AA40,AF40,AK40,AP40,AU40,AZ40,BE40,BJ40,BO40,BT40,BY40,CD40,CI40) -> 43 | G40: =L40 -> 1 | H40: =26+6+37+50 -> 119 | I40: =10+103+73+97 -> 283 | J40: =17+200+190+195+197 -> 799 | K40: 2 | L40: 1 | M40: =SUM(H40:L40) -> 1204 | N40: 0 | O40: 0 | P40: 0 | Q40: 0 | R40: 0 | S40: 2 | T40: =40 -> 40 | U40: =62 -> 62 | V40: 0 | W40: =SUM(S40:V40) -> 104 | X40: =252 -> 252 | Y40: =2 -> 2 | Z40: 1 | AA40: 0 | AB40: =SUM(X40:AA40) -> 255 | AH40: 0 | AI40: 33 | AJ40: 55 | AK40: 41 | AL40: =SUM(AH40:AK40) -> 129 | AM40: 26 | AN40: 23 | AO40: 42 | AP40: 0 | AQ40: =SUM(AM40:AP40) -> 91 | AR40: 77 | AS40: 0 | AT40: 61 | AU40: 0 | AV40: =SUM(AR40:AU40) -> 138 | AW40: 71 | AX40: 78 | AY40: 19 | AZ40: 0 | BA40: =SUM(AW40:AZ40) -> 168 | BB40: 249 | BC40: 0 | BD40: 3 | BE40: 0 | BF40: =SUM(BB40:BE40) -> 252 | BG40: 2 | BH40: 15 | BI40: 136 | BJ40: 0 | BK40: =SUM(BG40:BJ40) -> 153 | BL40: 3 | BM40: 1 | BN40: 84 | BO40: 0 | BP40: =SUM(BL40:BO40) -> 88 | BQ40: 1 | BR40: 85 | BS40: 15 | BT40: 0 | BU40: =SUM(BQ40:BT40) -> 101 | BV40: 42 | BW40: 35 | BX40: 1 | BY40: 0 | BZ40: =SUM(BV40:BY40) -> 78 | CA40: =68 -> 68 | CB40: 6 | CC40: 45 | CD40: 0 | CE40: =SUM(CA40:CD40) -> 119 | CF40: 25 | CG40: 33 | CH40: 240 | CI40: 0 | CJ40: =SUM(CF40:CI40) -> 298
A41: 44127 | B41: =SUM(C41:G41) -> 2557 | C41: =SUM(H41,S41,X41,AC41,AH41,N41,AM41,AR41,AW41,BB41,BG41,BL41,BQ41,BV41,CA41,CF41) -> 920 | D41: =SUM(I41,T41,Y41,AD41,AI41,AN41,AS41,O41,AX41,BC41,BH41,BM41,BR41,BW41,CB41,CG41) -> 414 | E41: =SUM(J41,P41,U41,Z41,AE41,AJ41,AO41,AT41,AY41,BD41,BI41,BN41,BS41,BX41,CC41,CH41) -> 1197 | F41: =SUM(K41,Q41,V41,AA41,AF41,AK41,AP41,AU41,AZ41,BE41,BJ41,BO41,BT41,BY41,CD41,CI41) -> 24 | G41: =L41 -> 2 | H41: =37+48 -> 85 | I41: =73+92 -> 165 | J41: =95+8+253 -> 356 | K41: =2 -> 2 | L41: =1+1 -> 2 | M41: =SUM(H41:L41) -> 610 | N41: 0 | O41: 0 | P41: 0 | Q41: 0 | R41: 0 | S41: 1 | T41: 45 | U41: 47 | V41: 0 | W41: =SUM(S41:V41) -> 93 | X41: 265 | Y41: 0 | Z41: 8 | AA41: 0 | AB41: =SUM(X41:AA41) -> 273 | AH41: 0 | AI41: 25 | AJ41: 51 | AK41: 22 | AL41: =SUM(AH41:AK41) -> 98 | AM41: 35 | AN41: 38 | AO41: 29 | AP41: 0 | AQ41: =SUM(AM41:AP41) -> 102 | AR41: 73 | AS41: 0 | AT41: 76 | AU41: 0 | AV41: =SUM(AR41:AU41) -> 149 | AW41: =61+2 -> 63 | AX41: 68 | AY41: 15 | AZ41: 0 | BA41: =SUM(AW41:AZ41) -> 146 | BB41: =252+1 -> 253 | BC41: 1 | BD41: 0 | BE41: 0 | BF41: =SUM(BB41:BE41) -> 254 | BG41: 1 | BH41: 20 | BI41: 131 | BJ41: 0 | BK41: =SUM(BG41:BJ41) -> 152 | BL41: 3 | BM41: 7 | BN41: 106 | BO41: 0 | BP41: =SUM(BL41:BO41) -> 116 | BQ41: 1 | BR41: 17 | BS41: 1 | BT41: 0 | BU41: =SUM(BQ41:BS41) -> 19 | BV41: 44 | BW41: 0 | BX41: 36 | BY41: 0 | BZ41: =SUM(BV41:BY41) -> 80 | CA41: =55+3 -> 58 | CB41: =5+0 -> 5 | CC41: 69 | CD41: 0 | CE41: =SUM(CA41:CD41) -> 132 | CF41: 38 | CG41: 23 | CH41: 272 | CI41: 0 | CJ41: =SUM(CF41:CI41) -> 333
...

Sheet In-Person Daily by Satellite
A1: In-person Absentee Voting -- Applications by Satellite
A2: November 3 2020 General Election
B4: Total In Person | C4: Total | G4: Government Center | K4: =K50 -> 50644 | L4: Centreville | P4: =P50 -> 10858 | Q4: Franconia | U4: =U50 -> 10161 | V4: Great Falls | Z4: =Z50 -> 2317 | AA4: Herndon | AE4: =AE50 -> 10104 | AF4: Laurel Hill | AJ4: =AJ50 -> 9207 | AK4: Mason | AO4: =AO50 -> 10732 | AP4: McLean | AT4: =AT50 -> 13504 | AU4: MT Vernon | AY4: =AY50 -> 13132 | AZ4: North County | BD4: =BD50 -> 11638 | BE4: Providence | BI4: =BI50 -> 11843 | BJ4: Sully | BN4: =BN50 -> 8467 | BO4: Thomas Jefferson | BS4: =BS50 -> 9536 | BT4: Tysons Pimmit | BX4: =BX50 -> 10318 | BY4: West Springfield | CC4: =CC50 -> 11135
A5: Date | B5: =B50 -> 193596 | C5: CD 8 | D5: CD 10 | E5: CD 11 | F5: CD 11- Herndon | G5: CD 8 | H5: CD 10 | I5: C11 | J5: Herndon | K5: Total | L5: CD 8 | M5: CD 10 | N5: CD 11 | O5: Herndon | P5: Total | Q5: CD 8 | R5: CD 10 | S5: CD 11 | T5: Herndon | U5: Total | V5: CD 8 | W5: CD 10 | X5: CD 11 | Y5: Herndon | Z5: Total | AA5: CD 8 | AB5: CD 10 | AC5: CD 11 | AD5: Herndon | AE5: Total | AF5: CD 8 | AG5: CD 10 | AH5: CD 11 | AI5: Herndon | AJ5: Total | AK5: CD 8 | AL5: CD 10 | AM5: CD 11 | AN5: Herndon | AO5: Total | AP5: CD 8 | AQ5: CD 10 | AR5: CD 11 | AS5: Herndon | AT5: Total | AU5: CD 8 | AV5: CD 10 | AW5: CD 11 | AX5: Herndon | AY5: Total | AZ5: CD 8 | BA5: CD 10 | BB5: CD 11 | BC5: Herndon | BD5: Total | BE5: CD 8 | BF5: CD 10 | BG5: CD 11 | BH5: Herndon | BI5: Total | BJ5: CD 8 | BK5: CD 10 | BL5: CD 11 | BM5: Herndon | BN5: Total | BO5: CD 8 | BP5: CD 10 | BQ5: CD 11 | BR5: Herndon | BS5: Total | BT5: CD 8 | BU5: CD 10 | BV5: CD 11 | BW5: Herndon | BX5: Total | BY5: CD 8 | BZ5: CD 10 | CA5: CD 11 | CB5: Herndon | CC5: Total
A6: 44092 | B6: =SUM(C6:F6) -> 1213 | C6: 286 | D6: 236 | E6: 683 | F6: =J6 -> 8 | G6: 286 | H6: 236 | I6: 683 | J6: 8 | K6: =SUM(G6:J6) -> 1213
A7: 44093 | B7: =SUM(C7:F7) -> 1048 | C7: 249 | D7: 181 | E7: 611 | F7: =J7 -> 7 | G7: 249 | H7: 181 | I7: 611 | J7: 7 | K7: =SUM(G7:J7) -> 1048
A8: 44094
A9: 44095 | B9: =SUM(C9:F9) -> 1003 | C9: =G9 -> 234 | D9: =H9 -> 224 | E9: =I9 -> 531 | F9: =J9 -> 14 | G9: 234 | H9: 224 | I9: 531 | J9: 14 | K9: =SUM(G9:J9) -> 1003
A10: 44096 | B10: =SUM(C10:F10) -> 901 | C10: =G10 -> 187 | D10: =H10 -> 195 | E10: =I10 -> 505 | F10: =J10 -> 14 | G10: 187 | H10: 195 | I10: 505 | J10: 14 | K10: =SUM(G10:J10) -> 901
A11: 44097 | B11: =SUM(G11:J11) -> 1121 | C11: =G11 -> 260 | D11: =H11 -> 267 | E11: =I11 -> 587 | F11: =J11 -> 7 | G11: 260 | H11: 267 | I11: 587 | J11: 7 | K11: =SUM(G11:J11) -> 1121
A12: 44098 | B12: =SUM(C12:F12) -> 1226 | C12: =G12 -> 224 | D12: =H12 -> 295 | E12: =I12 -> 698 | F12: =J12 -> 9 | G12: 224 | H12: 295 | I12: 698 | J12: 9 | K12: =SUM(G12:J12) -> 1226
A13: 44099 | B13: =SUM(C13:F13) -> 1264 | C13: =G13 -> 357 | D13: =H13 -> 321 | E13: =I13 -> 577 | F13: =J13 -> 9 | G13: 357 | H13: 321 | I13: 577 | J13: 9 | K13: =SUM(G13:J13) -> 1264
A14: 44100
A15: 44101
A16: 44102 | B16: =SUM(G16:J16) -> 1209 | C16: =G16 -> 275 | D16: =H16 -> 259 | E16: =I16 -> 670 | F16: =J16 -> 5 | G16: 275 | H16: 259 | I16: 670 | J16: 5 | K16: =SUM(G16:J16) -> 1209
A17: 44103 | B17: =SUM(C17:F17) -> 1270 | C17: 265 | D17: 284 | E17: 715 | F17: 6 | G17: 265 | H17: 284 | I17: 715 | J17: 6 | K17: =SUM(G17:J17) -> 1270
A18: 44104 | B18: =SUM(C18:F18) -> 1222 | C18: =G18 -> 297 | D18: =H18 -> 290 | E18: =I18 -> 620 | F18: =J18 -> 15 | G18: 297 | H18: 290 | I18: 620 | J18: 15 | K18: =SUM(G18:J18) -> 1222
A19: 44105 | B19: =SUM(C19:F19) -> 1244 | C19: =G19 -> 266 | D19: =H19 -> 271 | E19: =I19 -> 698 | F19: =J19 -> 9 | G19: 266 | H19: 271 | I19: 698 | J19: 9 | K19: =SUM(G19:J19) -> 1244
A20: 44106 | B20: =SUM(C20:F20) -> 1464 | C20: =G20 -> 304 | D20: =H20 -> 340 | E20: =I20 -> 798 | F20: =J20 -> 22 | G20: 304 | H20: 340 | I20: 798 | J20: 22 | K20: =SUM(G20:J20) -> 1464
A21: 44107
A22: 44108
A23: 44109 | B23: =SUM(C23:F23) -> 1213 | C23: =G23 -> 224 | D23: =H23 -> 306 | E23: =I23 -> 670 | F23: =J23 -> 13 | G23: 224 | H23: 306 | I23: 670 | J23: 13 | K23: =SUM(G23:J23) -> 1213
A24: 44110 | B24: =SUM(C24:F24) -> 1310 | C24: =G24 -> 223 | D24: =H24 -> 360 | E24: =I24 -> 718 | F24: =J24 -> 9 | G24: 223 | H24: 360 | I24: 718 | J24: 9 | K24: =SUM(G24:J24) -> 1310
A25: 44111 | B25: =SUM(C25:F25) -> 1323 | C25: 217 | D25: =H25 -> 352 | E25: =I25 -> 750 | F25: =J25 -> 4 | G25: 217 | H25: 352 | I25: 750 | J25: 4 | K25: =SUM(G25:J25) -> 1323
A26: 44112 | B26: =SUM(C26:F26) -> 1309 | C26: =G26 -> 242 | D26: =H26 -> 331 | E26: =I26 -> 721 | F26: =J26 -> 15 | G26: 242 | H26: 331 | I26: 721 | J26: 15 | K26: =SUM(G26:J26) -> 1309
A27: 44113 | B27: =SUM(C27:F27) -> 1490 | C27: =G27 -> 300 | D27: =H27 -> 383 | E27: =I27 -> 788 | F27: =J27 -> 19 | G27: 300 | H27: 383 | I27: 788 | J27: 19 | K27: =SUM(G27:J27) -> 1490
A28: 44114 | B28: =SUM(C28:F28) -> 1240 | C28: =G28 -> 250 | D28: =H28 -> 269 | E28: =I28 -> 710 | F28: =J28 -> 11 | G28: 250 | H28: 269 | I28: 710 | J28: 11 | K28: =SUM(G28:J28) -> 1240
A29: 44115
A30: 44116
A31: 44117 | B31: =SUM(C31:F31) -> 1238 | C31: =G31 -> 204 | D31: =H31 -> 292 | E31: =I31 -> 738 | F31: =J31 -> 4 | G31: 204 | H31: 292 | I31: 738 | J31: 4 | K31: =SUM(G31:J31) -> 1238
A32: 44118 | B32: =SUM(C32:F32) -> 7473 | C32: =G32+L32+Q32+V32+AA32+AF32+AK32+AP32+AU32+AZ32+BE32+BJ32+BO32+BT32+BY32 -> 2183 | D32: =H32+M32+R32+W32+AB32+AG32+AL32+AQ32+AV32+BA32+BF32+BK32+BP32+BU32+BZ32 -> 1572 | E32: =I32+N32+S32+X32+AC32+AH32+AM32+AR32+AW32+BB32+BG32+BL32+BQ32+BV32+CA32 -> 3584 | F32: =J32+O32+T32+Y32+AD32+AI32+AN32+AS32+AX32+BC32+BH32+BM32+BR32+BW32+CB32 -> 134 | G32: 165 | H32: 487 | I32: 978 | J32: 1 | K32: =SUM(G32:J32) -> 1631 | L32: 3 | M32: 164 | N32: 261 | O32: 0 | P32: =SUM(L32:O32) -> 428 | Q32: 426 | R32: 7 | S32: 26 | T32: 0 | U32: =SUM(Q32:T32) -> 459 | AA32: 0 | AB32: 79 | AC32: 136 | AD32: 128 | AE32: =SUM(AA32:AD32) -> 343 | AF32: 115 | AG32: 69 | AH32: 181 | AI32: 0 | AJ32: =SUM(AF32:AI32) -> 365 | AK32: 214 | AL32: 0 | AM32: 231 | AN32: 0 | AO32: =SUM(AK32:AN32) -> 445 | AP32: 176 | AQ32: 319 | AR32: 75 | AS32: 0 | AT32: =SUM(AP32:AS32) -> 570 | AU32: 550 | AV32: 0 | AW32: 2 | AX32: 0 | AY32: =SUM(AU32:AX32) -> 552 | AZ32: 1 | BA32: 51 | BB32: 439 | BC32: 3 | BD32: =SUM(AZ32:BC32) -> 494 | BE32: 22 | BF32: 17 | BG32: 478 | BH32: 0 | BI32: =SUM(BE32:BH32) -> 517 | BJ32: 1 | BK32: 324 | BL32: 55 | BM32: 2 | BN32: =SUM(BJ32:BM32) -> 382 | BO32: 190 | BP32: 4 | BQ32: 184 | BR32: 0 | BS32: =SUM(BO32:BR32) -> 378 | BT32: 280 | BU32: 22 | BV32: 189 | BW32: 0 | BX32: =SUM(BT32:BW32) -> 491 | BY32: 40 | BZ32: 29 | CA32: 349 | CB32: 0 | CC32: =SUM(BY32:CB32) -> 418
A33: 44119 | B33: =SUM(C33:F33) -> 8296 | C33: =G33+L33+Q33+V33+AA33+AF33+AK33+AP33+AU33+AZ33+BE33+BJ33+BO33+BT33+BY33 -> 2516 | D33: =H33+M33+R33+W33+AB33+AG33+AL33+AQ33+AV33+BA33+BF33+BK33+BP33+BU33+BZ33 -> 1693 | E33: =I33+N33+S33+X33+AC33+AH33+AM33+AR33+AW33+BB33+BG33+BL33+BQ33+BV33+CA33 -> 3939 | F33: =J33+O33+T33+Y33+AD33+AI33+AN33+AS33+AX33+BC33+BH33+BM33+BR33+BW33+CB33 -> 148 | G33: 158 | H33: 425 | I33: 974 | J33: 4 | K33: =SUM(G33:J33) -> 1561 | L33: 1 | M33: 192 | N33: 269 | O33: 0 | P33: =SUM(L33:O33) -> 462 | Q33: 500 | R33: 3 | S33: 17 | T33: 0 | U33: =SUM(Q33:T33) -> 520 | AA33: 0 | AB33: 96 | AC33: 184 | AD33: 132 | AE33: =SUM(AA33:AD33) -> 412 | AF33: 98 | AG33: 94 | AH33: 190 | AI33: 0 | AJ33: =SUM(AF33:AI33) -> 382 | AK33: 289 | AL33: 2 | AM33: 280 | AN33: 0 | AO33: =SUM(AK33:AN33) -> 571 | AP33: 256 | AQ33: 337 | AR33: 101 | AS33: 0 | AT33: =SUM(AP33:AS33) -> 694 | AU33: 619 | AV33: 0 | AW33: 2 | AX33: 0 | AY33: =SUM(AU33:AX33) -> 621 | AZ33: 1 | BA33: 77 | BB33: 475 | BC33: 11 | BD33: =SUM(AZ33:BC33) -> 564 | BE33: 9 | BF33: 14 | BG33: 548 | BH33: 0 | BI33: =SUM(BE33:BH33) -> 571 | BJ33: 2 | BK33: 357 | BL33: 60 | BM33: 0 | BN33: =SUM(BJ33:BM33) -> 419 | BO33: 238 | BP33: 4 | BQ33: 191 | BR33: 0 | BS33: =SUM(BO33:BR33) -> 433 | BT33: 260 | BU33: 35 | BV33: 214 | BW33: 1 | BX33: =SUM(BT33:BW33) -> 510 | BY33: 85 | BZ33: 57 | CA33: 434 | CB33: 0 | CC33: =SUM(BY33:CB33) -> 576
